Workbook

Sheet Note
A1: skip
B2: Life cycle inventories of global metal and mineral supply chains: a comprehensive data review, analysis and processing Frédéric Laia*, Stéphanie Mullera, Audrey Philippea, Robert Istrateb, Brenda Miranda Xicotencatlb, Afsoon Mansouri Askic, Aina Mas Fonsd,a, Juliana Segura-Salazare, Jair Santillán Saldivara, Alexander Cimprichf, Stephen Northeyg, Lígia da Silva Limah, Lieselot Booneh, Ryosuke Yokoii, Kamrul Islami, Ioanna Paschalidouj, Felipe Cerdask,l, Victor Balboa-Espinozae, Anish Koyamparambathd, Diae Henniouia, Victoire Collignona, Aurélien Reysa, Gyslain Ngadi Sakatadim, Jo Dewulfh, Bernhard Steubingb, Christoph Helbigc, Gaétan Lefebvrea, Gian Andrea Blenginin,m, Valeria Supertio, Masaharu Motoshitai, Guido Sonnemannd, Kwame Awuah-Offeij, Steven B. Youngf, Shinsuke Murakamip, Antoine Beylota aBRGM, F-45060 Orléans, France bInstitute of Environmental Sciences (CML), Leiden University, Einsteinweg 2, 2333 CC Leiden, NL cEcological Resource Technology, University of Bayreuth, Universitätstr. 30, 95447 Bayreuth, Germany dUniv. Bordeaux, CNRS, Bordeaux INP, ISM, UMR 5255, F-33400 Talence, France eSustainable Minerals Institute, The University of Queensland, QLD, 4072, Australia fSchool of Environment, Enterprise and Development, University of Waterloo, 200 University Avenue West, Waterloo, Ontario N2L 3G1, Canada gUniversity of Technology Sydney, Institute for Sustainable Futures, Australia hSustainable Systems Engineering (STEN), Department of Green Chemistry and Technology, Faculty of Bioscience Engineering, Ghent University, Coupure Links 653, 9000 Ghent, Belgium iAIST, 305-8569 Tsukuba, Japan jMining & Explosives Engineering, Missouri University of Science & Technology, Rolla, MO, USA 65409 kInstitute for Sustainable Energy Systems (INSYS), Technical University of Applied Sciences Würzburg-Schweinfurt (THWS), Ignaz-Schön-Straße 11, Schweinfurt, Germany lFraunhofer Institute for Surface Engineering and Thin Films IST, Riedenkamp 2, Braunschweig 38108, Germany mDepartment of Environment, Land and Infrastructure Engineering, Politecnico di Torino, Corso Duca degli Abruzzi, 24, 10129 Torino, Italy nUniversity of Turin, Earth Sciences Department (DST), Via Valperga Caluso, 35 – 10125 Torino, Italy oecoinvent association, Technopark, Technoparkstrasse 1, 8005 Zürich, Switzerland pGraduate School of Engineering, The University of Tokyo, Tokyo 113-8656, Japan *Corresponding author: f.lai@brgm.fr This file provides all LCI datasets developed for Cobalt (Co), with distinguishing its global market and each individual production route.
B33: Sheet | C33: Corresponding route
B34: Co_Market_GLO | C34: Co global market
B35: PR1_CoSO4_CN_Xinjiang | C35: Ni/Cu/Co ore mining in China/Xinjiang and CoSO4 production in Southeastern China
B36: PR2_CoSO4_CD-CN_Tongxiang | C36: Cu/Co ore mining in DRC and CoSO4 production in China/Tongxiang
B37: PR3_Co3O4_CD-CN_Quzhou | C37: Cu/Co ore mining in DRC and Co3O4 production in China/Quzhou
B38: PR4_Co_CD-CN-GLO | C38: Cu/Co ore mining in DRC and Co production
B39: PR5_Co_AU_HPAL_Laterites | C39: Co recovery from laterite ore mining and Ni class 1 production in Australia from HPAL
B40: PR6_Co_AU_FlashSmelting | C40: Co recovery from sulfide ore mining and Ni class 1 production in Australia through Flash Smelting
B41: PR7_Co(OH)2_Europe_Recycling | C41: Co(OH)2 production in Europe through hardmetal scrap recycling

Sheet Co_Market_GLO
A1: database | B1: Cobalt
A3: Activity | B3: Cobalt (Co) global market
A4: reference product | B4: Co commodities
A5: location | B5: GLO
A6: amount | B6: 1
A7: unit | B7: kilogram
A8: comment | B8: n/a
A9: Exchanges
A10: name | B10: reference product | C10: location | D10: amount | E10: unit | F10: database | G10: type | H10: categories | I10: uncertainty type | J10: pedigree | K10: loc | L10: scale | M10: minimum | N10: maximum
A11: =B3 -> Cobalt (Co) global market | B11: =B4 -> Co commodities | C11: =B5 -> GLO | D11: 1 | E11: =B7 -> kilogram | F11: =B1 -> Cobalt | G11: production
A12: =PR1_CoSO4_CN_Xinjiang!A76 -> Ni/Cu/Co ore mining in China/Xinjiang and CoSO4 production in Southeastern China | B12: =PR1_CoSO4_CN_Xinjiang!B76 -> CoSO4 | C12: =PR1_CoSO4_CN_Xinjiang!C76 -> CN | D12: 0.15164499 | E12: =PR1_CoSO4_CN_Xinjiang!E76 -> kilogram | F12: =PR1_CoSO4_CN_Xinjiang!F76 -> Cobalt | G12: technosphere
A13: ='PR2_CoSO4_CD-CN_Tongxiang'!A67 -> Cu/Co ore mining in DRC and CoSO4 production in China/Tongxiang | B13: ='PR2_CoSO4_CD-CN_Tongxiang'!B67 -> CoSO4 | C13: CN | D13: 0.15164499 | E13: ='PR2_CoSO4_CD-CN_Tongxiang'!E67 -> kilogram | F13: ='PR2_CoSO4_CD-CN_Tongxiang'!F67 -> Cobalt | G13: technosphere
A14: ='PR3_Co3O4_CD-CN_Quzhou'!A28 -> Cu/Co ore mining in DRC and Co3O4 production in China/Quzhou | B14: ='PR3_Co3O4_CD-CN_Quzhou'!B28 -> Co3O4 | C14: CN | D14: 0.15679843 | E14: ='PR3_Co3O4_CD-CN_Quzhou'!E28 -> kilogram | F14: ='PR3_Co3O4_CD-CN_Quzhou'!F28 -> Cobalt | G14: technosphere
A15: ='PR4_Co_CD-CN-GLO'!A20 -> Cu/Co ore mining in DRC and Co production | B15: ='PR4_Co_CD-CN-GLO'!B20 -> Co metal | C15: CN | D15: 0.51000416 | E15: ='PR4_Co_CD-CN-GLO'!E20 -> kilogram | F15: ='PR4_Co_CD-CN-GLO'!F20 -> Cobalt | G15: technosphere
A16: =PR5_Co_AU_HPAL_Laterites!A28 -> Co recovery from laterite ore mining and Ni class 1 production in Australia from HPAL | B16: =PR5_Co_AU_HPAL_Laterites!B28 -> Co | C16: =PR5_Co_AU_HPAL_Laterites!C28 -> AU | D16: 0.0035464535 | E16: =PR5_Co_AU_HPAL_Laterites!E28 -> kilogram | F16: =PR5_Co_AU_HPAL_Laterites!F28 -> Cobalt | G16: technosphere
A17: =PR6_Co_AU_FlashSmelting!A49 -> Co recovery from sulfide ore mining and Ni class 1 production in Australia through Flash Smelting | B17: =PR6_Co_AU_FlashSmelting!B49 -> Co | C17: =PR6_Co_AU_FlashSmelting!C49 -> AU | D17: 0.02009657 | E17: =PR6_Co_AU_FlashSmelting!E49 -> kilogram | F17: =PR6_Co_AU_FlashSmelting!F49 -> Cobalt | G17: technosphere
A18: ='PR7_Co(OH)2_Europe_Recycling'!A103 -> Co(OH)2 production in Europe through hardmetal scrap recycling | B18: ='PR7_Co(OH)2_Europe_Recycling'!B103 -> Co(OH)2 | C18: ='PR7_Co(OH)2_Europe_Recycling'!C103 -> Europe witout Switzerland | D18: 0.0062643908 | E18: ='PR7_Co(OH)2_Europe_Recycling'!E103 -> kilogram | F18: ='PR7_Co(OH)2_Europe_Recycling'!F103 -> Cobalt | G18: technosphere
A20: Activity | B20: Cobalt (Co) global market (Co content)
A21: reference product | B21: Co content
A22: location | B22: GLO
A23: amount | B23: 1
A24: unit | B24: kilogram
A25: comment | B25: Activity expressed for 1 kg Co contained
A26: Exchanges
A27: name | B27: reference product | C27: location | D27: amount | E27: unit | F27: database | G27: type | H27: categories | I27: uncertainty type | J27: pedigree | K27: loc | L27: scale | M27: minimum | N27: maximum
A28: =B20 -> Cobalt (Co) global market (Co content) | B28: =B21 -> Co content | C28: =B22 -> GLO | D28: 1 | E28: =B24 -> kilogram | F28: =F11 -> Cobalt | G28: production
A29: =PR1_CoSO4_CN_Xinjiang!A87 -> Ni/Cu/Co ore mining in China/Xinjiang and CoSO4 production in Southeastern China (Co content) | B29: =PR1_CoSO4_CN_Xinjiang!B87 -> CoSO4 (Co content) | C29: =PR1_CoSO4_CN_Xinjiang!C87 -> CN | D29: 0.15164499 | E29: =PR1_CoSO4_CN_Xinjiang!E87 -> kilogram | F29: =PR1_CoSO4_CN_Xinjiang!F87 -> Cobalt | G29: technosphere
A30: ='PR2_CoSO4_CD-CN_Tongxiang'!A80 -> Cu/Co ore mining in DRC and CoSO4 production in China/Tongxiang (Co content) | B30: ='PR2_CoSO4_CD-CN_Tongxiang'!B80 -> CoSO4 (Co content) | C30: CN | D30: 0.15164499 | E30: ='PR2_CoSO4_CD-CN_Tongxiang'!E80 -> kilogram | F30: ='PR2_CoSO4_CD-CN_Tongxiang'!F80 -> Cobalt | G30: technosphere
A31: ='PR3_Co3O4_CD-CN_Quzhou'!A42 -> Cu/Co ore mining in DRC and Co3O4 production in China/Quzhou (Co content) | B31: ='PR3_Co3O4_CD-CN_Quzhou'!B42 -> Co3O4 (Co content) | C31: CN | D31: 0.15679843 | E31: ='PR3_Co3O4_CD-CN_Quzhou'!E42 -> kilogram | F31: ='PR3_Co3O4_CD-CN_Quzhou'!F42 -> Cobalt | G31: technosphere
A32: ='PR4_Co_CD-CN-GLO'!A20 -> Cu/Co ore mining in DRC and Co production | B32: ='PR4_Co_CD-CN-GLO'!B20 -> Co metal | C32: CN | D32: 0.51000416 | E32: ='PR4_Co_CD-CN-GLO'!E20 -> kilogram | F32: ='PR4_Co_CD-CN-GLO'!F20 -> Cobalt | G32: technosphere
A33: =+PR5_Co_AU_HPAL_Laterites!A28 -> Co recovery from laterite ore mining and Ni class 1 production in Australia from HPAL | B33: =+PR5_Co_AU_HPAL_Laterites!B28 -> Co | C33: =+PR5_Co_AU_HPAL_Laterites!C28 -> AU | D33: 0.0035464535 | E33: =+PR5_Co_AU_HPAL_Laterites!E28 -> kilogram | F33: =+PR5_Co_AU_HPAL_Laterites!F28 -> Cobalt | G33: technosphere
A34: =PR6_Co_AU_FlashSmelting!A49 -> Co recovery from sulfide ore mining and Ni class 1 production in Australia through Flash Smelting | B34: =PR6_Co_AU_FlashSmelting!B49 -> Co | C34: =PR6_Co_AU_FlashSmelting!C49 -> AU | D34: 0.02009657 | E34: =PR6_Co_AU_FlashSmelting!E49 -> kilogram | F34: =PR6_Co_AU_FlashSmelting!F49 -> Cobalt | G34: technosphere
A35: ='PR7_Co(OH)2_Europe_Recycling'!A118 -> Co(OH)2 production in Europe through hardmetal scrap recycling (Co content) | B35: ='PR7_Co(OH)2_Europe_Recycling'!B118 -> Co(OH)2 (Co content) | C35: ='PR7_Co(OH)2_Europe_Recycling'!C118 -> Europe witout Switzerland | D35: 0.0062643908 | E35: ='PR7_Co(OH)2_Europe_Recycling'!E118 -> kilogram | F35: ='PR7_Co(OH)2_Europe_Recycling'!F118 -> Cobalt | G35: technosphere

Sheet PR1_CoSO4_CN_Xinjiang
A1: Activity | B1: [M+C+P] Cobalt sulfate (CoSO4) production (Xinjiang)
A2: reference product | B2: CoSO4
A3: location | B3: CN
A4: amount | B4: 1
A5: unit | B5: kilogram
A6: comment | B6: This unit process is allocated, but with unknown allocation factors (not provided in the original data source).
A7: Exchanges
A8: name | B8: reference product | C8: location | D8: amount | E8: unit | F8: database | G8: type | H8: categories | I8: uncertainty type | J8: pedigree | K8: loc | L8: scale | M8: minimum | N8: maximum
A9: =B1 -> [M+C+P] Cobalt sulfate (CoSO4) production (Xinjiang) | B9: =B2 -> CoSO4 | C9: =B3 -> CN | D9: 1 | E9: =B5 -> kilogram | F9: =Co_Market_GLO!B1 -> Cobalt | G9: production
A10: market for transport, freight, lorry >32 metric ton, EURO5 | B10: transport, freight, lorry >32 metric ton, EURO5 | C10: RoW | D10: 1.53066 | E10: ton kilometer | F10: ecoinvent 3.10 cutoff | G10: technosphere | J10: (2,4,2,2,2)
A11: market for sulfuric acid | B11: sulfuric acid | C11: RoW | D11: 0.38 | E11: kilogram | F11: ecoinvent 3.10 cutoff | G11: technosphere | J11: (1,2,1,1,1)
A12: market for soda ash, dense | B12: soda ash, dense | C12: GLO | D12: 0.86 | E12: kilogram | F12: ecoinvent 3.10 cutoff | G12: technosphere | J12: (1,2,1,1,1)
A13: market for limestone, crushed, washed | B13: limestone, crushed, washed | C13: RoW | D13: 0.05 | E13: kilogram | F13: ecoinvent 3.10 cutoff | G13: technosphere | J13: (1,2,1,1,1)
A14: market for hydrochloric acid, without water, in 30% solution state | B14: hydrochloric acid, without water, in 30% solution state | C14: RoW | D14: 1.19 | E14: kilogram | F14: ecoinvent 3.10 cutoff | G14: technosphere | J14: (1,2,1,1,1)
A15: market for sodium hydroxide, without water, in 50% solution state | B15: sodium hydroxide, without water, in 50% solution state | C15: RoW | D15: 0.4 | E15: kilogram | F15: ecoinvent 3.10 cutoff | G15: technosphere | J15: (2,4,3,2,2)
A16: market for ammonia, anhydrous, liquid | B16: ammonia, anhydrous, liquid | C16: RoW | D16: 0.0076 | E16: kilogram | F16: ecoinvent 3.10 cutoff | G16: technosphere | J16: (1,2,1,1,1)
A17: market for ammonium bicarbonate | B17: ammonium bicarbonate | C17: RoW | D17: 0.24 | E17: kilogram | F17: ecoinvent 3.10 cutoff | G17: technosphere | J17: (1,2,1,1,1)
A18: market for kerosene | B18: kerosene | C18: RoW | D18: 0.00513 | E18: kilogram | F18: ecoinvent 3.10 cutoff | G18: technosphere | J18: (1,2,1,1,1)
A19: market group for electricity, medium voltage | B19: electricity, medium voltage | C19: CN | D19: 11.5245 | E19: kilowatt hour | F19: ecoinvent 3.10 cutoff | G19: technosphere | J19: (2,4,3,2,2)
A20: market for transport, pipeline, long distance, natural gas | B20: transport, pipeline, long distance, natural gas | C20: RoW | D20: 0.07111 | E20: ton kilometer | F20: ecoinvent 3.10 cutoff | G20: technosphere | J20: (1,2,1,1,1)
A21: market for quicklime, milled, packed | B21: quicklime, milled, packed | C21: RoW | D21: 0.51 | E21: kilogram | F21: ecoinvent 3.10 cutoff | G21: technosphere | J21: (1,2,1,1,1)
... A40: market for hazardous waste, for incineration | B40: hazardous waste, for incineration | C40: RoW | D40: -0.00106 | E40: kilogram | F40: ecoinvent 3.10 cutoff | G40: technosphere | J40: (2,4,3,3,4)
A41: Occupation, mineral extraction site | D41: 0.02223 | E41: square meter-year | F41: biosphere3 | G41: biosphere | H41: natural resource::land | J41: (1,3,1,1,1)
A42: Cobalt | D42: 0.21 | E42: kilogram | F42: biosphere3 | G42: biosphere | H42: natural resource::in ground | J42: (1,4,3,2,2)
A43: Water, unspecified natural origin | D43: 0.10414 | E43: cubic meter | F43: biosphere3 | G43: biosphere | H43: natural resource::in ground | J43: (1,2,1,1,1)
A44: Suspended solids, unspecified | D44: 4.201e-05 | E44: kilogram | F44: biosphere3 | G44: biosphere | H44: water | J44: (1,4,2,2,1)
A45: COD, Chemical Oxygen Demand | D45: 7.33e-05 | E45: kilogram | F45: biosphere3 | G45: biosphere | H45: water | J45: (1,4,2,2,1)
A46: Oils, unspecified | D46: 4.13e-06 | E46: kilogram | F46: biosphere3 | G46: biosphere | H46: water | J46: (1,4,2,2,1)
A47: Nickel II | D47: 1.33e-06 | E47: kilogram | F47: biosphere3 | G47: biosphere | H47: water | J47: (1,4,2,2,1)
A48: Arsenic ion | D48: 9.58e-06 | E48: kilogram | F48: biosphere3 | G48: biosphere | H48: water | J48: (1,4,2,2,1)
A49: Mercury II | D49: 2.9e-07 | E49: kilogram | F49: biosphere3 | G49: biosphere | H49: water | J49: (1,4,2,2,1)
A50: Cobalt II | D50: 3.8e-07 | E50: kilogram | F50: biosphere3 | G50: biosphere | H50: water | J50: (1,4,2,2,1)
A51: Copper ion | D51: 7e-08 | E51: kilogram | F51: biosphere3 | G51: biosphere | H51: water | J51: (1,4,2,2,1)
A52: Manganese II | D52: 4.52e-06 | E52: kilogram | F52: biosphere3 | G52: biosphere | H52: water | J52: (1,4,2,2,1)
... A66: Nickel II | D66: 0.00010884 | E66: kilogram | F66: biosphere3 | G66: biosphere | H66: soil | J66: (1,2,1,1,1)
A68: Activity | B68: Ni/Cu/Co ore mining in China/Xinjiang and CoSO4 production in Southeastern China
A69: reference product | B69: CoSO4
A70: location | B70: CN
A71: amount | B71: 1
A72: unit | B72: kilogram
...

Sheet PR2_CoSO4_CD-CN_Tongxiang
A1: Activity | B1: [M] Copper (Cu) ore mining (Cobalt production)
A2: reference product | B2: Cu ore
A3: location | B3: CD
A4: amount | B4: 1
A5: unit | B5: kilogram
A6: comment | B6: n/a
A7: Exchanges
A8: name | B8: reference product | C8: location | D8: amount | E8: unit | F8: database | G8: type | H8: categories | I8: uncertainty type | J8: pedigree | K8: loc | L8: scale | M8: minimum | N8: maximum
A9: =B1 -> [M] Copper (Cu) ore mining (Cobalt production) | B9: =B2 -> Cu ore | C9: =B3 -> CD | D9: 1 | E9: =B5 -> kilogram | F9: =Co_Market_GLO!B1 -> Cobalt | G9: production
A10: market for diesel, burned in building machine | B10: diesel, burned in building machine | C10: GLO | D10: 0.5868 | E10: megajoule | F10: ecoinvent 3.10 cutoff | G10: technosphere | J10: (1,5,3,1,1)
A11: Water, unspecified natural origin | D11: 0.00017147907 | E11: cubic meter | F11: biosphere3 | G11: biosphere | H11: natural resource::in ground | J11: (1,5,3,1,1)
A12: Particulate Matter, > 2.5 um and < 10um | D12: 0.00144 | E12: kilogram | F12: biosphere3 | G12: biosphere | H12: air | J12: (1,5,3,1,1)
A13: Particulate Matter, < 2.5 um | D13: 0.000148 | E13: kilogram | F13: biosphere3 | G13: biosphere | H13: air | J13: (1,5,3,1,1)
A14: Cobalt | D14: 0.0032 | E14: kilogram | F14: biosphere3 | G14: biosphere | H14: natural resource::in ground | J14: (1,5,3,1,1)
A16: Activity | B16: [C+P] Cobalt hydroxide (Co(OH)2) production - Hydrometallurgy
A17: reference product | B17: Co(OH)2
A18: location | B18: CD
A19: amount | B19: 1
A20: unit | B20: kilogram
A21: comment | B21: Allocated unit process, considering as allocation factors (AF): 72% for Cu (1 kg) and 28% for Co (0.08 kg). MgO input is not subject to this allocation (only used for Co precipitation).
A22: Exchanges
A23: name | B23: reference product | C23: location | D23: amount | E23: unit | F23: database | G23: type | H23: categories | I23: uncertainty type | J23: pedigree | K23: loc | L23: scale | M23: minimum | N23: maximum
A24: =B16 -> [C+P] Cobalt hydroxide (Co(OH)2) production - Hydrometallurgy | B24: =B17 -> Co(OH)2 | C24: =B18 -> CD | D24: 1 | E24: kilogram | F24: =F9 -> Cobalt | G24: production
A25: market for electricity, medium voltage | B25: electricity, medium voltage | C25: CD | D25: 8.345257 | E25: kilowatt hour | F25: ecoinvent 3.10 cutoff | G25: technosphere | J25: (1,5,3,1,1)
A26: market for sulfur | B26: sulfur | C26: GLO | D26: 3.0608998 | E26: kilogram | F26: ecoinvent 3.10 cutoff | G26: technosphere | J26: (1,5,3,1,1)
A27: market for limestone, crushed, washed | B27: limestone, crushed, washed | C27: RoW | D27: 3.9822131 | E27: kilogram | F27: ecoinvent 3.10 cutoff | G27: technosphere | J27: (1,5,3,1,1)
A28: market for lime, packed | B28: lime, packed | C28: RoW | D28: 1.4502388 | E28: kilogram | F28: ecoinvent 3.10 cutoff | G28: technosphere | J28: (1,5,3,1,1)
A29: market for sodium hydroxide, without water, in 50% solution state | B29: sodium hydroxide, without water, in 50% solution state | C29: RoW | D29: 0.17474923 | E29: kilogram | F29: ecoinvent 3.10 cutoff | G29: technosphere | J29: (1,5,3,1,1)
A30: market for magnesium oxide | B30: magnesium oxide | C30: GLO | D30: 0.090348718 | E30: kilogram | F30: ecoinvent 3.10 cutoff | G30: technosphere | J30: (1,5,3,1,1)
A31: Water, unspecified natural origin | D31: 0.14462802 | E31: cubic meter | F31: biosphere3 | G31: biosphere | H31: natural resource::in ground | J31: (1,5,3,1,1)
A32: Sulfur oxides | D32: 0.027920252 | E32: kilogram | F32: biosphere3 | G32: biosphere | H32: air | J32: (1,5,3,1,1)
A34: Activity | B34: [P] Cobalt sulfate (CoSO4) production (Tongxiang)
A35: reference product | B35: CoSO4
A36: location | B36: CN
A37: amount | B37: 1
A38: unit | B38: kilogram
A39: comment | B39: n/a
A40: Exchanges
A41: name | B41: reference product | C41: location | D41: amount | E41: unit | F41: database | G41: type | H41: categories | I41: uncertainty type | J41: pedigree | K41: loc | L41: scale | M41: minimum | N41: maximum
A42: =B34 -> [P] Cobalt sulfate (CoSO4) production (Tongxiang) | B42: =B35 -> CoSO4 | C42: =B36 -> CN | D42: 1 | E42: =B38 -> kilogram | F42: =F24 -> Cobalt | G42: production
...

Sheet PR3_Co3O4_CD-CN_Quzhou
A1: Activity | B1: [P] Cobalt (II,III) oxide (Co3O4) production (Quzhou)
A2: reference product | B2: Co3O4
A3: location | B3: CN
A4: amount | B4: 1
A5: unit | B5: kilogram
A6: comment | B6: n/a
A7: Exchanges
A8: name | B8: reference product | C8: location | D8: amount | E8: unit | F8: database | G8: type | H8: categories | I8: uncertainty type | J8: pedigree | K8: loc | L8: scale | M8: minimum | N8: maximum
A9: =B1 -> [P] Cobalt (II,III) oxide (Co3O4) production (Quzhou) | B9: =B2 -> Co3O4 | C9: =B3 -> CN | D9: 1 | E9: =B5 -> kilogram | F9: =Co_Market_GLO!B1 -> Cobalt | G9: production
A10: market for natural gas, high pressure | B10: natural gas, high pressure | C10: CN | D10: 0.052442857 | E10: cubic meter | F10: ecoinvent 3.10 cutoff | G10: technosphere | J10: (1,1,3,1,1)
A11: market for steam, in chemical industry | B11: steam, in chemical industry | C11: RoW | D11: 4.1954286 | E11: kilogram | F11: ecoinvent 3.10 cutoff | G11: technosphere | J11: (1,1,3,1,1)
A12: market group for electricity, medium voltage | B12: electricity, medium voltage | C12: CN | D12: 0.025172571 | E12: kilowatt hour | F12: ecoinvent 3.10 cutoff | G12: technosphere | J12: (1,1,3,1,1)
A13: market for cobalt acetate | B13: cobalt acetate | C13: GLO | D13: 1.666634 | E13: kilogram | F13: ecoinvent 3.10 cutoff | G13: technosphere | J13: (1,1,3,1,1)
A14: market for sodium hydroxide, without water, in 50% solution state | B14: sodium hydroxide, without water, in 50% solution state | C14: RoW | D14: 1.4684 | E14: kilogram | F14: ecoinvent 3.10 cutoff | G14: technosphere | J14: (1,1,3,1,1)
A15: market for EDTA, ethylenediaminetetraacetic acid | B15: EDTA, ethylenediaminetetraacetic acid | C15: GLO | D15: 0.0025172571 | E15: kilogram | F15: ecoinvent 3.10 cutoff | G15: technosphere | J15: (1,1,3,1,1)
A16: market for ammonium bicarbonate | B16: ammonium bicarbonate | C16: RoW | D16: 1.35827 | E16: kilogram | F16: ecoinvent 3.10 cutoff | G16: technosphere | J16: (1,1,3,1,1)
A17: Water, unspecified natural origin | D17: 0.010069029 | E17: cubic meter | F17: biosphere3 | G17: biosphere | H17: natural resource::in ground | J17: (1,1,3,1,1)
A18: Carbon dioxide, fossil | D18: 0.92672296 | E18: kilogram | F18: biosphere3 | G18: biosphere | H18: air | J18: (1,1,3,1,1)
A20: Activity | B20: Cu/Co ore mining in DRC and Co3O4 production in China/Quzhou
A21: reference product | B21: Co3O4
A22: location | B22: CN
A23: amount | B23: 1
A24: unit | B24: kilogram
A25: comment | B25: Applied AF: "Cu ore" input = 28%.
A26: Exchanges
A27: name | B27: reference product | C27: location | D27: amount | E27: unit | F27: database | G27: type | H27: categories | I27: uncertainty type | J27: pedigree | K27: loc | L27: scale | M27: minimum | N27: maximum
A28: =B20 -> Cu/Co ore mining in DRC and Co3O4 production in China/Quzhou | B28: =B21 -> Co3O4 | C28: CN | D28: 1 | E28: =B24 -> kilogram | F28: =F9 -> Cobalt | G28: production
A29: =A9 -> [P] Cobalt (II,III) oxide (Co3O4) production (Quzhou) | B29: =B9 -> Co3O4 | C29: =C9 -> CN | D29: 1 | E29: =E9 -> kilogram | F29: =F9 -> Cobalt | G29: technosphere
A30: ='PR2_CoSO4_CD-CN_Tongxiang'!A42 -> [P] Cobalt sulfate (CoSO4) production (Tongxiang) | B30: ='PR2_CoSO4_CD-CN_Tongxiang'!B42 -> CoSO4 | C30: ='PR2_CoSO4_CD-CN_Tongxiang'!C42 -> CN | D30: 1.490426 | E30: ='PR2_CoSO4_CD-CN_Tongxiang'!E42 -> kilogram | F30: ='PR2_CoSO4_CD-CN_Tongxiang'!F42 -> Cobalt | G30: technosphere
A31: ='PR2_CoSO4_CD-CN_Tongxiang'!A24 -> [C+P] Cobalt hydroxide (Co(OH)2) production - Hydrometallurgy | B31: ='PR2_CoSO4_CD-CN_Tongxiang'!B24 -> Co(OH)2 | C31: ='PR2_CoSO4_CD-CN_Tongxiang'!C24 -> CD | D31: 1.6190105 | E31: ='PR2_CoSO4_CD-CN_Tongxiang'!E24 -> kilogram | F31: ='PR2_CoSO4_CD-CN_Tongxiang'!F24 -> Cobalt | G31: technosphere
A32: ='PR2_CoSO4_CD-CN_Tongxiang'!A9 -> [M] Copper (Cu) ore mining (Cobalt production) | B32: ='PR2_CoSO4_CD-CN_Tongxiang'!B9 -> Cu ore | C32: ='PR2_CoSO4_CD-CN_Tongxiang'!C9 -> CD | D32: 164.85969 | E32: ='PR2_CoSO4_CD-CN_Tongxiang'!E9 -> kilogram | F32: ='PR2_CoSO4_CD-CN_Tongxiang'!F9 -> Cobalt | G32: technosphere
A34: Activity | B34: Cu/Co ore mining in DRC and Co3O4 production in China/Quzhou (Co content)
A35: reference product | B35: Co3O4 (Co content)
A36: location | B36: CN
A37: amount | B37: 1
A38: unit | B38: kilogram
A39: comment | B39: Activity expressed for 1 kg Co contained. Applied AF: "Cu ore" input = 28%.
A40: Exchanges
A41: name | B41: reference product | C41: location | D41: amount | E41: unit | F41: database | G41: type | H41: categories | I41: uncertainty type | J41: pedigree | K41: loc | L41: scale | M41: minimum | N41: maximum
A42: =B34 -> Cu/Co ore mining in DRC and Co3O4 production in China/Quzhou (Co content) | B42: =B35 -> Co3O4 (Co content) | C42: CN | D42: 1 | E42: =B38 -> kilogram | F42: =F28 -> Cobalt | G42: production
...

Sheet PR4_Co_CD-CN-GLO
A1: Activity | B1: [R] Cobalt (Co) metal production
A2: reference product | B2: Co metal
A3: location | B3: GLO
A4: amount | B4: 1
A5: unit | B5: kilogram
A6: comment | B6: n/a
A7: Exchanges
A8: name | B8: reference product | C8: location | D8: amount | E8: unit | F8: database | G8: type | H8: categories | I8: uncertainty type | J8: pedigree | K8: loc | L8: scale | M8: minimum | N8: maximum
A9: =B1 -> [R] Cobalt (Co) metal production | B9: =B2 -> Co metal | C9: =B3 -> GLO | D9: 1 | E9: =B5 -> kilogram | F9: =Co_Market_GLO!B1 -> Cobalt | G9: production
A10: market group for electricity, medium voltage | B10: electricity, medium voltage | C10: CN | D10: 3.4 | E10: kilowatt hour | F10: ecoinvent 3.10 cutoff | G10: technosphere | J10: (4,5,4,3,3)
A12: Activity | B12: Cu/Co ore mining in DRC and Co production
A13: reference product | B13: Co metal
A14: location | B14: CN
A15: amount | B15: 1
A16: unit | B16: kilogram
A17: comment | B17: Applied AF: "Cu ore" input = 28%.
A18: Exchanges
A19: name | B19: reference product | C19: location | D19: amount | E19: unit | F19: database | G19: type | H19: categories | I19: uncertainty type | J19: pedigree | K19: loc | L19: scale | M19: minimum | N19: maximum
A20: =B12 -> Cu/Co ore mining in DRC and Co production | B20: =B13 -> Co metal | C20: CN | D20: 1 | E20: =B16 -> kilogram | F20: =F9 -> Cobalt | G20: production
A21: =A9 -> [R] Cobalt (Co) metal production | B21: =B9 -> Co metal | C21: =C9 -> GLO | D21: 1 | E21: =E9 -> kilogram | F21: =F9 -> Cobalt | G21: technosphere
A22: ='PR2_CoSO4_CD-CN_Tongxiang'!A68 -> [P] Cobalt sulfate (CoSO4) production (Tongxiang) | B22: ='PR2_CoSO4_CD-CN_Tongxiang'!B68 -> CoSO4 | C22: ='PR2_CoSO4_CD-CN_Tongxiang'!C68 -> CN | D22: 2.63 | E22: ='PR2_CoSO4_CD-CN_Tongxiang'!E68 -> kilogram | F22: ='PR2_CoSO4_CD-CN_Tongxiang'!F68 -> Cobalt | G22: technosphere
A23: ='PR2_CoSO4_CD-CN_Tongxiang'!A69 -> [C+P] Cobalt hydroxide (Co(OH)2) production - Hydrometallurgy | B23: ='PR2_CoSO4_CD-CN_Tongxiang'!B69 -> Co(OH)2 | C23: ='PR2_CoSO4_CD-CN_Tongxiang'!C69 -> CD | D23: 2.8568997 | E23: ='PR2_CoSO4_CD-CN_Tongxiang'!E69 -> kilogram | F23: ='PR2_CoSO4_CD-CN_Tongxiang'!F69 -> Cobalt | G23: technosphere
A24: ='PR2_CoSO4_CD-CN_Tongxiang'!A70 -> [M] Copper (Cu) ore mining (Cobalt production) | B24: ='PR2_CoSO4_CD-CN_Tongxiang'!B70 -> Cu ore | C24: ='PR2_CoSO4_CD-CN_Tongxiang'!C70 -> CD | D24: 290.91078 | E24: ='PR2_CoSO4_CD-CN_Tongxiang'!E70 -> kilogram | F24: ='PR2_CoSO4_CD-CN_Tongxiang'!F70 -> Cobalt | G24: technosphere

Sheet PR5_Co_AU_HPAL_Laterites
A1: Activity | B1: [M+C+P+R] Cobalt (Co) production - High Pressure Acid Leaching (HPAL)
A2: reference product | B2: Co
A3: location | B3: AU
A4: amount | B4: 1
A5: unit | B5: kilogram
A6: comment | B6: Allocated unit process, considering as allocation factors (AF): 84% for Ni (1 kg) and 16% for Co (0.07 kg). The co-produced ammonium sulfate is dealt through substitution.
A7: Exchanges
A8: name | B8: reference product | C8: location | D8: amount | E8: unit | F8: database | G8: type | H8: categories | I8: uncertainty type | J8: pedigree | K8: loc | L8: scale | M8: minimum | N8: maximum
A9: =B1 -> [M+C+P+R] Cobalt (Co) production - High Pressure Acid Leaching (HPAL) | B9: =B2 -> Co | C9: =B3 -> AU | D9: 1 | E9: =B5 -> kilogram | F9: =Co_Market_GLO!B1 -> Cobalt | G9: production
A10: market for ammonium sulfate | B10: ammonium sulfate | C10: RoW | D10: -4.8228571 | E10: kilogram | F10: ecoinvent 3.10 cutoff | G10: technosphere | J10: (1,5,3,1,1)
A11: market group for electricity, medium voltage | B11: electricity, medium voltage | C11: GLO | D11: 22.910529 | E11: kilowatt hour | F11: ecoinvent 3.10 cutoff | G11: technosphere | J11: (4,5,4,5,5)
A12: market group for heat, district or industrial, natural gas | B12: heat, district or industrial, natural gas | C12: GLO | D12: 67.838075 | E12: megajoule | F12: ecoinvent 3.10 cutoff | G12: technosphere | J12: (4,5,4,5,5)
A13: market for diesel, burned in building machine | B13: diesel, burned in building machine | C13: GLO | D13: 17.093545 | E13: megajoule | F13: ecoinvent 3.10 cutoff | G13: technosphere | J13: (4,5,4,5,5)
A14: market for transport, freight, lorry >32 metric ton, EURO6 | B14: transport, freight, lorry >32 metric ton, EURO6 | C14: RoW | D14: 2.2910529 | E14: ton kilometer | F14: ecoinvent 3.10 cutoff | G14: technosphere | J14: (4,5,4,5,5)
A15: market for limestone, crushed, washed | B15: limestone, crushed, washed | C15: RoW | D15: 36.106993 | E15: kilogram | F15: ecoinvent 3.10 cutoff | G15: technosphere | J15: (4,5,4,5,5)
A16: market for ammonia, anhydrous, liquid | B16: ammonia, anhydrous, liquid | C16: RoW | D16: 0.16953791 | E16: kilogram | F16: ecoinvent 3.10 cutoff | G16: technosphere | J16: (1,5,3,1,1)
A17: market for sulfur | B17: sulfur | C17: GLO | D17: 30.218987 | E17: kilogram | F17: ecoinvent 3.10 cutoff | G17: technosphere | J17: (1,5,3,1,1)
A18: Water, unspecified natural origin | D18: 3.1868545 | E18: cubic meter | F18: biosphere3 | G18: biosphere | H18: natural resource::in ground | J18: (4,5,4,5,5)
A20: Activity | B20: Co recovery from laterite ore mining and Ni class 1 production in Australia from HPAL
A21: reference product | B21: Co
A22: location | B22: AU
A23: amount | B23: 1
A24: unit | B24: kilogram
A25: comment | B25: n/a
A26: Exchanges
A27: name | B27: reference product | C27: location | D27: amount | E27: unit | F27: database | G27: type | H27: categories | I27: uncertainty type | J27: pedigree | K27: loc | L27: scale | M27: minimum | N27: maximum
A28: =B20 -> Co recovery from laterite ore mining and Ni class 1 production in Australia from HPAL | B28: =B21 -> Co | C28: =B22 -> AU | D28: 1 | E28: =B24 -> kilogram | F28: =F9 -> Cobalt | G28: production
A29: =A9 -> [M+C+P+R] Cobalt (Co) production - High Pressure Acid Leaching (HPAL) | B29: =B9 -> Co | C29: =C9 -> AU | D29: 1 | E29: =E9 -> kilogram | F29: =F9 -> Cobalt | G29: technosphere

Sheet PR6_Co_AU_FlashSmelting
A1: Activity | B1: [M+C] Nickel (Ni) ore mining and concentration
A2: reference product | B2: Ni concentrate
A3: location | B3: AU
A4: amount | B4: 1
A5: unit | B5: kilogram
A6: comment | B6: In the absence of detailed mass balance for this intermediary product, the reference flow of this unit process is set by default at 1 kg, while the input and ouput flows of the inventory are actually scaled to 1 kg of Co, as final output of this production route.
A7: Exchanges
A8: name | B8: reference product | C8: location | D8: amount | E8: unit | F8: database | G8: type | H8: categories | I8: uncertainty type | J8: pedigree | K8: loc | L8: scale | M8: minimum | N8: maximum
A9: =B1 -> [M+C] Nickel (Ni) ore mining and concentration | B9: =B2 -> Ni concentrate | C9: =B3 -> AU | D9: 1 | E9: =B5 -> kilogram | F9: =Co_Market_GLO!B1 -> Cobalt | G9: production
A10: market for diesel, burned in building machine | B10: diesel, burned in building machine | C10: GLO | D10: 235.57451 | E10: megajoule | F10: ecoinvent 3.10 cutoff | G10: technosphere | J10: (4.0,5.0,5.0,5.0,5.0)
A11: market for electricity, medium voltage | B11: electricity, medium voltage | C11: AU | D11: 142.27952 | E11: kilowatt hour | F11: ecoinvent 3.10 cutoff | G11: technosphere | J11: (4.0,5.0,5.0,5.0,5.0)
A12: market for electricity, medium voltage | B12: electricity, medium voltage | C12: AU | D12: 190.95246 | E12: kilowatt hour | F12: ecoinvent 3.10 cutoff | G12: technosphere | J12: (4.0,5.0,5.0,5.0,5.0)
A13: market for natural gas, high pressure | B13: natural gas, high pressure | C13: RoW | D13: 13.905705 | E13: cubic meter | F13: ecoinvent 3.10 cutoff | G13: technosphere | J13: (1.0,1.0,2.0,1.0,1.0)
A14: Cobalt | D14: 4.4681255 | E14: kilogram | F14: biosphere3 | G14: biosphere | H14: natural resource::in ground | J14: (4.0,5.0,5.0,5.0,5.0)
A16: Activity | B16: [P+R] Cobalt (Co) production - Flash Smelting
A17: reference product | B17: Co
A18: location | B18: AU
A19: amount | B19: 1
A20: unit | B20: kilogram
A21: comment | B21: Allocated unit process, considering as allocation factors (AF): 85% for Ni (1 kg) and 15% for Co (0.016 kg).
A22: Exchanges
A23: name | B23: reference product | C23: location | D23: amount | E23: unit | F23: database | G23: type | H23: categories | I23: uncertainty type | J23: pedigree | K23: loc | L23: scale | M23: minimum | N23: maximum
A24: =B16 -> [P+R] Cobalt (Co) production - Flash Smelting | B24: =B17 -> Co | C24: =B18 -> AU | D24: 1 | E24: kilogram | F24: =F9 -> Cobalt | G24: production
A25: market for diesel, burned in building machine | B25: diesel, burned in building machine | C25: GLO | D25: 37.232177 | E25: megajoule | F25: ecoinvent 3.10 cutoff | G25: technosphere | J25: (4.0,5.0,5.0,5.0,5.0)
A26: market for diesel, burned in building machine | B26: diesel, burned in building machine | C26: GLO | D26: 59.571484 | E26: megajoule | F26: ecoinvent 3.10 cutoff | G26: technosphere | J26: (1.0,1.0,2.0,1.0,1.0)
A27: market for hard coal | B27: hard coal | C27: AU | D27: 3.7507971 | E27: kilogram | F27: ecoinvent 3.10 cutoff | G27: technosphere | J27: (1.0,1.0,2.0,1.0,1.0)
A28: market for compressed air, 800 kPa gauge | B28: compressed air, 800 kPa gauge | C28: RoW | D28: 92.45531 | E28: cubic meter | F28: ecoinvent 3.10 cutoff | G28: technosphere | J28: (1.0,1.0,2.0,1.0,1.0)
A29: market for compressed air, 800 kPa gauge | B29: compressed air, 800 kPa gauge | C29: RoW | D29: 3.1440505 | E29: cubic meter | F29: ecoinvent 3.10 cutoff | G29: technosphere | J29: (1.0,1.0,2.0,1.0,1.0)
A30: market for activated silica | B30: activated silica | C30: GLO | D30: 20.555839 | E30: kilogram | F30: ecoinvent 3.10 cutoff | G30: technosphere | J30: (1.0,1.0,2.0,1.0,1.0)
A31: market for compressed air, 800 kPa gauge | B31: compressed air, 800 kPa gauge | C31: RoW | D31: 22.633487 | E31: cubic meter | F31: ecoinvent 3.10 cutoff | G31: technosphere | J31: (1.0,1.0,2.0,1.0,1.0)
A32: market for activated silica | B32: activated silica | C32: GLO | D32: 2.6935871 | E32: kilogram | F32: ecoinvent 3.10 cutoff | G32: technosphere | J32: (1.0,1.0,2.0,1.0,1.0)
A33: market for diesel, burned in building machine | B33: diesel, burned in building machine | C33: GLO | D33: 9.5148898 | E33: megajoule | F33: ecoinvent 3.10 cutoff | G33: technosphere | J33: (4.0,5.0,5.0,5.0,5.0)
A34: market for coke | B34: coke | C34: RoW | D34: 83.083834 | E34: megajoule | F34: ecoinvent 3.10 cutoff | G34: technosphere | J34: (1.0,1.0,2.0,1.0,1.0)
A35: market for electricity, medium voltage | B35: electricity, medium voltage | C35: AU | D35: 6.3892255 | E35: kilowatt hour | F35: ecoinvent 3.10 cutoff | G35: technosphere | J35: (1.0,1.0,2.0,1.0,1.0)
A36: market for ammonia, anhydrous, liquid | B36: ammonia, anhydrous, liquid | C36: RoW | D36: 5.8560239 | E36: kilogram | F36: ecoinvent 3.10 cutoff | G36: technosphere | J36: (4.0,5.0,5.0,5.0,5.0)
... A39: market for natural gas, high pressure | B39: natural gas, high pressure | C39: RoW | D39: 4.6278343 | E39: cubic meter | F39: ecoinvent 3.10 cutoff | G39: technosphere | J39: (4.0,5.0,5.0,5.0,5.0)
A41: Activity | B41: Co recovery from sulfide ore mining and Ni class 1 production in Australia through Flash Smelting
A42: reference product | B42: Co
A43: location | B43: AU
A44: amount | B44: 1
...

Sheet PR7_Co(OH)2_Europe_Recycling
A1: Activity | B1: [P] Scrap oxidation
A2: reference product | B2: Oxidized scrap
A3: location | B3: Europe witout Switzerland
A4: amount | B4: 1
A5: unit | B5: kilogram
A6: comment | B6: n/a
A7: Exchanges
A8: name | B8: reference product | C8: location | D8: amount | E8: unit | F8: database | G8: type | H8: categories | I8: uncertainty type | J8: pedigree | K8: loc | L8: scale | M8: minimum | N8: maximum
A9: =B1 -> [P] Scrap oxidation | B9: =B2 -> Oxidized scrap | C9: =B3 -> Europe witout Switzerland | D9: 1 | E9: =B5 -> kilogram | F9: =Co_Market_GLO!B1 -> Cobalt | G9: production
A10: market for compressed air, 800 kPa gauge | B10: compressed air, 800 kPa gauge | C10: RER | D10: 0.25315092 | E10: cubic meter | F10: ecoinvent 3.10 cutoff | G10: technosphere | J10: (2.0,5.0,1.0,1.0,2.0)
A11: market for heat, from steam, in chemical industry | B11: heat, from steam, in chemical industry | C11: RER | D11: 15.299883 | E11: megajoule | F11: ecoinvent 3.10 cutoff | G11: technosphere | J11: (2.0,5.0,1.0,1.0,2.0)
A12: market group for electricity, medium voltage | B12: electricity, medium voltage | C12: RER | D12: 0.30700552 | E12: kilowatt hour | F12: ecoinvent 3.10 cutoff | G12: technosphere | J12: (2.0,5.0,1.0,1.0,2.0)
A13: Oxygen | D13: 0.16831683 | E13: kilogram | F13: biosphere3 | G13: biosphere | H13: air | J13: (2.0,5.0,1.0,1.0,2.0)
A14: Nitrogen | D14: 1.8998993 | E14: kilogram | F14: biosphere3 | G14: biosphere | H14: air | J14: (2.0,5.0,1.0,1.0,2.0)
A15: Carbon dioxide, fossil | D15: 0.17377077 | E15: kilogram | F15: biosphere3 | G15: biosphere | H15: air | J15: (2.0,5.0,1.0,1.0,2.0)
A17: Activity | B17: [P] Alkali leaching
A18: reference product | B18: Cobalt (Co) sludge
A19: location | B19: Europe witout Switzerland
A20: amount | B20: 1
A21: unit | B21: kilogram
A22: comment | B22: Allocated unit process, considering as allocation factors (AF): 85.6% for W (1 kg APT) and 14.4% for Co (0.26 kg Co(OH)2).
A23: Exchanges
A24: name | B24: reference product | C24: location | D24: amount | E24: unit | F24: database | G24: type | H24: categories | I24: uncertainty type | J24: pedigree | K24: loc | L24: scale | M24: minimum | N24: maximum
A25: =B17 -> [P] Alkali leaching | B25: =B18 -> Cobalt (Co) sludge | C25: =B19 -> Europe witout Switzerland | D25: 1 | E25: =B21 -> kilogram | F25: =F9 -> Cobalt | G25: production
A26: market group for tap water | B26: tap water | C26: RER | D26: 0.23320908 | E26: kilogram | F26: ecoinvent 3.10 cutoff | G26: technosphere | J26: (2.0,5.0,1.0,1.0,2.0)
A27: market for sodium hydroxide, without water, in 50% solution state | B27: sodium hydroxide, without water, in 50% solution state | C27: RER | D27: 0.10542328 | E27: kilogram | F27: ecoinvent 3.10 cutoff | G27: technosphere | J27: (2.0,5.0,1.0,1.0,2.0)
A28: market group for electricity, medium voltage | B28: electricity, medium voltage | C28: RER | D28: 0.056255914 | E28: kilowatt hour | F28: ecoinvent 3.10 cutoff | G28: technosphere | J28: (2.0,5.0,1.0,1.0,2.0)
A29: Water | D29: 2.4524547e-05 | E29: cubic meter | F29: biosphere3 | G29: biosphere | H29: air | J29: (2.0,5.0,1.0,1.0,2.0)
A31: Activity | B31: [P] Acid leaching
A32: reference product | B32: Co solution
A33: location | B33: Europe witout Switzerland
A34: amount | B34: 1
A35: unit | B35: kilogram
A36: comment | B36: n/a
A37: Exchanges
A38: name | B38: reference product | C38: location | D38: amount | E38: unit | F38: database | G38: type | H38: categories | I38: uncertainty type | J38: pedigree | K38: loc | L38: scale | M38: minimum | N38: maximum
A39: =B31 -> [P] Acid leaching | B39: =B32 -> Co solution | C39: =B33 -> Europe witout Switzerland | D39: 1 | E39: =B35 -> kilogram | F39: =F25 -> Cobalt | G39: production
A40: market group for tap water | B40: tap water | C40: RER | D40: 0.79532773 | E40: kilogram | F40: ecoinvent 3.10 cutoff | G40: technosphere | J40: (2.0,5.0,1.0,1.0,2.0)
A41: market for sulfuric acid | B41: sulfuric acid | C41: RER | D41: 0.19986112 | E41: kilogram | F41: ecoinvent 3.10 cutoff | G41: technosphere | J41: (2.0,5.0,1.0,1.0,2.0)
A42: market for hydrogen peroxide, without water, in 50% solution state | B42: hydrogen peroxide, without water, in 50% solution state | C42: RER | D42: 0.010341492 | E42: kilogram | F42: ecoinvent 3.10 cutoff | G42: technosphere | J42: (2.0,5.0,1.0,1.0,2.0)
...
