Workbook

Sheet Note
A1: skip
B2: Life cycle inventories of global metal and mineral supply chains: a comprehensive data review, analysis and processing Frédéric Laia*, Stéphanie Mullera, Audrey Philippea, Robert Istrateb, Brenda Miranda Xicotencatlb, Afsoon Mansouri Askic, Aina Mas Fonsd,a, Juliana Segura-Salazare, Jair Santillán Saldivara, Alexander Cimprichf, Stephen Northeyg, Lígia da Silva Limah, Lieselot Booneh, Ryosuke Yokoii, Kamrul Islami, Ioanna Paschalidouj, Felipe Cerdask,l, Victor Balboa-Espinozae, Anish Koyamparambathd, Diae Henniouia, Victoire Collignona, Aurélien Reysa, Gyslain Ngadi Sakatadim, Jo Dewulfh, Bernhard Steubingb, Christoph Helbigc, Gaétan Lefebvrea, Gian Andrea Blenginin,m, Valeria Supertio, Masaharu Motoshitai, Guido Sonnemannd, Kwame Awuah-Offeij, Steven B. Youngf, Shinsuke Murakamip, Antoine Beylota aBRGM, F-45060 Orléans, France bInstitute of Environmental Sciences (CML), Leiden University, Einsteinweg 2, 2333 CC Leiden, NL cEcological Resource Technology, University of Bayreuth, Universitätstr. 30, 95447 Bayreuth, Germany dUniv. Bordeaux, CNRS, Bordeaux INP, ISM, UMR 5255, F-33400 Talence, France eSustainable Minerals Institute, The University of Queensland, QLD, 4072, Australia fSchool of Environment, Enterprise and Development, University of Waterloo, 200 University Avenue West, Waterloo, Ontario N2L 3G1, Canada gUniversity of Technology Sydney, Institute for Sustainable Futures, Australia hSustainable Systems Engineering (STEN), Department of Green Chemistry and Technology, Faculty of Bioscience Engineering, Ghent University, Coupure Links 653, 9000 Ghent, Belgium iAIST, 305-8569 Tsukuba, Japan jMining & Explosives Engineering, Missouri University of Science & Technology, Rolla, MO, USA 65409 kInstitute for Sustainable Energy Systems (INSYS), Technical University of Applied Sciences Würzburg-Schweinfurt (THWS), Ignaz-Schön-Straße 11, Schweinfurt, Germany lFraunhofer Institute for Surface Engineering and Thin Films IST, Riedenkamp 2, Braunschweig 38108, Germany mDepartment of Environment, Land and Infrastructure Engineering, Politecnico di Torino, Corso Duca degli Abruzzi, 24, 10129 Torino, Italy nUniversity of Turin, Earth Sciences Department (DST), Via Valperga Caluso, 35 – 10125 Torino, Italy oecoinvent association, Technopark, Technoparkstrasse 1, 8005 Zürich, Switzerland pGraduate School of Engineering, The University of Tokyo, Tokyo 113-8656, Japan *Corresponding author: f.lai@brgm.fr This file provides all LCI datasets developed for Graphite (C), with distinguishing its global market and each individual production route.
B33: Sheet | C33: Corresponding route
B34: Graphite_Market_GLO | C34: Graphite global market
B35: PR1_NaturalGraphite_CN | C35: Graphite ore mining in China/Heilongjiang and natural graphite production in China/Shandong
B36: PR2_SyntheticGraphite_CN | C36: Synthetic graphite production in China

Sheet Graphite_Market_GLO
A1: database | B1: Graphite
A3: Activity | B3: Graphite (C) global market
A4: reference product | B4: Battery-grade graphite
A5: location | B5: GLO
A6: amount | B6: 1
A7: unit | B7: kilogram
A8: comment | B8: n/a
A9: Exchanges
A10: name | B10: reference product | C10: location | D10: amount | E10: unit | F10: database | G10: type | H10: categories | I10: uncertainty type | J10: pedigree | K10: loc | L10: scale | M10: minimum | N10: maximum
A11: =B3 -> Graphite (C) global market | B11: =B4 -> Battery-grade graphite | C11: =B5 -> GLO | D11: 1 | E11: =B7 -> kilogram | F11: =B1 -> Graphite | G11: production
A12: =PR1_NaturalGraphite_CN!A110 -> Graphite ore mining in China/Heilongjiang and natural graphite production in China/Shandong | B12: =PR1_NaturalGraphite_CN!B110 -> Battery-grade graphite | C12: =PR1_NaturalGraphite_CN!C110 -> CN | D12: 0.42057679 | E12: =PR1_NaturalGraphite_CN!E110 -> kilogram | F12: =PR1_NaturalGraphite_CN!F110 -> Graphite | G12: technosphere
A13: =PR2_SyntheticGraphite_CN!A39 -> Synthetic graphite production in China | B13: =PR2_SyntheticGraphite_CN!B39 -> Battery-grade graphite | C13: =PR2_SyntheticGraphite_CN!C39 -> CN | D13: 0.57942321 | E13: =PR2_SyntheticGraphite_CN!E39 -> kilogram | F13: =PR2_SyntheticGraphite_CN!F39 -> Graphite | G13: technosphere

Sheet PR1_NaturalGraphite_CN
A1: Activity | B1: [M] Graphite ore mining
A2: reference product | B2: Graphite ore
A3: location | B3: CN
A4: amount | B4: 1
A5: unit | B5: kilogram
A6: comment | B6: n/a
A7: Exchanges
A8: name | B8: reference product | C8: location | D8: amount | E8: unit | F8: database | G8: type | H8: categories | I8: uncertainty type | J8: pedigree | K8: loc | L8: scale | M8: minimum | N8: maximum
A9: =B1 -> [M] Graphite ore mining | B9: =B2 -> Graphite ore | C9: =B3 -> CN | D9: 1 | E9: kilogram | F9: =Graphite_Market_GLO!B1 -> Graphite | G9: production
A10: market group for electricity, medium voltage | B10: electricity, medium voltage | C10: CN | D10: 0.0087 | E10: kilowatt hour | F10: ecoinvent 3.10 cutoff | G10: technosphere | J10: (1,1,2,1,1)
A11: market for diesel | B11: diesel | C11: RoW | D11: 0.002241 | E11: kilogram | F11: ecoinvent 3.10 cutoff | G11: technosphere | J11: (1,1,2,1,1)
A12: ammonium nitrate production | B12: ammonium nitrate | C12: CN | D12: 0.000248 | E12: kilogram | F12: ecoinvent 3.10 cutoff | G12: technosphere | J12: (1,1,2,1,1)
A13: market for diesel | B13: diesel | C13: RoW | D13: 1.2e-05 | E13: kilogram | F13: ecoinvent 3.10 cutoff | G13: technosphere | J13: (1,1,2,1,1)
A14: market for transport, freight, lorry 16-32 metric ton, EURO5 | B14: transport, freight, lorry 16-32 metric ton, EURO5 | C14: RoW | D14: 0.0001222 | E14: ton kilometer | F14: ecoinvent 3.10 cutoff | G14: technosphere | J14: (1,1,2,1,1)
A15: market for inert waste, for final disposal | B15: inert waste, for final disposal | C15: RoW | D15: -2.5e-05 | E15: kilogram | F15: ecoinvent 3.10 cutoff | G15: technosphere | J15: (1,1,2,1,1)
A16: Nitrogen oxides | D16: 0.000138 | E16: kilogram | F16: biosphere3 | G16: biosphere | H16: air | J16: (1,1,2,1,1)
A17: Water | D17: 1.13e-07 | E17: cubic meter | F17: biosphere3 | G17: biosphere | H17: air | J17: (1,1,2,1,1)
A18: Carbon dioxide, fossil | D18: 4e-05 | E18: kilogram | F18: biosphere3 | G18: biosphere | H18: air | J18: (2,1,2,1,1)
A19: Particulate Matter, > 2.5 um and < 10um | D19: 0.005 | E19: kilogram | F19: biosphere3 | G19: biosphere | H19: air | J19: (1,1,2,1,1)
A21: Activity | B21: [C] Flotation
A22: reference product | B22: Graphite concentrate
A23: location | B23: CN
A24: amount | B24: 1
A25: unit | B25: kilogram
A26: comment | B26: n/a
A27: Exchanges
A28: name | B28: reference product | C28: location | D28: amount | E28: unit | F28: database | G28: type | H28: categories | I28: uncertainty type | J28: pedigree | K28: loc | L28: scale | M28: minimum | N28: maximum
A29: =B21 -> [C] Flotation | B29: =B22 -> Graphite concentrate | C29: =B23 -> CN | D29: 1 | E29: kilogram | F29: =F9 -> Graphite | G29: production
A30: market group for electricity, medium voltage | B30: electricity, medium voltage | C30: CN | D30: 0.506 | E30: kilowatt hour | F30: ecoinvent 3.10 cutoff | G30: technosphere | J30: (1,1,2,1,1)
A31: market for diesel, burned in building machine | B31: diesel, burned in building machine | C31: GLO | D31: 0.04482 | E31: megajoule | F31: ecoinvent 3.10 cutoff | G31: technosphere | J31: (1,1,2,1,1)
A32: market for hard coal | B32: hard coal | C32: CN | D32: 0.05 | E32: kilogram | F32: ecoinvent 3.10 cutoff | G32: technosphere | J32: (1,1,2,1,1)
A33: market for vegetable oil, refined | B33: vegetable oil, refined | C33: GLO | D33: 0.001163 | E33: kilogram | F33: ecoinvent 3.10 cutoff | G33: technosphere | J33: (1,1,2,1,1)
A34: market for diesel | B34: diesel | C34: RoW | D34: 0.001551 | E34: kilogram | F34: ecoinvent 3.10 cutoff | G34: technosphere | J34: (1,1,2,1,1)
A35: market for steel, low-alloyed | B35: steel, low-alloyed | C35: GLO | D35: 0.009 | E35: kilogram | F35: ecoinvent 3.10 cutoff | G35: technosphere | J35: (1,1,2,1,1)
A36: market for transport, freight, lorry 16-32 metric ton, EURO5 | B36: transport, freight, lorry 16-32 metric ton, EURO5 | C36: RoW | D36: 0.01918 | E36: ton kilometer | F36: ecoinvent 3.10 cutoff | G36: technosphere | J36: (1,1,2,1,1)
A37: market for non-sulfidic tailing, off-site | B37: non-sulfidic tailing, off-site | C37: GLO | D37: -0.001396 | E37: kilogram | F37: ecoinvent 3.10 cutoff | G37: technosphere | J37: (1,1,2,1,1)
A38: market for wastewater, average | B38: wastewater, average | C38: RoW | D38: -0.021707 | E38: cubic meter | F38: ecoinvent 3.10 cutoff | G38: technosphere | J38: (1,1,2,1,1)
A39: market for non-sulfidic tailing, off-site | B39: non-sulfidic tailing, off-site | C39: GLO | D39: -8.596 | E39: kilogram | F39: ecoinvent 3.10 cutoff | G39: technosphere | J39: (1,1,2,1,1)
A40: Water, unspecified natural origin | D40: 0.022027 | E40: cubic meter | F40: biosphere3 | G40: biosphere | H40: natural resource::in ground | J40: (1,1,2,1,1)
A41: Carbon dioxide, fossil | D41: 0.183333 | E41: kilogram | F41: biosphere3 | G41: biosphere | H41: air | J41: (1,1,2,1,1)
...

Sheet PR2_SyntheticGraphite_CN
A1: Activity | B1: [P+R] Synthetic graphite production
A2: reference product | B2: Battery-grade graphite
A3: location | B3: CN
A4: amount | B4: 1
A5: unit | B5: kilogram
A6: comment | B6: n/a
A7: Exchanges
A8: name | B8: reference product | C8: location | D8: amount | E8: unit | F8: database | G8: type | H8: categories | I8: uncertainty type | J8: pedigree | K8: loc | L8: scale | M8: minimum | N8: maximum
A9: =B1 -> [P+R] Synthetic graphite production | B9: =B2 -> Battery-grade graphite | C9: =B3 -> CN | D9: 1 | E9: kilogram | F9: =Graphite_Market_GLO!B1 -> Graphite | G9: production
A10: market for petroleum coke | B10: petroleum coke | C10: GLO | D10: 2.03 | E10: kilogram | F10: ecoinvent 3.10 cutoff | G10: technosphere | J10: (1,1,2,1,1)
A11: market group for electricity, medium voltage | B11: electricity, medium voltage | C11: CN | D11: 1.88 | E11: kilowatt hour | F11: ecoinvent 3.10 cutoff | G11: technosphere | J11: (1,1,2,1,1)
A12: market for heat, district or industrial, natural gas | B12: heat, district or industrial, natural gas | C12: RoW | D12: 0.756 | E12: megajoule | F12: ecoinvent 3.10 cutoff | G12: technosphere | J12: (1,1,2,1,1)
A13: market for anode, graphite, for Li-ion battery | B13: anode, graphite, for Li-ion battery | C13: CN | D13: 0.27 | E13: kilogram | F13: ecoinvent 3.10 cutoff | G13: technosphere | J13: (4,5,5,5,1)
A14: market group for electricity, medium voltage | B14: electricity, medium voltage | C14: CN | D14: 16 | E14: kilowatt hour | F14: ecoinvent 3.10 cutoff | G14: technosphere | J14: (1,1,2,1,1)
A15: market for coke | B15: coke | C15: CN | D15: 12.74 | E15: megajoule | F15: ecoinvent 3.10 cutoff | G15: technosphere | J15: (3,5,2,5,1)
A16: market for inert waste, for final disposal | B16: inert waste, for final disposal | C16: RoW | D16: -0.26 | E16: kilogram | F16: ecoinvent 3.10 cutoff | G16: technosphere | J16: (3,5,2,5,1)
A17: market group for electricity, medium voltage | B17: electricity, medium voltage | C17: CN | D17: 3.33 | E17: kilowatt hour | F17: ecoinvent 3.10 cutoff | G17: technosphere | J17: (3,5,2,5,1)
A18: market for heat, district or industrial, natural gas | B18: heat, district or industrial, natural gas | C18: RoW | D18: 0.972 | E18: megajoule | F18: ecoinvent 3.10 cutoff | G18: technosphere | J18: (1,1,2,1,1)
A19: market for coal tar | B19: coal tar | C19: GLO | D19: 0.05 | E19: kilogram | F19: ecoinvent 3.10 cutoff | G19: technosphere | J19: (1,1,2,1,1)
A20: market group for electricity, medium voltage | B20: electricity, medium voltage | C20: CN | D20: 0.17 | E20: kilowatt hour | F20: ecoinvent 3.10 cutoff | G20: technosphere | J20: (3,5,2,5,1)
A21: market group for electricity, medium voltage | B21: electricity, medium voltage | C21: CN | D21: 0.21 | E21: kilowatt hour | F21: ecoinvent 3.10 cutoff | G21: technosphere | J21: (3,5,2,5,1)
... A27: market for heat, district or industrial, natural gas | B27: heat, district or industrial, natural gas | C27: RoW | D27: 0.108 | E27: megajoule | F27: ecoinvent 3.10 cutoff | G27: technosphere | J27: (1,1,2,1,1)
A28: Carbon dioxide, fossil | D28: 0.72 | E28: kilogram | F28: biosphere3 | G28: biosphere | H28: air | J28: (4,1,1,1,1)
A29: Carbon dioxide, fossil | D29: 0.07 | E29: kilogram | F29: biosphere3 | G29: biosphere | H29: air | J29: (4,1,1,1,1)
A31: Activity | B31: Synthetic graphite production in China
A32: reference product | B32: Battery-grade graphite
A33: location | B33: CN
A34: amount | B34: 1
A35: unit | B35: kilogram
A36: comment | B36: n/a
A37: Exchanges
A38: name | B38: reference product | C38: location | D38: amount | E38: unit | F38: database | G38: type | H38: categories | I38: uncertainty type | J38: pedigree | K38: loc | L38: scale | M38: minimum | N38: maximum
A39: =B31 -> Synthetic graphite production in China | B39: =B32 -> Battery-grade graphite | C39: =B33 -> CN | D39: 1 | E39: kilogram | F39: =F9 -> Graphite | G39: production
A40: =A9 -> [P+R] Synthetic graphite production | B40: =B9 -> Battery-grade graphite | C40: =C9 -> CN | D40: =D9 -> 1 | E40: =E9 -> kilogram | F40: =F9 -> Graphite | G40: technosphere
