Workbook

Sheet DEMAND
A1: Scenario | B1: Country | C1: Year | D1: Technology | E1: Metal | F1: Metal_demand_t | G1: Mode | H1: Powertain | I1: Powertrain
A2: Canada Net-zero | B2: Canada | C2: 2020 | D2: Bioenergy | E2: Cobalt | F2: 5.0482
A3: Canada Net-zero | B3: Canada | C3: 2020 | D3: Bioenergy | E3: Copper | F3: 5609.8122
A4: Canada Net-zero | B4: Canada | C4: 2020 | D4: Bioenergy | E4: Nickel | F4: 50.482
A5: Canada Net-zero | B5: Canada | C5: 2021 | D5: Bioenergy | E5: Cobalt | F5: 5.0862
A6: Canada Net-zero | B6: Canada | C6: 2021 | D6: Bioenergy | E6: Copper | F6: 5652.0397
A7: Canada Net-zero | B7: Canada | C7: 2021 | D7: Bioenergy | E7: Nickel | F7: 50.862
A8: Canada Net-zero | B8: Canada | C8: 2022 | D8: Bioenergy | E8: Cobalt | F8: 5.0862
A9: Canada Net-zero | B9: Canada | C9: 2022 | D9: Bioenergy | E9: Copper | F9: 5652.0397
A10: Canada Net-zero | B10: Canada | C10: 2022 | D10: Bioenergy | E10: Nickel | F10: 50.862
A11: Canada Net-zero | B11: Canada | C11: 2023 | D11: Bioenergy | E11: Cobalt | F11: 5.0862
A12: Canada Net-zero | B12: Canada | C12: 2023 | D12: Bioenergy | E12: Copper | F12: 5652.0397
A13: Canada Net-zero | B13: Canada | C13: 2023 | D13: Bioenergy | E13: Nickel | F13: 50.862
... A2636: Global Net-zero | B2636: Canada | C2636: 2050 | D2636: Uranium SMR | E2636: Nickel | F2636: 161.61846
A2637: Current Measures | B2637: Canada | C2637: 2024 | D2637: Vehicle battery | E2637: Cobalt | F2637: 0.7837938 | G2637: 2 and 3 wheelers | I2637: BEV
A2638: Current Measures | B2638: Canada | C2638: 2024 | D2638: Vehicle battery | E2638: Copper | F2638: 0.25154467 | G2638: 2 and 3 wheelers | I2638: BEV
A2639: Current Measures | B2639: Canada | C2639: 2024 | D2639: Vehicle battery | E2639: Lithium | F2639: 0.065542097 | G2639: 2 and 3 wheelers | I2639: BEV
A2640: Current Measures | B2640: Canada | C2640: 2024 | D2640: Vehicle battery | E2640: Nickel | F2640: 0.0714 | G2640: 2 and 3 wheelers | I2640: BEV
A2641: Current Measures | B2641: Canada | C2641: 2024 | D2641: Vehicle battery | E2641: Cobalt | F2641: 13.611585 | G2641: Buses | I2641: BEV
A2642: Current Measures | B2642: Canada | C2642: 2024 | D2642: Vehicle battery | E2642: Copper | F2642: 19.975609 | G2642: Buses | I2642: BEV
A2643: Current Measures | B2643: Canada | C2643: 2024 | D2643: Vehicle battery | E2643: Lithium | F2643: 23.553298 | G2643: Buses | I2643: BEV
A2644: Current Measures | B2644: Canada | C2644: 2024 | D2644: Vehicle battery | E2644: Nickel | F2644: 35.512197 | G2644: Buses | I2644: BEV
A2645: Current Measures | B2645: Canada | C2645: 2024 | D2645: Vehicle battery | E2645: Cobalt | F2645: 7878.4516 | G2645: Cars | I2645: BEV
A2646: Current Measures | B2646: Canada | C2646: 2024 | D2646: Vehicle battery | E2646: Copper | F2646: 2528.4488 | G2646: Cars | I2646: BEV
A2647: Current Measures | B2647: Canada | C2647: 2024 | D2647: Vehicle battery | E2647: Lithium | F2647: 658.80879 | G2647: Cars | I2647: BEV
A2648: Current Measures | B2648: Canada | C2648: 2024 | D2648: Vehicle battery | E2648: Nickel | F2648: 717.69061 | G2648: Cars | I2648: BEV
... A11951: Global Net-zero | B11951: Canada | C11951: 2050 | D11951: Vehicle motor | E11951: Copper | F11951: 7910.4659 | G11951: Vans | I11951: PHEV

Sheet PRODUCTION
A1: Scenario | B1: Year | C1: Unit | D1: Cobalt | E1: Copper | F1: Graphite | G1: Lithium | H1: Nickel
A2: Existing production | B2: 2020 | C2: t | D2: =[1]Production_mining!D2*[1]Chartier_Poncelet!$D$12 -> 1405.909 | E2: =[1]Production_mining!E2*[1]Chartier_Poncelet!$D$14 -> 443166.53 | F2: =[1]Production_mining!F2 -> 8200 | G2: =[1]Production_mining!G2*[1]Chartier_Poncelet!$D$28 -> 0 | H2: =[1]Production_mining!I2*[1]Chartier_Poncelet!$D$35 -> 121598.49
A3: Existing production | B3: 2021 | C3: t | D3: =[1]Production_mining!D3*[1]Chartier_Poncelet!$D$12 -> 1669.5169 | E3: =[1]Production_mining!E3*[1]Chartier_Poncelet!$D$14 -> 407773.31 | F3: =[1]Production_mining!F3 -> 4200 | G3: =[1]Production_mining!G3*[1]Chartier_Poncelet!$D$28 -> 139.83409 | H3: =[1]Production_mining!I3*[1]Chartier_Poncelet!$D$35 -> 109391.39
A4: Existing production | B4: 2022 | C4: t | D4: =[1]Production_mining!D4*[1]Chartier_Poncelet!$D$12 -> 1098.3664 | E4: =[1]Production_mining!E4*[1]Chartier_Poncelet!$D$14 -> 384316.95 | F4: =[1]Production_mining!F4 -> 13600 | G4: =[1]Production_mining!G4*[1]Chartier_Poncelet!$D$28 -> 2447.0966 | H4: =[1]Production_mining!I4*[1]Chartier_Poncelet!$D$35 -> 99704.463
A5: Existing production | B5: 2023 | C5: t | D5: =[1]Production_mining!D5*[1]Chartier_Poncelet!$D$12 -> 2108.8635 | E5: =[1]Production_mining!E5*[1]Chartier_Poncelet!$D$14 -> 337237.29 | F5: =[1]Production_mining!F5 -> 4200 | G5: =[1]Production_mining!G5*[1]Chartier_Poncelet!$D$28 -> 11676.147 | H5: =[1]Production_mining!I5*[1]Chartier_Poncelet!$D$35 -> 147115.27
A6: Existing production | B6: 2024 | C6: t | D6: =[1]Production_mining!D6*[1]Chartier_Poncelet!$D$12 -> 1493.7783 | E6: =[1]Production_mining!E6*[1]Chartier_Poncelet!$D$14 -> 399759.75 | F6: =[1]Production_mining!F6 -> 6300 | G6: =[1]Production_mining!G6*[1]Chartier_Poncelet!$D$28 -> 27896.902 | H6: =[1]Production_mining!I6*[1]Chartier_Poncelet!$D$35 -> 106004.9
A7: Existing production | B7: 2025 | C7: t | D7: =[1]Production_mining!D7*[1]Chartier_Poncelet!$D$12 -> 1537.713 | E7: =[1]Production_mining!E7*[1]Chartier_Poncelet!$D$14 -> 403933.47 | F7: =[1]Production_mining!F7 -> 0 | G7: =[1]Production_mining!G7*[1]Chartier_Poncelet!$D$28 -> 26288.81 | H7: =[1]Production_mining!I7*[1]Chartier_Poncelet!$D$35 -> 121756
A8: Existing production | B8: 2026 | C8: t | D8: =[1]Production_mining!D8*[1]Chartier_Poncelet!$D$12 -> 1537.713 | E8: =[1]Production_mining!E8*[1]Chartier_Poncelet!$D$14 -> 397005.08 | F8: =[1]Production_mining!F8 -> 0 | G8: =[1]Production_mining!G8*[1]Chartier_Poncelet!$D$28 -> 27966.819 | H8: =[1]Production_mining!I8*[1]Chartier_Poncelet!$D$35 -> 124827.47
A9: Existing production | B9: 2027 | C9: t | D9: =[1]Production_mining!D9*[1]Chartier_Poncelet!$D$12 -> 1845.2556 | E9: =[1]Production_mining!E9*[1]Chartier_Poncelet!$D$14 -> 413199.15 | F9: =[1]Production_mining!F9 -> 0 | G9: =[1]Production_mining!G9*[1]Chartier_Poncelet!$D$28 -> 29155.409 | H9: =[1]Production_mining!I9*[1]Chartier_Poncelet!$D$35 -> 124827.47
A10: Existing production | B10: 2028 | C10: t | D10: =[1]Production_mining!D10*[1]Chartier_Poncelet!$D$12 -> 1845.2556 | E10: =[1]Production_mining!E10*[1]Chartier_Poncelet!$D$14 -> 384901.27 | F10: =[1]Production_mining!F10 -> 0 | G10: =[1]Production_mining!G10*[1]Chartier_Poncelet!$D$28 -> 28176.57 | H10: =[1]Production_mining!I10*[1]Chartier_Poncelet!$D$35 -> 121913.51
A11: Existing production | B11: 2029 | C11: t | D11: =[1]Production_mining!D11*[1]Chartier_Poncelet!$D$12 -> 1713.4516 | E11: =[1]Production_mining!E11*[1]Chartier_Poncelet!$D$14 -> 290741.95 | F11: =[1]Production_mining!F11 -> 0 | G11: =[1]Production_mining!G11*[1]Chartier_Poncelet!$D$28 -> 26498.561 | H11: =[1]Production_mining!I11*[1]Chartier_Poncelet!$D$35 -> 119787.12
A12: Existing production | B12: 2030 | C12: t | D12: =[1]Production_mining!D12*[1]Chartier_Poncelet!$D$12 -> 1713.4516 | E12: =[1]Production_mining!E12*[1]Chartier_Poncelet!$D$14 -> 276885.17 | F12: =[1]Production_mining!F12 -> 0 | G12: =[1]Production_mining!G12*[1]Chartier_Poncelet!$D$28 -> 27267.648 | H12: =[1]Production_mining!I12*[1]Chartier_Poncelet!$D$35 -> 118290.76
A13: Existing production | B13: 2031 | C13: t | D13: =[1]Production_mining!D13*[1]Chartier_Poncelet!$D$12 -> 1625.5823 | E13: =[1]Production_mining!E13*[1]Chartier_Poncelet!$D$14 -> 259689.41 | F13: =[1]Production_mining!F13 -> 0 | G13: =[1]Production_mining!G13*[1]Chartier_Poncelet!$D$28 -> 26708.312 | H13: =[1]Production_mining!I13*[1]Chartier_Poncelet!$D$35 -> 109706.41
... A43: Production potential | B43: 2040 | C43: t | D43: =[1]Production_mining!D43*[1]Chartier_Poncelet!$D$12 -> 13751.548 | E43: =[1]Production_mining!E43*[1]Chartier_Poncelet!$D$14 -> 1085169.5 | F43: =[1]Production_mining!F43 -> 400000 | G43: =[1]Production_mining!G43*[1]Chartier_Poncelet!$D$28 -> 460263.92 | H43: =[1]Production_mining!I43*[1]Chartier_Poncelet!$D$35 -> 251308.8

Sheet validation
A1: Geography | B1: Commodity | C1: Product_type | D1: Variable | E1: Unit | F1: Value | G1: data_source | H1: Value_tonnes
A2: canada | B2: aluminum | C2: alloys | D2: quantity produced | E2: Tonnes | F2: 43691 | G2: 16100019 | H2: 43691
A3: canada | B3: aluminum | C3: molten metal | D3: quantity produced | E3: Tonnes | F3: 3258153 | G3: 16100019 | H3: 3258153
A4: canada | B4: aluminum | C4: Smelter production, aluminum | E4: thousand metric tons | F4: 3200 | G4: USGS MCS 2025 | H4: 3200000
A5: canada | B5: bauxite | C5: Refinery production, alumina - calcined equivalent weights | E5: thousand metric dry tons | F5: 1500 | G5: USGS MCS 2025 | H5: 1500000
A6: canada | B6: cadmium | C6: Refinery production, estimated | E6: metric tons | F6: 1800 | G6: USGS MCS 2025 | H6: 1800
A7: canada | B7: cobalt | C7: refined | D7: quantity produced | E7: Kilograms | F7: 4923174 | G7: 16100019 | H7: 4923.174
A8: canada | B8: cobalt | C8: recoverable | D8: quantity produced | E8: Tonnes | F8: 3260 | G8: 16100022 | H8: 3260
A9: canada | B9: cobalt | C9: Mine production, cobalt content, estimated | E9: metric tons | F9: 4220 | G9: USGS MCS 2025 | H9: 4220
A10: canada | B10: copper | C10: concentrates | D10: quantity produced | E10: Tonnes | F10: 1272135 | G10: 16100022 | H10: 1272135
A11: canada | B11: copper | C11: recoverable | D11: quantity produced | E11: Tonnes | F11: 484552 | G11: 16100022 | H11: 484552
A12: canada | B12: copper | C12: Refinery production, copper | E12: thousand metric tons | F12: 315 | G12: USGS MCS 2025 | H12: 315000
A13: canada | B13: copper | C13: Mine production, recoverable copper content | E13: thousand metric tons | F13: 500 | G13: USGS MCS 2025 | H13: 500000
A14: canada | B14: diamonds | C14: undefined | D14: quantity produced | E14: Carats | F14: 15674351 | G14: 16100022 | H14: 3.1348702
A15: canada | B15: gemstones | C15: Mine production, thousand carats of gem-quality diamond | E15: thousand carats | F15: 16000 | G15: USGS MCS 2025 | H15: 3.2
A16: canada | B16: gold | C16: mine production, gold content | E16: metric tons | F16: 198 | G16: USGS MCS 2025 | H16: 198
A17: canada | B17: gold | C17: recoverable | D17: quantity produced | E17: Kilograms | F17: 191035 | G17: 16100022 | H17: 191.035
A18: canada | B18: gold and silver bullion | C18: crude and dore | D18: quantity produced | E18: Kilograms | F18: 215873 | G18: 16100022 | H18: 215.873
A19: canada | B19: graphite | C19: Mine production | E19: metric tons | F19: 5470 | G19: USGS MCS 2025 | H19: 5470
A20: canada | B20: indium | C20: Refinery production | E20: metric tons | F20: 40 | G20: USGS MCS 2025 | H20: 40
A21: canada | B21: iridium | C21: recoverable | D21: quantity produced | E21: Grams | F21: 91895 | G21: 16100022 | H21: 0.091895
A22: canada | B22: iron | C22: concentrates | D22: quantity produced | E22: Tonnes | F22: 65165564 | G22: 16100022 | H22: 65165564
A23: canada | B23: iron | C23: agglomerates | D23: quantity produced | E23: Tonnes | F23: 17708017 | G23: 16100022 | H23: 17708017
A24: canada | B24: iron and steel | C24: Raw steel | E24: million metric tons | F24: 12 | G24: USGS MCS 2025 | H24: 12000000
A25: canada | B25: iron and steel | C25: Pig iron | E25: million metric tons | F25: 6 | G25: USGS MCS 2025 | H25: 6000000
A26: canada | B26: iron ore | C26: Mine production, usable ore | E26: thousand metric tons | F26: 59400 | G26: USGS MCS 2025 | H26: 59400000
A27: canada | B27: iron ore | C27: Mine production, iron content | E27: thousand metric tons | F27: 35700 | G27: USGS MCS 2025 | H27: 35700000
A28: canada | B28: lithium | C28: Mine production, lithium content | E28: metric tons | F28: 3240 | G28: USGS MCS 2025 | H28: 3240
A29: canada | B29: lithium | C29: recoverable | D29: quantity produced | E29: Kilograms | F29: 31600000 | G29: 16100022 | H29: 31600
A30: canada | B30: molybdenum | C30: recoverable | D30: quantity produced | E30: Tonnes | F30: 1171 | G30: 16100022 | H30: 1171
A31: canada | B31: molybdenum | C31: Mine production, molybdenum content | E31: metric tons | F31: 1150 | G31: USGS MCS 2025 | H31: 1150
A32: canada | B32: molybdenum | C32: concentrates | D32: quantity produced | E32: Tonnes | F32: 2537 | G32: 16100022 | H32: 2537
A33: canada | B33: nickel | C33: Mine production, nickel content | E33: metric tons | F33: 159000 | G33: USGS MCS 2025 | H33: 159000
A34: canada | B34: nickel | C34: recoverable | D34: quantity produced | E34: Tonnes | F34: 127237 | G34: 16100022 | H34: 127237
A35: canada | B35: nickel | C35: concentrates | D35: quantity produced | E35: Tonnes | F35: 949184 | G35: 16100022 | H35: 949184
A36: canada | B36: niobium | C36: Mine production, niobium content | E36: metric tons | F36: 6700 | G36: USGS MCS 2025 | H36: 6700
A37: canada | B37: palladium | C37: recoverable | D37: quantity produced | E37: Grams | F37: 17267477 | G37: 16100022 | H37: 17.267477
A38: canada | B38: palladium | C38: concentrates | D38: quantity produced | E38: Kilograms | F38: 39792000 | G38: 16100022 | H38: 39792
A39: canada | B39: platinum | C39: recoverable | D39: quantity produced | E39: Grams | F39: 6119780 | G39: 16100022 | H39: 6.11978
A40: canada | B40: platinum group | C40: refined | D40: quantity produced | E40: Grams | F40: 11541177 | G40: 16100019 | H40: 11.541177
...

Sheet Feuil2
B1: CCI | C1: Validation | D1: Percentage difference
A2: Cobalt | B2: =PRODUCTION!D5 -> 2108.8635 | C2: =validation!H8 -> 3260 | D2: =(C2-B2)/C2 -> 0.35310935
A3: Copper | B3: =PRODUCTION!E5 -> 337237.29 | C3: =validation!H11 -> 484552 | D3: =(C3-B3)/C3 -> 0.3040225
A4: Graphite | B4: =PRODUCTION!F5 -> 4200 | C4: =validation!H19 -> 5470 | D4: =(C4-B4)/C4 -> 0.2321755
A5: Lithium | B5: =PRODUCTION!G5 -> 11676.147 | C5: =validation!H29 -> 31600 | D5: =(C5-B5)/C5 -> 0.63050168
A6: Nickel | B6: =PRODUCTION!H5 -> 147115.27 | C6: =validation!H34 -> 127237 | D6: =(C6-B6)/C6 -> -0.15623029
