Workbook

Sheet README
A1: Title of the article | B1: Supplementary Information for ''A Macro-LCSA framework for sectoral sustainability assessment: application to metal supply chains in Canada"
A2: Authors | B2: Marin Pellan¹, Maxime Agez1, Sara Russo-Garrido¹, Anne de Bortoli1,2,3
A3: Affiliations | B3: ¹CIRAIG, Ecole Polytechnique de Montréal, P.O. Box 6079, Montréal, H3C 3A7, Québec, Canada 2CIRAIG, Université du Québec à Montréal, C.P. 8888, succ. Centre-ville. Montréal (Québec) H3C 3P8, Québec, Canada 3LVMT, Ecole des Ponts ParisTech, Cité Descartes, 6-8 Avenue Blaise Pascal, Champs-sur-Marne, 77420, France
A4: Corresponding author | B4: pellan.marin@gmail.com
A5: Journal
A6: Date | B6: 46163
A7: Purpose and scope
A11: TAB | B11: DESCRIPTION | C11: COMMENT
A12: SUPPLY | B12: Description of the supply scenarios created, and their associated production scenarios
A13: DEMAND | B13: Results of the demand scenarios (CER) with metal intensity | C13: Attention valeurs Gr commence à 2024
A14: PRODUCTION | B14: CCI production scenarios, with production yield +
A15: Result_notebook | B15: Combination to assess mining and refining volumes in CAN and RoW for impact assessment calculations | C15: Year from 2025 to 2040
A17: Result_notebook_retravaill | B17: On ajoute Refining RoW (mining CA) et Refining RoW (mining RoW)
A20: ## Canada
A21: "Cu refining CA": ("copper production, cathode, solvent extraction and electrowinning process", "copper, cathode", 'CA'), | B21: mining+refining
A22: "Ni refining CA": ("processing of nickel-rich materials", "nickel, class 1", 'CA'), | B22: refining
A23: "Li refining CA": ("lithium carbonate production, from spodumene", "lithium carbonate", 'CA'), | B23: refining
A24: "Co refining CA": ("cobalt sulfate production, from copper mining, economic allocation", "cobalt sulfate", 'CA'), | B24: refining
A25: "C refining CA": ("synthetic graphite production, battery grade", "synthetic graphite, battery grade", 'CA'),
A26: "Nd refining CA": ("rare earth oxides production, from rare earth carbonate concentrate", "neodymium oxide", 'CA'), | B26: refining
A28: ## World
A29: "Cu refining World": ("market for copper, cathode", "copper, cathode", 'World'),
A30: "Ni refining World": ("market for nickel, class 1", "nickel, class 1", 'World'), | B30: Changer pour market for nickel-rich materials
A31: "Li refining World": ("lithium (Li) global market", "li commodities", 'GLO'),
A32: "Co refining World": ("market for cobalt sulfate", "cobalt sulfate", 'World'),
A33: "C refining World": ("synthetic graphite production, battery grade", "synthetic graphite, battery grade", 'CN'),
A34: "Nd refining World": ("rare earth oxides production, from rare earth carbonate concentrate", "neodymium oxide", 'CN'),
A35: #"Nd refining World": ("neodymium (Nd) global market", "nd oxide (Nd2O3)", 'GLO'),
A43: copper production, cathode, solvent extraction and electrowinning process

Sheet Data_to_couple_w_LCI
A1: Year | B1: Metal | C1: Demand scenario CER | D1: Production scenario CCI | E1: Production scenario CCI|Refining CAN share | F1: Supply scenario | G1: Demand_value_t | H1: Mining CAN | I1: Mining RoW | J1: Refining CAN (mining CAN) | K1: Refining RoW (mining CAN) | L1: Refining RoW (mining RoW) | M1: Verif | N1: Verif mining
A2: =Result_notebook_retravaill!A2 -> 2025 | B2: =Result_notebook_retravaill!B2 -> Cobalt | C2: =Result_notebook_retravaill!C2 -> Canada Net-zero | D2: =Result_notebook_retravaill!D2 -> Existing production | E2: =Result_notebook_retravaill!E2 -> Current shares | F2: =Result_notebook_retravaill!F2 -> NIMBY | G2: =Result_notebook_retravaill!G2 -> 9556.3204 | H2: =IF(Result_notebook_retravaill!I2>Result_notebook_retravaill!G2,Result_notebook_retravaill!I2/Result_notebook_retravaill!N2,Result_notebook_retravaill!H2) -> 0 | I2: =Result_notebook_retravaill!K2 -> 21718.91 | J2: =MIN(G2,Result_notebook_retravaill!I2) -> 0 | K2: =IF(Result_notebook_retravaill!I2>Result_notebook_retravaill!G2,0,IF(Result_notebook_retravaill!I2+Result_notebook_retravaill!J2>Result_notebook_retravaill!G2,Result_notebook_retravaill!G2-Result_notebook_retravaill!I2,Result_notebook_retravaill!J2)) -> 0 | L2: =IF(Result_notebook_retravaill!I2>Result_notebook_retravaill!G2,0,IF(Result_notebook_retravaill!I2+Result_notebook_retravaill!J2>Result_notebook_retravaill!G2,0,Result_notebook_retravaill!M2)) -> 9556.3204 | M2: =SUM(J2:L2)-G2 -> 0
A3: =Result_notebook_retravaill!A3 -> 2025 | B3: =Result_notebook_retravaill!B3 -> Cobalt | C3: =Result_notebook_retravaill!C3 -> Canada Net-zero | D3: =Result_notebook_retravaill!D3 -> Existing production | E3: =Result_notebook_retravaill!E3 -> Current shares | F3: =Result_notebook_retravaill!F3 -> Status Quo | G3: =Result_notebook_retravaill!G3 -> 9556.3204 | H3: =IF(Result_notebook_retravaill!I3>Result_notebook_retravaill!G3,Result_notebook_retravaill!I3/Result_notebook_retravaill!N3,Result_notebook_retravaill!H3) -> 3494 | I3: =Result_notebook_retravaill!K3 -> 18224.91 | J3: =MIN(G3,Result_notebook_retravaill!I3) -> 1482.0913 | K3: =IF(Result_notebook_retravaill!I3>Result_notebook_retravaill!G3,0,IF(Result_notebook_retravaill!I3+Result_notebook_retravaill!J3>Result_notebook_retravaill!G3,Result_notebook_retravaill!G3-Result_notebook_retravaill!I3,Result_notebook_retravaill!J3)) -> 52.985592 | L3: =IF(Result_notebook_retravaill!I3>Result_notebook_retravaill!G3,0,IF(Result_notebook_retravaill!I3+Result_notebook_retravaill!J3>Result_notebook_retravaill!G3,0,Result_notebook_retravaill!M3)) -> 8021.2435 | M3: =SUM(J3:L3)-G3 -> 0
A4: =Result_notebook_retravaill!A4 -> 2025 | B4: =Result_notebook_retravaill!B4 -> Cobalt | C4: =Result_notebook_retravaill!C4 -> Canada Net-zero | D4: =Result_notebook_retravaill!D4 -> Production potential | E4: =Result_notebook_retravaill!E4 -> Current shares | F4: =Result_notebook_retravaill!F4 -> Expansion Extractive | G4: =Result_notebook_retravaill!G4 -> 9556.3204 | H4: =IF(Result_notebook_retravaill!I4>Result_notebook_retravaill!G4,Result_notebook_retravaill!I4/Result_notebook_retravaill!N4,Result_notebook_retravaill!H4) -> 3850.4061 | I4: =Result_notebook_retravaill!K4 -> 17868.504 | J4: =MIN(G4,Result_notebook_retravaill!I4) -> 1633.2723 | K4: =IF(Result_notebook_retravaill!I4>Result_notebook_retravaill!G4,0,IF(Result_notebook_retravaill!I4+Result_notebook_retravaill!J4>Result_notebook_retravaill!G4,Result_notebook_retravaill!G4-Result_notebook_retravaill!I4,Result_notebook_retravaill!J4)) -> 58.390396 | L4: =IF(Result_notebook_retravaill!I4>Result_notebook_retravaill!G4,0,IF(Result_notebook_retravaill!I4+Result_notebook_retravaill!J4>Result_notebook_retravaill!G4,0,Result_notebook_retravaill!M4)) -> 7864.6577 | M4: =SUM(J4:L4)-G4 -> 0
A5: =Result_notebook_retravaill!A5 -> 2025 | B5: =Result_notebook_retravaill!B5 -> Cobalt | C5: =Result_notebook_retravaill!C5 -> Canada Net-zero | D5: =Result_notebook_retravaill!D5 -> Production potential | E5: =Result_notebook_retravaill!E5 -> Current shares | F5: =Result_notebook_retravaill!F5 -> Expansion Extractive+Circularity | G5: =Result_notebook_retravaill!G5 -> 9556.3204 | H5: =IF(Result_notebook_retravaill!I5>Result_notebook_retravaill!G5,Result_notebook_retravaill!I5/Result_notebook_retravaill!N5,Result_notebook_retravaill!H5) -> 3850.4061 | I5: =Result_notebook_retravaill!K5 -> 17868.504 | J5: =MIN(G5,Result_notebook_retravaill!I5) -> 1633.2723 | K5: =IF(Result_notebook_retravaill!I5>Result_notebook_retravaill!G5,0,IF(Result_notebook_retravaill!I5+Result_notebook_retravaill!J5>Result_notebook_retravaill!G5,Result_notebook_retravaill!G5-Result_notebook_retravaill!I5,Result_notebook_retravaill!J5)) -> 58.390396 | L5: =IF(Result_notebook_retravaill!I5>Result_notebook_retravaill!G5,0,IF(Result_notebook_retravaill!I5+Result_notebook_retravaill!J5>Result_notebook_retravaill!G5,0,Result_notebook_retravaill!M5)) -> 7864.6577 | M5: =SUM(J5:L5)-G5 -> 0
A6: =Result_notebook_retravaill!A6 -> 2025 | B6: =Result_notebook_retravaill!B6 -> Cobalt | C6: =Result_notebook_retravaill!C6 -> Canada Net-zero | D6: =Result_notebook_retravaill!D6 -> Production potential | E6: =Result_notebook_retravaill!E6 -> 100% CAN | F6: =Result_notebook_retravaill!F6 -> Integrated | G6: =Result_notebook_retravaill!G6 -> 9556.3204 | H6: =IF(Result_notebook_retravaill!I6>Result_notebook_retravaill!G6,Result_notebook_retravaill!I6/Result_notebook_retravaill!N6,Result_notebook_retravaill!H6) -> 3850.4061 | I6: =Result_notebook_retravaill!K6 -> 17868.504 | J6: =MIN(G6,Result_notebook_retravaill!I6) -> 1691.6627 | K6: =IF(Result_notebook_retravaill!I6>Result_notebook_retravaill!G6,0,IF(Result_notebook_retravaill!I6+Result_notebook_retravaill!J6>Result_notebook_retravaill!G6,Result_notebook_retravaill!G6-Result_notebook_retravaill!I6,Result_notebook_retravaill!J6)) -> 0 | L6: =IF(Result_notebook_retravaill!I6>Result_notebook_retravaill!G6,0,IF(Result_notebook_retravaill!I6+Result_notebook_retravaill!J6>Result_notebook_retravaill!G6,0,Result_notebook_retravaill!M6)) -> 7864.6577 | M6: =SUM(J6:L6)-G6 -> 0
A7: =Result_notebook_retravaill!A7 -> 2025 | B7: =Result_notebook_retravaill!B7 -> Cobalt | C7: =Result_notebook_retravaill!C7 -> Current Measures | D7: =Result_notebook_retravaill!D7 -> Existing production | E7: =Result_notebook_retravaill!E7 -> Current shares | F7: =Result_notebook_retravaill!F7 -> NIMBY | G7: =Result_notebook_retravaill!G7 -> 8776.8729 | H7: =IF(Result_notebook_retravaill!I7>Result_notebook_retravaill!G7,Result_notebook_retravaill!I7/Result_notebook_retravaill!N7,Result_notebook_retravaill!H7) -> 0 | I7: =Result_notebook_retravaill!K7 -> 19947.438 | J7: =MIN(G7,Result_notebook_retravaill!I7) -> 0 | K7: =IF(Result_notebook_retravaill!I7>Result_notebook_retravaill!G7,0,IF(Result_notebook_retravaill!I7+Result_notebook_retravaill!J7>Result_notebook_retravaill!G7,Result_notebook_retravaill!G7-Result_notebook_retravaill!I7,Result_notebook_retravaill!J7)) -> 0 | L7: =IF(Result_notebook_retravaill!I7>Result_notebook_retravaill!G7,0,IF(Result_notebook_retravaill!I7+Result_notebook_retravaill!J7>Result_notebook_retravaill!G7,0,Result_notebook_retravaill!M7)) -> 8776.8729 | M7: =SUM(J7:L7)-G7 -> 0
A8: =Result_notebook_retravaill!A8 -> 2025 | B8: =Result_notebook_retravaill!B8 -> Cobalt | C8: =Result_notebook_retravaill!C8 -> Current Measures | D8: =Result_notebook_retravaill!D8 -> Existing production | E8: =Result_notebook_retravaill!E8 -> Current shares | F8: =Result_notebook_retravaill!F8 -> Status Quo | G8: =Result_notebook_retravaill!G8 -> 8776.8729 | H8: =IF(Result_notebook_retravaill!I8>Result_notebook_retravaill!G8,Result_notebook_retravaill!I8/Result_notebook_retravaill!N8,Result_notebook_retravaill!H8) -> 3494 | I8: =Result_notebook_retravaill!K8 -> 16453.438 | J8: =MIN(G8,Result_notebook_retravaill!I8) -> 1482.0913 | K8: =IF(Result_notebook_retravaill!I8>Result_notebook_retravaill!G8,0,IF(Result_notebook_retravaill!I8+Result_notebook_retravaill!J8>Result_notebook_retravaill!G8,Result_notebook_retravaill!G8-Result_notebook_retravaill!I8,Result_notebook_retravaill!J8)) -> 52.985592 | L8: =IF(Result_notebook_retravaill!I8>Result_notebook_retravaill!G8,0,IF(Result_notebook_retravaill!I8+Result_notebook_retravaill!J8>Result_notebook_retravaill!G8,0,Result_notebook_retravaill!M8)) -> 7241.796 | M8: =SUM(J8:L8)-G8 -> 0
A9: =Result_notebook_retravaill!A9 -> 2025 | B9: =Result_notebook_retravaill!B9 -> Cobalt | C9: =Result_notebook_retravaill!C9 -> Current Measures | D9: =Result_notebook_retravaill!D9 -> Production potential | E9: =Result_notebook_retravaill!E9 -> Current shares | F9: =Result_notebook_retravaill!F9 -> Expansion Extractive | G9: =Result_notebook_retravaill!G9 -> 8776.8729 | H9: =IF(Result_notebook_retravaill!I9>Result_notebook_retravaill!G9,Result_notebook_retravaill!I9/Result_notebook_retravaill!N9,Result_notebook_retravaill!H9) -> 3850.4061 | I9: =Result_notebook_retravaill!K9 -> 16097.032 | J9: =MIN(G9,Result_notebook_retravaill!I9) -> 1633.2723 | K9: =IF(Result_notebook_retravaill!I9>Result_notebook_retravaill!G9,0,IF(Result_notebook_retravaill!I9+Result_notebook_retravaill!J9>Result_notebook_retravaill!G9,Result_notebook_retravaill!G9-Result_notebook_retravaill!I9,Result_notebook_retravaill!J9)) -> 58.390396 | L9: =IF(Result_notebook_retravaill!I9>Result_notebook_retravaill!G9,0,IF(Result_notebook_retravaill!I9+Result_notebook_retravaill!J9>Result_notebook_retravaill!G9,0,Result_notebook_retravaill!M9)) -> 7085.2102 | M9: =SUM(J9:L9)-G9 -> 0
A10: =Result_notebook_retravaill!A10 -> 2025 | B10: =Result_notebook_retravaill!B10 -> Cobalt | C10: =Result_notebook_retravaill!C10 -> Current Measures | D10: =Result_notebook_retravaill!D10 -> Production potential | E10: =Result_notebook_retravaill!E10 -> Current shares | F10: =Result_notebook_retravaill!F10 -> Expansion Extractive+Circularity | G10: =Result_notebook_retravaill!G10 -> 8776.8729 | H10: =IF(Result_notebook_retravaill!I10>Result_notebook_retravaill!G10,Result_notebook_retravaill!I10/Result_notebook_retravaill!N10,Result_notebook_retravaill!H10) -> 3850.4061 | I10: =Result_notebook_retravaill!K10 -> 16097.032 | J10: =MIN(G10,Result_notebook_retravaill!I10) -> 1633.2723 | K10: =IF(Result_notebook_retravaill!I10>Result_notebook_retravaill!G10,0,IF(Result_notebook_retravaill!I10+Result_notebook_retravaill!J10>Result_notebook_retravaill!G10,Result_notebook_retravaill!G10-Result_notebook_retravaill!I10,Result_notebook_retravaill!J10)) -> 58.390396 | L10: =IF(Result_notebook_retravaill!I10>Result_notebook_retravaill!G10,0,IF(Result_notebook_retravaill!I10+Result_notebook_retravaill!J10>Result_notebook_retravaill!G10,0,Result_notebook_retravaill!M10)) -> 7085.2102 | M10: =SUM(J10:L10)-G10 -> 0
A11: =Result_notebook_retravaill!A11 -> 2025 | B11: =Result_notebook_retravaill!B11 -> Cobalt | C11: =Result_notebook_retravaill!C11 -> Current Measures | D11: =Result_notebook_retravaill!D11 -> Production potential | E11: =Result_notebook_retravaill!E11 -> 100% CAN | F11: =Result_notebook_retravaill!F11 -> Integrated | G11: =Result_notebook_retravaill!G11 -> 8776.8729 | H11: =IF(Result_notebook_retravaill!I11>Result_notebook_retravaill!G11,Result_notebook_retravaill!I11/Result_notebook_retravaill!N11,Result_notebook_retravaill!H11) -> 3850.4061 | I11: =Result_notebook_retravaill!K11 -> 16097.032 | J11: =MIN(G11,Result_notebook_retravaill!I11) -> 1691.6627 | K11: =IF(Result_notebook_retravaill!I11>Result_notebook_retravaill!G11,0,IF(Result_notebook_retravaill!I11+Result_notebook_retravaill!J11>Result_notebook_retravaill!G11,Result_notebook_retravaill!G11-Result_notebook_retravaill!I11,Result_notebook_retravaill!J11)) -> 0 | L11: =IF(Result_notebook_retravaill!I11>Result_notebook_retravaill!G11,0,IF(Result_notebook_retravaill!I11+Result_notebook_retravaill!J11>Result_notebook_retravaill!G11,0,Result_notebook_retravaill!M11)) -> 7085.2102 | M11: =SUM(J11:L11)-G11 -> 0
A12: =Result_notebook_retravaill!A12 -> 2025 | B12: =Result_notebook_retravaill!B12 -> Cobalt | C12: =Result_notebook_retravaill!C12 -> Global Net-zero | D12: =Result_notebook_retravaill!D12 -> Existing production | E12: =Result_notebook_retravaill!E12 -> Current shares | F12: =Result_notebook_retravaill!F12 -> NIMBY | G12: =Result_notebook_retravaill!G12 -> 9422.7256 | H12: =IF(Result_notebook_retravaill!I12>Result_notebook_retravaill!G12,Result_notebook_retravaill!I12/Result_notebook_retravaill!N12,Result_notebook_retravaill!H12) -> 0 | I12: =Result_notebook_retravaill!K12 -> 21415.285 | J12: =MIN(G12,Result_notebook_retravaill!I12) -> 0 | K12: =IF(Result_notebook_retravaill!I12>Result_notebook_retravaill!G12,0,IF(Result_notebook_retravaill!I12+Result_notebook_retravaill!J12>Result_notebook_retravaill!G12,Result_notebook_retravaill!G12-Result_notebook_retravaill!I12,Result_notebook_retravaill!J12)) -> 0 | L12: =IF(Result_notebook_retravaill!I12>Result_notebook_retravaill!G12,0,IF(Result_notebook_retravaill!I12+Result_notebook_retravaill!J12>Result_notebook_retravaill!G12,0,Result_notebook_retravaill!M12)) -> 9422.7256 | M12: =SUM(J12:L12)-G12 -> 0
A13: =Result_notebook_retravaill!A13 -> 2025 | B13: =Result_notebook_retravaill!B13 -> Cobalt | C13: =Result_notebook_retravaill!C13 -> Global Net-zero | D13: =Result_notebook_retravaill!D13 -> Existing production | E13: =Result_notebook_retravaill!E13 -> Current shares | F13: =Result_notebook_retravaill!F13 -> Status Quo | G13: =Result_notebook_retravaill!G13 -> 9422.7256 | H13: =IF(Result_notebook_retravaill!I13>Result_notebook_retravaill!G13,Result_notebook_retravaill!I13/Result_notebook_retravaill!N13,Result_notebook_retravaill!H13) -> 3494 | I13: =Result_notebook_retravaill!K13 -> 17921.285 | J13: =MIN(G13,Result_notebook_retravaill!I13) -> 1482.0913 | K13: =IF(Result_notebook_retravaill!I13>Result_notebook_retravaill!G13,0,IF(Result_notebook_retravaill!I13+Result_notebook_retravaill!J13>Result_notebook_retravaill!G13,Result_notebook_retravaill!G13-Result_notebook_retravaill!I13,Result_notebook_retravaill!J13)) -> 52.985592 | L13: =IF(Result_notebook_retravaill!I13>Result_notebook_retravaill!G13,0,IF(Result_notebook_retravaill!I13+Result_notebook_retravaill!J13>Result_notebook_retravaill!G13,0,Result_notebook_retravaill!M13)) -> 7887.6487 | M13: =SUM(J13:L13)-G13 -> 0
... A1441: =Result_notebook_retravaill!A1441 -> 2040 | B1441: =Result_notebook_retravaill!B1441 -> Lithium | C1441: =Result_notebook_retravaill!C1441 -> Global Net-zero | D1441: =Result_notebook_retravaill!D1441 -> Production potential | E1441: =Result_notebook_retravaill!E1441 -> 100% CAN | F1441: =Result_notebook_retravaill!F1441 -> Integrated | G1441: =Result_notebook_retravaill!G1441 -> 82859.957 | H1441: =IF(Result_notebook_retravaill!I1441>Result_notebook_retravaill!G1441,Result_notebook_retravaill!I1441/Result_notebook_retravaill!N1441,Result_notebook_retravaill!H1441) -> 546435 | I1441: =Result_notebook_retravaill!K1441 -> 0 | J1441: =MIN(G1441,Result_notebook_retravaill!I1441) -> 82859.957 | K1441: =IF(Result_notebook_retravaill!I1441>Result_notebook_retravaill!G1441,0,IF(Result_notebook_retravaill!I1441+Result_notebook_retravaill!J1441>Result_notebook_retravaill!G1441,Result_notebook_retravaill!G1441-Result_notebook_retravaill!I1441,Result_notebook_retravaill!J1441)) -> 0 | L1441: =IF(Result_notebook_retravaill!I1441>Result_notebook_retravaill!G1441,0,IF(Result_notebook_retravaill!I1441+Result_notebook_retravaill!J1441>Result_notebook_retravaill!G1441,0,Result_notebook_retravaill!M1441)) -> 0 | M1441: =SUM(J1441:L1441)-G1441 -> 0

Sheet Result_notebook_retravaill
A1: Year | B1: Metal | C1: Demand scenario CER | D1: Production scenario CCI | E1: Production scenario CCI|Refining CAN share | F1: Supply scenario | G1: Demand_value_t | H1: Mining CA | I1: Refining CA (mining CA) | J1: Refining RoW (mining CA) | K1: Mining RoW | L1: Refining RoW (mining RoW) | M1: Refining RoW (mining RoW) | N1: Production_yield | O1: Demand - sum refining | P1: Export potential refining CAN | Q1: Test production yield
A2: 2025 | B2: Cobalt | C2: Canada Net-zero | D2: Existing production | E2: Current shares | F2: NIMBY | G2: 9556.3204 | H2: 0 | I2: 0 | J2: =H2*N2-I2 -> 0 | K2: 21718.91 | L2: 9556.3204 | M2: =MAX(L2-J2,0) -> 9556.3204 | N2: =Result_notebook!L2 -> 0.43934657 | O2: =G2-(I2+J2+M2) -> 0 | P2: =MAX(I2-G2,0) -> 0 | Q2: =(H2*N2)-I2 -> 0
A3: 2025 | B3: Cobalt | C3: Canada Net-zero | D3: Existing production | E3: Current shares | F3: Status Quo | G3: 9556.3204 | H3: 3494 | I3: 1482.0913 | J3: =H3*N3-I3 -> 52.985592 | K3: 18224.91 | L3: 8074.2291 | M3: =MAX(L3-J3,0) -> 8021.2435 | N3: =Result_notebook!L3 -> 0.43934657 | O3: =G3-(I3+J3+M3) -> 0 | P3: =MAX(I3-G3,0) -> 0 | Q3: =(H3*N3)-I3 -> 52.985592
A4: 2025 | B4: Cobalt | C4: Canada Net-zero | D4: Production potential | E4: Current shares | F4: Expansion Extractive | G4: 9556.3204 | H4: 3850.4061 | I4: 1633.2723 | J4: =H4*N4-I4 -> 58.390396 | K4: 17868.504 | L4: 7923.0481 | M4: =MAX(L4-J4,0) -> 7864.6577 | N4: =Result_notebook!L4 -> 0.43934657 | O4: =G4-(I4+J4+M4) -> 0 | P4: =MAX(I4-G4,0) -> 0 | Q4: =(H4*N4)-I4 -> 58.390396
A5: 2025 | B5: Cobalt | C5: Canada Net-zero | D5: Production potential | E5: Current shares | F5: Expansion Extractive+Circularity | G5: 9556.3204 | H5: 3850.4061 | I5: 1633.2723 | J5: =H5*N5-I5 -> 58.390396 | K5: 17868.504 | L5: 7923.0481 | M5: =MAX(L5-J5,0) -> 7864.6577 | N5: =Result_notebook!L5 -> 0.43934657 | O5: =G5-(I5+J5+M5) -> 0 | P5: =MAX(I5-G5,0) -> 0 | Q5: =(H5*N5)-I5 -> 58.390396
A6: 2025 | B6: Cobalt | C6: Canada Net-zero | D6: Production potential | E6: 100% CAN | F6: Integrated | G6: 9556.3204 | H6: 3850.4061 | I6: 1691.6627 | J6: =H6*N6-I6 -> 0 | K6: 17868.504 | L6: 7864.6577 | M6: =MAX(L6-J6,0) -> 7864.6577 | N6: =Result_notebook!L6 -> 0.43934657 | O6: =G6-(I6+J6+M6) -> 0 | P6: =MAX(I6-G6,0) -> 0 | Q6: =(H6*N6)-I6 -> 0
A7: 2025 | B7: Cobalt | C7: Current Measures | D7: Existing production | E7: Current shares | F7: NIMBY | G7: 8776.8729 | H7: 0 | I7: 0 | J7: =H7*N7-I7 -> 0 | K7: 19947.438 | L7: 8776.8729 | M7: =MAX(L7-J7,0) -> 8776.8729 | N7: =Result_notebook!L7 -> 0.43934657 | O7: =G7-(I7+J7+M7) -> 0 | P7: =MAX(I7-G7,0) -> 0 | Q7: =(H7*N7)-I7 -> 0
A8: 2025 | B8: Cobalt | C8: Current Measures | D8: Existing production | E8: Current shares | F8: Status Quo | G8: 8776.8729 | H8: 3494 | I8: 1482.0913 | J8: =H8*N8-I8 -> 52.985592 | K8: 16453.438 | L8: 7294.7816 | M8: =MAX(L8-J8,0) -> 7241.796 | N8: =Result_notebook!L8 -> 0.43934657 | O8: =G8-(I8+J8+M8) -> 0 | P8: =MAX(I8-G8,0) -> 0 | Q8: =(H8*N8)-I8 -> 52.985592
A9: 2025 | B9: Cobalt | C9: Current Measures | D9: Production potential | E9: Current shares | F9: Expansion Extractive | G9: 8776.8729 | H9: 3850.4061 | I9: 1633.2723 | J9: =H9*N9-I9 -> 58.390396 | K9: 16097.032 | L9: 7143.6006 | M9: =MAX(L9-J9,0) -> 7085.2102 | N9: =Result_notebook!L9 -> 0.43934657 | O9: =G9-(I9+J9+M9) -> 0 | P9: =MAX(I9-G9,0) -> 0 | Q9: =(H9*N9)-I9 -> 58.390396
A10: 2025 | B10: Cobalt | C10: Current Measures | D10: Production potential | E10: Current shares | F10: Expansion Extractive+Circularity | G10: 8776.8729 | H10: 3850.4061 | I10: 1633.2723 | J10: =H10*N10-I10 -> 58.390396 | K10: 16097.032 | L10: 7143.6006 | M10: =MAX(L10-J10,0) -> 7085.2102 | N10: =Result_notebook!L10 -> 0.43934657 | O10: =G10-(I10+J10+M10) -> 0 | P10: =MAX(I10-G10,0) -> 0 | Q10: =(H10*N10)-I10 -> 58.390396
A11: 2025 | B11: Cobalt | C11: Current Measures | D11: Production potential | E11: 100% CAN | F11: Integrated | G11: 8776.8729 | H11: 3850.4061 | I11: 1691.6627 | J11: =H11*N11-I11 -> 0 | K11: 16097.032 | L11: 7085.2102 | M11: =MAX(L11-J11,0) -> 7085.2102 | N11: =Result_notebook!L11 -> 0.43934657 | O11: =G11-(I11+J11+M11) -> 0 | P11: =MAX(I11-G11,0) -> 0 | Q11: =(H11*N11)-I11 -> 0
A12: 2025 | B12: Cobalt | C12: Global Net-zero | D12: Existing production | E12: Current shares | F12: NIMBY | G12: 9422.7256 | H12: 0 | I12: 0 | J12: =H12*N12-I12 -> 0 | K12: 21415.285 | L12: 9422.7256 | M12: =MAX(L12-J12,0) -> 9422.7256 | N12: =Result_notebook!L12 -> 0.43934657 | O12: =G12-(I12+J12+M12) -> 0 | P12: =MAX(I12-G12,0) -> 0 | Q12: =(H12*N12)-I12 -> 0
A13: 2025 | B13: Cobalt | C13: Global Net-zero | D13: Existing production | E13: Current shares | F13: Status Quo | G13: 9422.7256 | H13: 3494 | I13: 1482.0913 | J13: =H13*N13-I13 -> 52.985592 | K13: 17921.285 | L13: 7940.6343 | M13: =MAX(L13-J13,0) -> 7887.6487 | N13: =Result_notebook!L13 -> 0.43934657 | O13: =G13-(I13+J13+M13) -> 0 | P13: =MAX(I13-G13,0) -> 0 | Q13: =(H13*N13)-I13 -> 52.985592
... A1441: 2040 | B1441: Lithium | C1441: Global Net-zero | D1441: Production potential | E1441: 100% CAN | F1441: Integrated | G1441: 82859.957 | H1441: 615511.71 | I1441: 430347.61 | J1441: =H1441*N1441-I1441 -> 54401.711 | K1441: 0 | L1441: 0 | M1441: =MAX(L1441-J1441,0) -> 0 | N1441: =Result_notebook!L1441 -> 0.787555 | O1441: =G1441-(I1441+J1441+M1441) -> -401889.37 | P1441: =MAX(I1441-G1441,0) -> 347487.66 | Q1441: =(H1441*N1441)-I1441 -> 54401.711

Sheet Result_notebook
A1: Year | B1: Metal | C1: Demand scenario CER | D1: Production scenario CCI | E1: Production scenario CCI|Refining CAN share | F1: Supply scenario | G1: Demand_value_t | H1: Production_mining_CAN_t | I1: Production_refining_CAN_t | J1: Production_mining_RoW_t | K1: Production_refining_RoW_t | L1: Production_yield
A2: 2025 | B2: Cobalt | C2: Canada Net-zero | D2: Existing production | E2: Current shares | F2: NIMBY | G2: 9556.3204 | H2: 0 | I2: 0 | J2: 21751.212 | K2: 9556.3204 | L2: 0.43934657
A3: 2025 | B3: Cobalt | C3: Canada Net-zero | D3: Existing production | E3: Current shares | F3: Status Quo | G3: 9556.3204 | H3: 3494 | I3: 1482.0913 | J3: 18257.212 | K3: 8074.2291 | L3: 0.43934657
A4: 2025 | B4: Cobalt | C4: Canada Net-zero | D4: Production potential | E4: Current shares | F4: Expansion Extractive | G4: 9556.3204 | H4: 3850.4061 | I4: 1633.2723 | J4: 17900.806 | K4: 7923.0481 | L4: 0.43934657
A5: 2025 | B5: Cobalt | C5: Canada Net-zero | D5: Production potential | E5: Current shares | F5: Expansion Extractive+Circularity | G5: 9556.3204 | H5: 3850.4061 | I5: 1633.2723 | J5: 17900.806 | K5: 7923.0481 | L5: 0.43934657
A6: 2025 | B6: Cobalt | C6: Canada Net-zero | D6: Production potential | E6: 100% CAN | F6: Integrated | G6: 9556.3204 | H6: 3850.4061 | I6: 1691.6627 | J6: 17900.806 | K6: 7864.6577 | L6: 0.43934657
A7: 2025 | B7: Cobalt | C7: Current Measures | D7: Existing production | E7: Current shares | F7: NIMBY | G7: 8776.8729 | H7: 0 | I7: 0 | J7: 19977.106 | K7: 8776.8729 | L7: 0.43934657
A8: 2025 | B8: Cobalt | C8: Current Measures | D8: Existing production | E8: Current shares | F8: Status Quo | G8: 8776.8729 | H8: 3494 | I8: 1482.0913 | J8: 16483.106 | K8: 7294.7816 | L8: 0.43934657
A9: 2025 | B9: Cobalt | C9: Current Measures | D9: Production potential | E9: Current shares | F9: Expansion Extractive | G9: 8776.8729 | H9: 3850.4061 | I9: 1633.2723 | J9: 16126.7 | K9: 7143.6006 | L9: 0.43934657
A10: 2025 | B10: Cobalt | C10: Current Measures | D10: Production potential | E10: Current shares | F10: Expansion Extractive+Circularity | G10: 8776.8729 | H10: 3850.4061 | I10: 1633.2723 | J10: 16126.7 | K10: 7143.6006 | L10: 0.43934657
A11: 2025 | B11: Cobalt | C11: Current Measures | D11: Production potential | E11: 100% CAN | F11: Integrated | G11: 8776.8729 | H11: 3850.4061 | I11: 1691.6627 | J11: 16126.7 | K11: 7085.2102 | L11: 0.43934657
A12: 2025 | B12: Cobalt | C12: Global Net-zero | D12: Existing production | E12: Current shares | F12: NIMBY | G12: 9422.7256 | H12: 0 | I12: 0 | J12: 21447.136 | K12: 9422.7256 | L12: 0.43934657
A13: 2025 | B13: Cobalt | C13: Global Net-zero | D13: Existing production | E13: Current shares | F13: Status Quo | G13: 9422.7256 | H13: 3494 | I13: 1482.0913 | J13: 17953.136 | K13: 7940.6343 | L13: 0.43934657
... A1441: 2040 | B1441: Nickel | C1441: Global Net-zero | D1441: Production potential | E1441: 100% CAN | F1441: Integrated | G1441: 194473.95 | H1441: 282129.48 | I1441: 222192.48 | J1441: 0 | K1441: 0 | L1441: 0.787555

Sheet SUPPLY
A1: # | B1: Supply scenario | C1: Production scenario CCI | D1: Mining_RoW | E1: Production scenario CCI|Refining CAN share | F1: Refining_RoW | G1: Secondary_production | H1: Associated LCIs
A2: 1 | B2: NIMBY | C2: 0 | D2: 100% occured in RoW | E2: 0 | F2: 100% occured in RoW | G2: BAU
A3: 2 | B3: Status Quo | C3: Existing production | D3: Difference between demand and CAN supply is sourced from RoW | E3: Current shares | F3: Difference between demand and CAN supply is sourced from RoW | G3: BAU
A4: 3 | B4: Expansion Extractive | C4: Production potential | D4: Difference between demand and CAN supply is sourced from RoW | E4: Current shares | F4: Difference between demand and CAN supply is sourced from RoW | G4: BAU
A5: 4 | B5: Expansion Extractive+Circularity | C5: Production potential | D5: Difference between demand and CAN supply is sourced from RoW | E5: Current shares | F5: Difference between demand and CAN supply is sourced from RoW | G5: NZE
A6: 5 | B6: Integrated | C6: Production potential | D6: Difference between demand and CAN supply is sourced from RoW | E6: 100% CAN | F6: Difference between demand and CAN supply is sourced from RoW | G6: BAU

Sheet DEMAND
A1: Demand scenario CER | B1: Country | C1: Year | D1: Metal | E1: Demand_value_t
A2: Canada Net-zero | B2: Canada | C2: 2020 | D2: Cobalt | E2: 1093.0696
A3: Canada Net-zero | B3: Canada | C3: 2021 | D3: Cobalt | E3: 1169.5356
A4: Canada Net-zero | B4: Canada | C4: 2022 | D4: Cobalt | E4: 1380.3796
A5: Canada Net-zero | B5: Canada | C5: 2023 | D5: Cobalt | E5: 1460.0596
A6: Canada Net-zero | B6: Canada | C6: 2024 | D6: Cobalt | E6: 6136.1112
A7: Canada Net-zero | B7: Canada | C7: 2025 | D7: Cobalt | E7: 9556.3204
A8: Canada Net-zero | B8: Canada | C8: 2026 | D8: Cobalt | E8: 14666.709
A9: Canada Net-zero | B9: Canada | C9: 2027 | D9: Cobalt | E9: 22846.057
A10: Canada Net-zero | B10: Canada | C10: 2028 | D10: Cobalt | E10: 33558.204
A11: Canada Net-zero | B11: Canada | C11: 2029 | D11: Cobalt | E11: 45543.652
A12: Canada Net-zero | B12: Canada | C12: 2030 | D12: Cobalt | E12: 58753.881
A13: Canada Net-zero | B13: Canada | C13: 2031 | D13: Cobalt | E13: 74634.661
... A531: Global Net-zero | B531: Canada | C531: 2050 | D531: Nickel | E531: 267966.24

Sheet PRODUCTION
A1: Metal | B1: Year | C1: Production scenario CCI | D1: Production scenario CCI|Refining CAN share | E1: Value | F1: Unit | G1: Production_mining_CAN_t | H1: Production_refining_CAN_t
A2: Cobalt | B2: 2018 | C2: Existing production | D2: 100% CAN | E2: 4.1361 | F2: kilotonnes | G2: 4136.1 | H2: 1817.1813
A3: Cobalt | B3: 2019 | C3: Existing production | D3: 100% CAN | E3: 3.433 | F3: kilotonnes | G3: 3433 | H3: 1508.2768
A4: Cobalt | B4: 2020 | C4: Existing production | D4: 100% CAN | E4: 3.236324 | F4: kilotonnes | G4: 3236.324 | H4: 1421.8678
A5: Cobalt | B5: 2021 | C5: Existing production | D5: 100% CAN | E5: 3.808657 | F5: kilotonnes | G5: 3808.657 | H5: 1673.3204
A6: Cobalt | B6: 2022 | C6: Existing production | D6: 100% CAN | E6: 2.536143 | F6: kilotonnes | G6: 2536.143 | H6: 1114.2457
A7: Cobalt | B7: 2023 | C7: Existing production | D7: 100% CAN | E7: 4.796 | F7: kilotonnes | G7: 4796 | H7: 2107.1061
A8: Cobalt | B8: 2024 | C8: Existing production | D8: 100% CAN | E8: 3.381 | F8: kilotonnes | G8: 3381 | H8: 1485.4307
A9: Cobalt | B9: 2025 | C9: Existing production | D9: 100% CAN | E9: 3.494 | F9: kilotonnes | G9: 3494 | H9: 1535.0769
A10: Cobalt | B10: 2026 | C10: Existing production | D10: 100% CAN | E10: 3.494 | F10: kilotonnes | G10: 3494 | H10: 1535.0769
A11: Cobalt | B11: 2027 | C11: Existing production | D11: 100% CAN | E11: 4.176 | F11: kilotonnes | G11: 4176 | H11: 1834.7113
A12: Cobalt | B12: 2028 | C12: Existing production | D12: 100% CAN | E12: 4.176 | F12: kilotonnes | G12: 4176 | H12: 1834.7113
A13: Cobalt | B13: 2029 | C13: Existing production | D13: 100% CAN | E13: 3.861 | F13: kilotonnes | G13: 3861 | H13: 1696.3171
... A70: Copper | B70: 2040 | C70: Existing production | D70: 100% CAN | E70: 183.019 | F70: kilotonnes | G70: 183019 | H70: 152774.33
A71: Copper | B71: 2018 | C71: Production potential | D71: 100% CAN | E71: 535.509 | F71: kilotonnes | G71: 535509 | H71: 447013.87 | J71: =H71/G71 -> 0.83474576
A72: Copper | B72: 2019 | C72: Production potential | D72: 100% CAN | E72: 557.849 | F72: kilotonnes | G72: 557849 | H72: 465662.09 | J72: =H72/G72 -> 0.83474576
A73: Copper | B73: 2020 | C73: Production potential | D73: 100% CAN | E73: 530.921 | F73: kilotonnes | G73: 530921 | H73: 443184.06 | J73: =H73/G73 -> 0.83474576
A74: Copper | B74: 2021 | C74: Production potential | D74: 100% CAN | E74: 488.522 | F74: kilotonnes | G74: 488522 | H74: 407791.67 | J74: =H74/G74 -> 0.83474576
A75: Copper | B75: 2022 | C75: Production potential | D75: 100% CAN | E75: 460.415 | F75: kilotonnes | G75: 460415 | H75: 384329.47 | J75: =H75/G75 -> 0.83474576
A76: Copper | B76: 2023 | C76: Production potential | D76: 100% CAN | E76: 483.968 | F76: kilotonnes | G76: 483968 | H76: 403990.23 | J76: =H76/G76 -> 0.83474576
A77: Copper | B77: 2024 | C77: Production potential | D77: 100% CAN | E77: 508.72587 | F77: kilotonnes | G77: 508725.87 | H77: 424656.76 | J77: =H77/G77 -> 0.83474576
A78: Copper | B78: 2025 | C78: Production potential | D78: 100% CAN | E78: 534.75026 | F78: kilotonnes | G78: 534750.26 | H78: 446380.51 | J78: =H78/G78 -> 0.83474576 | L78: =G78*0.83 -> 443842.71
A79: Copper | B79: 2026 | C79: Production potential | D79: 100% CAN | E79: 562.10595 | F79: kilotonnes | G79: 562105.95 | H79: 469215.56 | J79: =H79/G79 -> 0.83474576
A80: Copper | B80: 2027 | C80: Production potential | D80: 100% CAN | E80: 590.86105 | F80: kilotonnes | G80: 590861.05 | H80: 493218.76 | J80: =H80/G80 -> 0.83474576
A81: Copper | B81: 2028 | C81: Production potential | D81: 100% CAN | E81: 621.08715 | F81: kilotonnes | G81: 621087.15 | H81: 518449.86 | J81: =H81/G81 -> 0.83474576
A82: Copper | B82: 2029 | C82: Production potential | D82: 100% CAN | E82: 652.85949 | F82: kilotonnes | G82: 652859.49 | H82: 544971.69 | J82: =H82/G82 -> 0.83474576
A83: Copper | B83: 2030 | C83: Production potential | D83: 100% CAN | E83: 686.25718 | F83: kilotonnes | G83: 686257.18 | H83: 572850.27 | J83: =H83/G83 -> 0.83474576
A84: Copper | B84: 2031 | C84: Production potential | D84: 100% CAN | E84: 721.36336 | F84: kilotonnes | G84: 721363.36 | H84: 602155.01 | J84: =H84/G84 -> 0.83474576
A85: Copper | B85: 2032 | C85: Production potential | D85: 100% CAN | E85: 758.26544 | F85: kilotonnes | G85: 758265.44 | H85: 632958.86 | J85: =H85/G85 -> 0.83474576
A86: Copper | B86: 2033 | C86: Production potential | D86: 100% CAN | E86: 797.05528 | F86: kilotonnes | G86: 797055.28 | H86: 665338.51 | J86: =H86/G86 -> 0.83474576
A87: Copper | B87: 2034 | C87: Production potential | D87: 100% CAN | E87: 837.82945 | F87: kilotonnes | G87: 837829.45 | H87: 699374.58 | J87: =H87/G87 -> 0.83474576
A88: Copper | B88: 2035 | C88: Production potential | D88: 100% CAN | E88: 880.68946 | F88: kilotonnes | G88: 880689.46 | H88: 735151.8 | J88: =H88/G88 -> 0.83474576
A89: Copper | B89: 2036 | C89: Production potential | D89: 100% CAN | E89: 925.74202 | F89: kilotonnes | G89: 925742.02 | H89: 772759.23 | J89: =H89/G89 -> 0.83474576
A90: Copper | B90: 2037 | C90: Production potential | D90: 100% CAN | E90: 973.0993 | F90: kilotonnes | G90: 973099.3 | H90: 812290.52 | J90: =H90/G90 -> 0.83474576
... A93: Copper | B93: 2040 | C93: Production potential | D93: 100% CAN | E93: 1130.2088 | F93: kilotonnes | G93: 1130208.8 | H93: 943437.04 | J93: =H93/G93 -> 0.83474576
A94: Lithium | B94: 2018 | C94: Existing production | D94: 100% CAN | E94: 0 | F94: kilotonnes | G94: 0 | H94: 0
A95: Lithium | B95: 2019 | C95: Existing production | D95: 100% CAN | E95: 0 | F95: kilotonnes | G95: 0 | H95: 0
A96: Lithium | B96: 2020 | C96: Existing production | D96: 100% CAN | E96: 0 | F96: kilotonnes | G96: 0 | H96: 0
A97: Lithium | B97: 2021 | C97: Existing production | D97: 100% CAN | E97: 0.188 | F97: kilotonnes | G97: 188 | H97: 131.44405
A98: Lithium | B98: 2022 | C98: Existing production | D98: 100% CAN | E98: 3.475 | F98: kilotonnes | G98: 3475 | H98: 2429.6174
...

Sheet Associated_LCIs
A1: Scenario | B1: Associated supply scenario | C1: Year | D1: Metal | E1: Impact category | F1: Unit | G1: Mining | H1: Refining | I1: Mining+refining | J1: % Mining
A2: 100% CAN | B2: Status Quo, Expansion Extractive, Integrated | C2: 2025 | D2: Cobalt | E2: Total EP | F2: PDF.m2.yr/kg
A3: 100% CAN | B3: Status Quo, Expansion Extractive, Integrated | C3: 2025 | D3: Cobalt | E3: Total HH | F3: DALY/kg
A4: 100% CAN | B4: Status Quo, Expansion Extractive, Integrated | C4: 2025 | D4: Copper | E4: Total EP | F4: PDF.m2.yr/kg | I4: =EQ_LCA_results!AC73 -> 38.143652
A5: 100% CAN | B5: Status Quo, Expansion Extractive, Integrated | C5: 2025 | D5: Copper | E5: Total HH | F5: DALY/kg
A6: 100% CAN | B6: Status Quo, Expansion Extractive, Integrated | C6: 2025 | D6: Graphite | E6: Total EP | F6: PDF.m2.yr/kg
A7: 100% CAN | B7: Status Quo, Expansion Extractive, Integrated | C7: 2025 | D7: Graphite | E7: Total HH | F7: DALY/kg
A8: 100% CAN | B8: Status Quo, Expansion Extractive, Integrated | C8: 2025 | D8: Lithium | E8: Total EP | F8: PDF.m2.yr/kg
A9: 100% CAN | B9: Status Quo, Expansion Extractive, Integrated | C9: 2025 | D9: Lithium | E9: Total HH | F9: DALY/kg
A10: 100% CAN | B10: Status Quo, Expansion Extractive, Integrated | C10: 2025 | D10: Neodymium | E10: Total EP | F10: PDF.m2.yr/kg
A11: 100% CAN | B11: Status Quo, Expansion Extractive, Integrated | C11: 2025 | D11: Neodymium | E11: Total HH | F11: DALY/kg
A12: 100% CAN | B12: Status Quo, Expansion Extractive, Integrated | C12: 2025 | D12: Nickel | E12: Total EP | F12: PDF.m2.yr/kg | G12: =EQ_LCA_results!AC108 -> 0.35636318 | H12: =EQ_LCA_results!AC118 -> 3.0408316
A13: 100% CAN | B13: Status Quo, Expansion Extractive, Integrated | C13: 2025 | D13: Nickel | E13: Total HH | F13: DALY/kg
A14: 100% RoW | B14: NIMBY, Status Quo, Expansion Extractive, Integrated | C14: 2025 | D14: Cobalt | E14: Total EP | F14: PDF.m2.yr/kg
A15: 100% RoW | B15: NIMBY, Status Quo, Expansion Extractive, Integrated | C15: 2025 | D15: Cobalt | E15: Total HH | F15: DALY/kg
A16: 100% RoW | B16: NIMBY, Status Quo, Expansion Extractive, Integrated | C16: 2025 | D16: Copper | E16: Total EP | F16: PDF.m2.yr/kg | I16: =EQ_LCA_results!AC78 -> 18.763247
A17: 100% RoW | B17: NIMBY, Status Quo, Expansion Extractive, Integrated | C17: 2025 | D17: Copper | E17: Total HH | F17: DALY/kg
A18: 100% RoW | B18: NIMBY, Status Quo, Expansion Extractive, Integrated | C18: 2025 | D18: Graphite | E18: Total EP | F18: PDF.m2.yr/kg
A19: 100% RoW | B19: NIMBY, Status Quo, Expansion Extractive, Integrated | C19: 2025 | D19: Graphite | E19: Total HH | F19: DALY/kg
A20: 100% RoW | B20: NIMBY, Status Quo, Expansion Extractive, Integrated | C20: 2025 | D20: Lithium | E20: Total EP | F20: PDF.m2.yr/kg
A21: 100% RoW | B21: NIMBY, Status Quo, Expansion Extractive, Integrated | C21: 2025 | D21: Lithium | E21: Total HH | F21: DALY/kg
A22: 100% RoW | B22: NIMBY, Status Quo, Expansion Extractive, Integrated | C22: 2025 | D22: Neodymium | E22: Total EP | F22: PDF.m2.yr/kg
A23: 100% RoW | B23: NIMBY, Status Quo, Expansion Extractive, Integrated | C23: 2025 | D23: Neodymium | E23: Total HH | F23: DALY/kg
A24: 100% RoW | B24: NIMBY, Status Quo, Expansion Extractive, Integrated | C24: 2025 | D24: Nickel | E24: Total EP | F24: PDF.m2.yr/kg
A25: 100% RoW | B25: NIMBY, Status Quo, Expansion Extractive, Integrated | C25: 2025 | D25: Nickel | E25: Total HH | F25: DALY/kg
A26: Mining CAN, Refining RoW | B26: Status Quo, Expansion Extractive | C26: 2025 | D26: Cobalt | E26: Total EP | F26: PDF.m2.yr/kg
A27: Mining CAN, Refining RoW | B27: Status Quo, Expansion Extractive | C27: 2025 | D27: Cobalt | E27: Total HH | F27: DALY/kg
A28: Mining CAN, Refining RoW | B28: Status Quo, Expansion Extractive | C28: 2025 | D28: Copper | E28: Total EP | F28: PDF.m2.yr/kg
... A49: Mining RoW, Refining CAN | B49: ? Not used | C49: 2025 | D49: Nickel | E49: Total HH | F49: DALY/kg

Sheet EQ_LCA_results
A1: Scenario | B1: Year | C1: Commodity | D1: Geography | E1: Metal | F1: Reference point | G1: Climate change EQ LT (PDF.m2.yr) | H1: Climate change EQ ST (PDF.m2.yr) | I1: Fisheries impact (PDF.m2.yr) | J1: Freshwater acidification (PDF.m2.yr) | K1: Freshwater ecotoxicity LT (PDF.m2.yr) | L1: Freshwater ecotoxicity ST (PDF.m2.yr) | M1: Freshwater eutrophication (PDF.m2.yr) | N1: Ionizing radiations EQ (PDF.m2.yr) | O1: Land occupation biodiversity (PDF.m2.yr) | P1: Land transformation biodiversity (PDF.m2.yr) | Q1: Marine acidification LT (PDF.m2.yr) | R1: Marine acidification ST (PDF.m2.yr) | S1: Marine ecotoxicity LT (PDF.m2.yr) | T1: Marine ecotoxicity ST (PDF.m2.yr) | U1: Marine eutrophication (PDF.m2.yr) | V1: Photochemical ozone EQ (PDF.m2.yr) | W1: Terrestrial acidification (PDF.m2.yr) | X1: Terrestrial ecotoxicity LT (PDF.m2.yr) | Y1: Terrestrial ecotoxicity ST (PDF.m2.yr) | Z1: Thermally polluted water (PDF.m2.yr) | AA1: Water availability freshwater (PDF.m2.yr) | AB1: Water availability terrestrial (PDF.m2.yr) | AC1: Total EQ
A2: IMAGE_SSP2L | B2: 2020 | C2: C mining CA | D2: Canada | E2: Graphite | F2: Mining | G2: 0.0044140233 | H2: 0.0013540927 | I2: 9.0255917e-17 | J2: 9.1593607e-09 | K2: 0.00030948318 | L2: 0.00023297994 | M2: 1.3657046e-10 | N2: 2.5607708e-13 | O2: 1.6106544e-08 | P2: 1.9561119e-08 | Q2: 0.001580599 | R2: 0.00017157669 | S2: 2.8141914e-10 | T2: 4.8124512e-10 | U2: 1.1808556e-06 | V2: 1.6491284e-06 | W2: 6.0190238e-08 | X2: 1.0272339e-05 | Y2: 1.7565447e-05 | Z2: 6.6520597e-11 | AA2: 4.9920335e-12 | AB2: 6.4150874e-11 | AC2: =SUM(G2:AB2) -> 0.0080935286
A3: IMAGE_SSP2L | B3: 2025 | C3: C mining CA | D3: Canada | E3: Graphite | F3: Mining | G3: 0.0044140233 | H3: 0.0013540927 | I3: 9.0255917e-17 | J3: 9.1593607e-09 | K3: 0.00030948318 | L3: 0.00023297994 | M3: 1.3657046e-10 | N3: 2.5607708e-13 | O3: 1.6106544e-08 | P3: 1.9561119e-08 | Q3: 0.001580599 | R3: 0.00017157669 | S3: 2.8141914e-10 | T3: 4.8124512e-10 | U3: 1.1808556e-06 | V3: 1.6491284e-06 | W3: 6.0190238e-08 | X3: 1.0272339e-05 | Y3: 1.7565447e-05 | Z3: 6.6520597e-11 | AA3: 4.9920335e-12 | AB3: 6.4150874e-11 | AC3: =SUM(G3:AB3) -> 0.0080935286
A4: IMAGE_SSP2L | B4: 2030 | C4: C mining CA | D4: Canada | E4: Graphite | F4: Mining | G4: 0.0044140233 | H4: 0.0013540927 | I4: 9.0255917e-17 | J4: 9.1593607e-09 | K4: 0.00030948318 | L4: 0.00023297994 | M4: 1.3657046e-10 | N4: 2.5607708e-13 | O4: 1.6106544e-08 | P4: 1.9561119e-08 | Q4: 0.001580599 | R4: 0.00017157669 | S4: 2.8141914e-10 | T4: 4.8124512e-10 | U4: 1.1808556e-06 | V4: 1.6491284e-06 | W4: 6.0190238e-08 | X4: 1.0272339e-05 | Y4: 1.7565447e-05 | Z4: 6.6520597e-11 | AA4: 4.9920335e-12 | AB4: 6.4150874e-11 | AC4: =SUM(G4:AB4) -> 0.0080935286
A5: IMAGE_SSP2L | B5: 2035 | C5: C mining CA | D5: Canada | E5: Graphite | F5: Mining | G5: 0.0044140233 | H5: 0.0013540927 | I5: 9.0255917e-17 | J5: 9.1593607e-09 | K5: 0.00030948318 | L5: 0.00023297994 | M5: 1.3657046e-10 | N5: 2.5607708e-13 | O5: 1.6106544e-08 | P5: 1.9561119e-08 | Q5: 0.001580599 | R5: 0.00017157669 | S5: 2.8141914e-10 | T5: 4.8124512e-10 | U5: 1.1808556e-06 | V5: 1.6491284e-06 | W5: 6.0190238e-08 | X5: 1.0272339e-05 | Y5: 1.7565447e-05 | Z5: 6.6520597e-11 | AA5: 4.9920335e-12 | AB5: 6.4150874e-11 | AC5: =SUM(G5:AB5) -> 0.0080935286
A6: IMAGE_SSP2L | B6: 2040 | C6: C mining CA | D6: Canada | E6: Graphite | F6: Mining | G6: 0.0044140233 | H6: 0.0013540927 | I6: 9.0255917e-17 | J6: 9.1593607e-09 | K6: 0.00030948318 | L6: 0.00023297994 | M6: 1.3657046e-10 | N6: 2.5607708e-13 | O6: 1.6106544e-08 | P6: 1.9561119e-08 | Q6: 0.001580599 | R6: 0.00017157669 | S6: 2.8141914e-10 | T6: 4.8124512e-10 | U6: 1.1808556e-06 | V6: 1.6491284e-06 | W6: 6.0190238e-08 | X6: 1.0272339e-05 | Y6: 1.7565447e-05 | Z6: 6.6520597e-11 | AA6: 4.9920335e-12 | AB6: 6.4150874e-11 | AC6: =SUM(G6:AB6) -> 0.0080935286
A7: IMAGE_SSP2L | B7: 2020 | C7: C mining World | D7: World | E7: Graphite | F7: Mining | G7: 0.056765328 | H7: 0.017204601 | I7: 9.6444358e-16 | J7: 2.8122556e-08 | K7: 0.0032888201 | L7: 0.0028802483 | M7: 6.3805587e-10 | N7: 4.7528047e-13 | O7: 9.5448628e-08 | P7: 1.7547761e-07 | Q7: 0.020512609 | R7: 0.0022266889 | S7: 3.674225e-09 | T7: 6.5616288e-09 | U7: 1.016253e-05 | V7: 2.1570027e-05 | W7: 1.850375e-07 | X7: 0.00013411561 | Y7: 0.00023949944 | Z7: 3.3357018e-10 | AA7: 1.5215424e-11 | AB7: 7.6637923e-10 | AC7: =SUM(G7:AB7) -> 0.10328414
A8: IMAGE_SSP2L | B8: 2025 | C8: C mining World | D8: World | E8: Graphite | F8: Mining | G8: 0.056765328 | H8: 0.017204601 | I8: 9.6444358e-16 | J8: 2.8122556e-08 | K8: 0.0032888201 | L8: 0.0028802483 | M8: 6.3805587e-10 | N8: 4.7528047e-13 | O8: 9.5448628e-08 | P8: 1.7547761e-07 | Q8: 0.020512609 | R8: 0.0022266889 | S8: 3.674225e-09 | T8: 6.5616288e-09 | U8: 1.016253e-05 | V8: 2.1570027e-05 | W8: 1.850375e-07 | X8: 0.00013411561 | Y8: 0.00023949944 | Z8: 3.3357018e-10 | AA8: 1.5215424e-11 | AB8: 7.6637923e-10 | AC8: =SUM(G8:AB8) -> 0.10328414
A9: IMAGE_SSP2L | B9: 2030 | C9: C mining World | D9: World | E9: Graphite | F9: Mining | G9: 0.056765328 | H9: 0.017204601 | I9: 9.6444358e-16 | J9: 2.8122556e-08 | K9: 0.0032888201 | L9: 0.0028802483 | M9: 6.3805587e-10 | N9: 4.7528047e-13 | O9: 9.5448628e-08 | P9: 1.7547761e-07 | Q9: 0.020512609 | R9: 0.0022266889 | S9: 3.674225e-09 | T9: 6.5616288e-09 | U9: 1.016253e-05 | V9: 2.1570027e-05 | W9: 1.850375e-07 | X9: 0.00013411561 | Y9: 0.00023949944 | Z9: 3.3357018e-10 | AA9: 1.5215424e-11 | AB9: 7.6637923e-10 | AC9: =SUM(G9:AB9) -> 0.10328414
A10: IMAGE_SSP2L | B10: 2035 | C10: C mining World | D10: World | E10: Graphite | F10: Mining | G10: 0.056765328 | H10: 0.017204601 | I10: 9.6444358e-16 | J10: 2.8122556e-08 | K10: 0.0032888201 | L10: 0.0028802483 | M10: 6.3805587e-10 | N10: 4.7528047e-13 | O10: 9.5448628e-08 | P10: 1.7547761e-07 | Q10: 0.020512609 | R10: 0.0022266889 | S10: 3.674225e-09 | T10: 6.5616288e-09 | U10: 1.016253e-05 | V10: 2.1570027e-05 | W10: 1.850375e-07 | X10: 0.00013411561 | Y10: 0.00023949944 | Z10: 3.3357018e-10 | AA10: 1.5215424e-11 | AB10: 7.6637923e-10 | AC10: =SUM(G10:AB10) -> 0.10328414
A11: IMAGE_SSP2L | B11: 2040 | C11: C mining World | D11: World | E11: Graphite | F11: Mining | G11: 0.056765328 | H11: 0.017204601 | I11: 9.6444358e-16 | J11: 2.8122556e-08 | K11: 0.0032888201 | L11: 0.0028802483 | M11: 6.3805587e-10 | N11: 4.7528047e-13 | O11: 9.5448628e-08 | P11: 1.7547761e-07 | Q11: 0.020512609 | R11: 0.0022266889 | S11: 3.674225e-09 | T11: 6.5616288e-09 | U11: 1.016253e-05 | V11: 2.1570027e-05 | W11: 1.850375e-07 | X11: 0.00013411561 | Y11: 0.00023949944 | Z11: 3.3357018e-10 | AA11: 1.5215424e-11 | AB11: 7.6637923e-10 | AC11: =SUM(G11:AB11) -> 0.10328414
A12: IMAGE_SSP2L | B12: 2020 | C12: C refining CA | D12: Canada | E12: Graphite | F12: Refining | G12: =G22-G2 -> 1.3184625 | H12: =H22-H2 -> 0.42122002 | I12: =I22-I2 -> 3.398158e-14 | J12: =J22-J2 -> 5.4856625e-07 | K12: =K22-K2 -> 0.40464908 | L12: =L22-L2 -> 0.25797192 | M12: =M22-M2 -> 2.8698002e-08 | N12: =N22-N2 -> 1.5321352e-10 | ... AB12: =AB22-AB2 -> 1.6253585e-08 | AC12: =SUM(G12:AB12) -> 2.9683353
A13: IMAGE_SSP2L | B13: 2025 | C13: C refining CA | D13: Canada | E13: Graphite | F13: Refining | G13: =G23-G3 -> 1.3184625 | H13: =H23-H3 -> 0.42122002 | I13: =I23-I3 -> 3.398158e-14 | J13: =J23-J3 -> 5.4856625e-07 | K13: =K23-K3 -> 0.40464908 | L13: =L23-L3 -> 0.25797192 | M13: =M23-M3 -> 2.8698002e-08 | N13: =N23-N3 -> 1.5321352e-10 | ... AB13: =AB23-AB3 -> 1.6253585e-08 | AC13: =SUM(G13:AB13) -> 2.9683353
A14: IMAGE_SSP2L | B14: 2030 | C14: C refining CA | D14: Canada | E14: Graphite | F14: Refining | G14: =G24-G4 -> 1.3184625 | H14: =H24-H4 -> 0.42122002 | I14: =I24-I4 -> 3.398158e-14 | J14: =J24-J4 -> 5.4856625e-07 | K14: =K24-K4 -> 0.40464908 | L14: =L24-L4 -> 0.25797192 | M14: =M24-M4 -> 2.8698002e-08 | N14: =N24-N4 -> 1.5321352e-10 | ... AB14: =AB24-AB4 -> 1.6253585e-08 | AC14: =SUM(G14:AB14) -> 2.9683353
A15: IMAGE_SSP2L | B15: 2035 | C15: C refining CA | D15: Canada | E15: Graphite | F15: Refining | G15: =G25-G5 -> 1.3184625 | H15: =H25-H5 -> 0.42122002 | I15: =I25-I5 -> 3.398158e-14 | J15: =J25-J5 -> 5.4856625e-07 | K15: =K25-K5 -> 0.40464908 | L15: =L25-L5 -> 0.25797192 | M15: =M25-M5 -> 2.8698002e-08 | N15: =N25-N5 -> 1.5321352e-10 | ... AB15: =AB25-AB5 -> 1.6253585e-08 | AC15: =SUM(G15:AB15) -> 2.9683353
A16: IMAGE_SSP2L | B16: 2040 | C16: C refining CA | D16: Canada | E16: Graphite | F16: Refining | G16: =G26-G6 -> 1.3184625 | H16: =H26-H6 -> 0.42122002 | I16: =I26-I6 -> 3.398158e-14 | J16: =J26-J6 -> 5.4856625e-07 | K16: =K26-K6 -> 0.40464908 | L16: =L26-L6 -> 0.25797192 | M16: =M26-M6 -> 2.8698002e-08 | N16: =N26-N6 -> 1.5321352e-10 | ... AB16: =AB26-AB6 -> 1.6253585e-08 | AC16: =SUM(G16:AB16) -> 2.9683353
A17: IMAGE_SSP2L | B17: 2020 | C17: C refining World | D17: World | E17: Graphite | F17: Refining | G17: =G27-G7 -> 2.1329131 | H17: =H27-H7 -> 0.67892309 | I17: =I27-I7 -> 3.990826e-14 | J17: =J27-J7 -> 6.2171808e-07 | K17: =K27-K7 -> 0.60186421 | L17: =L27-L7 -> 0.39213865 | M17: =M27-M7 -> 3.3582931e-08 | N17: =N27-N7 -> 1.0031658e-10 | ... AB17: =AB27-AB7 -> 1.905773e-08 | AC17: =SUM(G17:AB17) -> 4.6999493
A18: IMAGE_SSP2L | B18: 2025 | C18: C refining World | D18: World | E18: Graphite | F18: Refining | G18: =G28-G8 -> 2.1329131 | H18: =H28-H8 -> 0.67892309 | I18: =I28-I8 -> 3.990826e-14 | J18: =J28-J8 -> 6.2171808e-07 | K18: =K28-K8 -> 0.60186421 | L18: =L28-L8 -> 0.39213865 | M18: =M28-M8 -> 3.3582931e-08 | N18: =N28-N8 -> 1.0031658e-10 | ... AB18: =AB28-AB8 -> 1.905773e-08 | AC18: =SUM(G18:AB18) -> 4.6999493
A19: IMAGE_SSP2L | B19: 2030 | C19: C refining World | D19: World | E19: Graphite | F19: Refining | G19: =G29-G9 -> 2.1329131 | H19: =H29-H9 -> 0.67892309 | I19: =I29-I9 -> 3.990826e-14 | J19: =J29-J9 -> 6.2171808e-07 | K19: =K29-K9 -> 0.60186421 | L19: =L29-L9 -> 0.39213865 | M19: =M29-M9 -> 3.3582931e-08 | N19: =N29-N9 -> 1.0031658e-10 | ... AB19: =AB29-AB9 -> 1.905773e-08 | AC19: =SUM(G19:AB19) -> 4.6999493
A20: IMAGE_SSP2L | B20: 2035 | C20: C refining World | D20: World | E20: Graphite | F20: Refining | G20: =G30-G10 -> 2.1329131 | H20: =H30-H10 -> 0.67892309 | I20: =I30-I10 -> 3.990826e-14 | J20: =J30-J10 -> 6.2171808e-07 | K20: =K30-K10 -> 0.60186421 | L20: =L30-L10 -> 0.39213865 | M20: =M30-M10 -> 3.3582931e-08 | N20: =N30-N10 -> 1.0031658e-10 | ... AB20: =AB30-AB10 -> 1.905773e-08 | AC20: =SUM(G20:AB20) -> 4.6999493
A21: IMAGE_SSP2L | B21: 2040 | C21: C refining World | D21: World | E21: Graphite | F21: Refining | G21: =G31-G11 -> 2.1329131 | H21: =H31-H11 -> 0.67892309 | I21: =I31-I11 -> 3.990826e-14 | J21: =J31-J11 -> 6.2171808e-07 | K21: =K31-K11 -> 0.60186421 | L21: =L31-L11 -> 0.39213865 | M21: =M31-M11 -> 3.3582931e-08 | N21: =N31-N11 -> 1.0031658e-10 | ... AB21: =AB31-AB11 -> 1.905773e-08 | AC21: =SUM(G21:AB21) -> 4.6999493
A22: IMAGE_SSP2L | B22: 2020 | C22: C refining CA | D22: Canada | E22: Graphite | F22: Mining+refining | G22: 1.3228766 | H22: 0.42257411 | I22: 3.4071835e-14 | J22: 5.5772561e-07 | K22: 0.40495857 | L22: 0.2582049 | M22: 2.8834573e-08 | N22: 1.534696e-10 | O22: 5.1805579e-06 | P22: 6.6702226e-06 | Q22: 0.47448979 | R22: 0.051507005 | S22: 5.5012886e-07 | T22: 5.6849021e-07 | U22: 0.00034603832 | V22: 0.00062441706 | W22: 3.7288093e-06 | X22: 0.020080271 | Y22: 0.020749893 | Z22: 6.6254664e-09 | AA22: 3.0025869e-10 | AB22: 1.6317736e-08 | AC22: =SUM(G22:AB22) -> 2.9764289
A23: IMAGE_SSP2L | B23: 2025 | C23: C refining CA | D23: Canada | E23: Graphite | F23: Mining+refining | G23: 1.3228766 | H23: 0.42257411 | I23: 3.4071835e-14 | J23: 5.5772561e-07 | K23: 0.40495857 | L23: 0.2582049 | M23: 2.8834573e-08 | N23: 1.534696e-10 | O23: 5.1805579e-06 | P23: 6.6702226e-06 | Q23: 0.47448979 | R23: 0.051507005 | S23: 5.5012886e-07 | T23: 5.6849021e-07 | U23: 0.00034603832 | V23: 0.00062441706 | W23: 3.7288093e-06 | X23: 0.020080271 | Y23: 0.020749893 | Z23: 6.6254664e-09 | AA23: 3.0025869e-10 | AB23: 1.6317736e-08 | AC23: =SUM(G23:AB23) -> 2.9764289
A24: IMAGE_SSP2L | B24: 2030 | C24: C refining CA | D24: Canada | E24: Graphite | F24: Mining+refining | G24: 1.3228766 | H24: 0.42257411 | I24: 3.4071835e-14 | J24: 5.5772561e-07 | K24: 0.40495857 | L24: 0.2582049 | M24: 2.8834573e-08 | N24: 1.534696e-10 | O24: 5.1805579e-06 | P24: 6.6702226e-06 | Q24: 0.47448979 | R24: 0.051507005 | S24: 5.5012886e-07 | T24: 5.6849021e-07 | U24: 0.00034603832 | V24: 0.00062441706 | W24: 3.7288093e-06 | X24: 0.020080271 | Y24: 0.020749893 | Z24: 6.6254664e-09 | AA24: 3.0025869e-10 | AB24: 1.6317736e-08 | AC24: =SUM(G24:AB24) -> 2.9764289
A25: IMAGE_SSP2L | B25: 2035 | C25: C refining CA | D25: Canada | E25: Graphite | F25: Mining+refining | G25: 1.3228766 | H25: 0.42257411 | I25: 3.4071835e-14 | J25: 5.5772561e-07 | K25: 0.40495857 | L25: 0.2582049 | M25: 2.8834573e-08 | N25: 1.534696e-10 | O25: 5.1805579e-06 | P25: 6.6702226e-06 | Q25: 0.47448979 | R25: 0.051507005 | S25: 5.5012886e-07 | T25: 5.6849021e-07 | U25: 0.00034603832 | V25: 0.00062441706 | W25: 3.7288093e-06 | X25: 0.020080271 | Y25: 0.020749893 | Z25: 6.6254664e-09 | AA25: 3.0025869e-10 | AB25: 1.6317736e-08 | AC25: =SUM(G25:AB25) -> 2.9764289
A26: IMAGE_SSP2L | B26: 2040 | C26: C refining CA | D26: Canada | E26: Graphite | F26: Mining+refining | G26: 1.3228766 | H26: 0.42257411 | I26: 3.4071835e-14 | J26: 5.5772561e-07 | K26: 0.40495857 | L26: 0.2582049 | M26: 2.8834573e-08 | N26: 1.534696e-10 | O26: 5.1805579e-06 | P26: 6.6702226e-06 | Q26: 0.47448979 | R26: 0.051507005 | S26: 5.5012886e-07 | T26: 5.6849021e-07 | U26: 0.00034603832 | V26: 0.00062441706 | W26: 3.7288093e-06 | X26: 0.020080271 | Y26: 0.020749893 | Z26: 6.6254664e-09 | AA26: 3.0025869e-10 | AB26: 1.6317736e-08 | AC26: =SUM(G26:AB26) -> 2.9764289
A27: IMAGE_SSP2L | B27: 2020 | C27: C refining World | D27: World | E27: Graphite | F27: Mining+refining | G27: 2.1896784 | H27: 0.6961277 | I27: 4.0872704e-14 | J27: 6.4984064e-07 | K27: 0.60515303 | L27: 0.3950189 | M27: 3.4220987e-08 | N27: 1.0079186e-10 | O27: 6.2488728e-06 | P27: 7.7248372e-06 | Q27: 0.78656662 | R27: 0.085383735 | S27: 5.9645773e-07 | T27: 6.1426009e-07 | U27: 0.00043321963 | V27: 0.00065887171 | W27: 4.3518163e-06 | X27: 0.021772221 | Y27: 0.022420493 | Z27: 7.466954e-09 | AA27: 3.5756397e-10 | AB27: 1.982411e-08 | AC27: =SUM(G27:AB27) -> 4.8032334
A28: IMAGE_SSP2L | B28: 2025 | C28: C refining World | D28: World | E28: Graphite | F28: Mining+refining | G28: 2.1896784 | H28: 0.6961277 | I28: 4.0872704e-14 | J28: 6.4984064e-07 | K28: 0.60515303 | L28: 0.3950189 | M28: 3.4220987e-08 | N28: 1.0079186e-10 | O28: 6.2488728e-06 | P28: 7.7248372e-06 | Q28: 0.78656662 | R28: 0.085383735 | S28: 5.9645773e-07 | T28: 6.1426009e-07 | U28: 0.00043321963 | V28: 0.00065887171 | W28: 4.3518163e-06 | X28: 0.021772221 | Y28: 0.022420493 | Z28: 7.466954e-09 | AA28: 3.5756397e-10 | AB28: 1.982411e-08 | AC28: =SUM(G28:AB28) -> 4.8032334
A29: IMAGE_SSP2L | B29: 2030 | C29: C refining World | D29: World | E29: Graphite | F29: Mining+refining | G29: 2.1896784 | H29: 0.6961277 | I29: 4.0872704e-14 | J29: 6.4984064e-07 | K29: 0.60515303 | L29: 0.3950189 | M29: 3.4220987e-08 | N29: 1.0079186e-10 | O29: 6.2488728e-06 | P29: 7.7248372e-06 | Q29: 0.78656662 | R29: 0.085383735 | S29: 5.9645773e-07 | T29: 6.1426009e-07 | U29: 0.00043321963 | V29: 0.00065887171 | W29: 4.3518163e-06 | X29: 0.021772221 | Y29: 0.022420493 | Z29: 7.466954e-09 | AA29: 3.5756397e-10 | AB29: 1.982411e-08 | AC29: =SUM(G29:AB29) -> 4.8032334
A30: IMAGE_SSP2L | B30: 2035 | C30: C refining World | D30: World | E30: Graphite | F30: Mining+refining | G30: 2.1896784 | H30: 0.6961277 | I30: 4.0872704e-14 | J30: 6.4984064e-07 | K30: 0.60515303 | L30: 0.3950189 | M30: 3.4220987e-08 | N30: 1.0079186e-10 | O30: 6.2488728e-06 | P30: 7.7248372e-06 | Q30: 0.78656662 | R30: 0.085383735 | S30: 5.9645773e-07 | T30: 6.1426009e-07 | U30: 0.00043321963 | V30: 0.00065887171 | W30: 4.3518163e-06 | X30: 0.021772221 | Y30: 0.022420493 | Z30: 7.466954e-09 | AA30: 3.5756397e-10 | AB30: 1.982411e-08 | AC30: =SUM(G30:AB30) -> 4.8032334
A31: IMAGE_SSP2L | B31: 2040 | C31: C refining World | D31: World | E31: Graphite | F31: Mining+refining | G31: 2.1896784 | H31: 0.6961277 | I31: 4.0872704e-14 | J31: 6.4984064e-07 | K31: 0.60515303 | L31: 0.3950189 | M31: 3.4220987e-08 | N31: 1.0079186e-10 | O31: 6.2488728e-06 | P31: 7.7248372e-06 | Q31: 0.78656662 | R31: 0.085383735 | S31: 5.9645773e-07 | T31: 6.1426009e-07 | U31: 0.00043321963 | V31: 0.00065887171 | W31: 4.3518163e-06 | X31: 0.021772221 | Y31: 0.022420493 | Z31: 7.466954e-09 | AA31: 3.5756397e-10 | AB31: 1.982411e-08 | AC31: =SUM(G31:AB31) -> 4.8032334
A32: IMAGE_SSP2L | B32: 2020 | C32: Co mining CA | D32: Canada | E32: Cobalt | F32: Mining | G32: 0.013181434 | H32: 0.0039930123 | I32: 7.203811e-17 | J32: 1.5490258e-08 | K32: 0.00068311664 | L32: 0.00066585495 | M32: 2.6505496e-10 | N32: 8.2116631e-14 | O32: 3.7798043e-08 | P32: 4.6738717e-08 | Q32: 0.0047862556 | R32: 0.00051955577 | S32: 4.1086658e-10 | T32: 5.0712603e-10 | U32: 2.3909561e-06 | V32: 5.3903474e-06 | W32: 1.008942e-07 | X32: 1.4997641e-05 | Y32: 1.85101e-05 | Z32: 2.2016033e-10 | AA32: 5.9452408e-12 | AB32: 1.7065892e-10 | AC32: =SUM(G32:AB32) -> 0.02387072
A33: IMAGE_SSP2L | B33: 2025 | C33: Co mining CA | D33: Canada | E33: Cobalt | F33: Mining | G33: 0.013181434 | H33: 0.0039930123 | I33: 7.203811e-17 | J33: 1.5490258e-08 | K33: 0.00068311664 | L33: 0.00066585495 | M33: 2.6505496e-10 | N33: 8.2116631e-14 | O33: 3.7798043e-08 | P33: 4.6738717e-08 | Q33: 0.0047862556 | R33: 0.00051955577 | S33: 4.1086658e-10 | T33: 5.0712603e-10 | U33: 2.3909561e-06 | V33: 5.3903474e-06 | W33: 1.008942e-07 | X33: 1.4997641e-05 | Y33: 1.85101e-05 | Z33: 2.2016033e-10 | AA33: 5.9452408e-12 | AB33: 1.7065892e-10 | AC33: =SUM(G33:AB33) -> 0.02387072
... A41: IMAGE_SSP2L | B41: 2040 | C41: Co mining World | D41: World | E41: Cobalt | F41: Mining | G41: 0.041630757 | H41: 0.012595724 | I41: 5.6966791e-16 | J41: 2.4897232e-08 | K41: 0.0021581296 | L41: 0.0020229846 | M41: 5.2584969e-10 | N41: 2.6014119e-13 | O41: 7.9287044e-08 | P41: 1.3211088e-07 | Q41: 0.015073977 | R41: 0.0016363113 | S41: 2.2934816e-09 | T41: 3.9494097e-09 | U41: 7.3154325e-06 | V41: 1.6454356e-05 | W41: 1.6292274e-07 | X41: 8.3715537e-05 | Y41: 0.00014415345 | Z41: 3.5287061e-10 | AA41: 1.1256898e-11 | AB41: 5.6050316e-10 | AC41: =SUM(G41:AB41) -> 0.075369929
A42: IMAGE_SSP2L | B42: 2020 | C42: Co refining CA | D42: Canada | E42: Cobalt | F42: Refining | G42: =G52-G32 -> 4.0001553 | H42: =H52-H32 -> 1.200056 | I42: =I52-I32 -> 7.6578605e-13 | J42: =J52-J32 -> 6.3631621e-06 | K42: =K52-K32 -> 1.1610115 | L42: =L52-L32 -> 0.22373536 | M42: =M52-M32 -> 3.7574044e-07 | N42: =N52-N32 -> 8.3539847e-10 | ... AB42: =AB52-AB32 -> 2.2084375e-07 | AC42: =SUM(G42:AB42) -> 8.2949134
A43: IMAGE_SSP2L | B43: 2025 | C43: Co refining CA | D43: Canada | E43: Cobalt | F43: Refining | G43: =G53-G33 -> 4.0001553 | H43: =H53-H33 -> 1.200056 | I43: =I53-I33 -> 7.6578605e-13 | J43: =J53-J33 -> 6.3631621e-06 | K43: =K53-K33 -> 1.1610115 | L43: =L53-L33 -> 0.22373536 | M43: =M53-M33 -> 3.7574044e-07 | N43: =N53-N33 -> 8.3539847e-10 | ... AB43: =AB53-AB33 -> 2.2084375e-07 | AC43: =SUM(G43:AB43) -> 8.2949134
A44: IMAGE_SSP2L | B44: 2030 | C44: Co refining CA | D44: Canada | E44: Cobalt | F44: Refining | G44: =G54-G34 -> 4.0001553 | H44: =H54-H34 -> 1.200056 | I44: =I54-I34 -> 7.6578605e-13 | J44: =J54-J34 -> 6.3631621e-06 | K44: =K54-K34 -> 1.1610115 | L44: =L54-L34 -> 0.22373536 | M44: =M54-M34 -> 3.7574044e-07 | N44: =N54-N34 -> 8.3539847e-10 | ... AB44: =AB54-AB34 -> 2.2084375e-07 | AC44: =SUM(G44:AB44) -> 8.2949134
A45: IMAGE_SSP2L | B45: 2035 | C45: Co refining CA | D45: Canada | E45: Cobalt | F45: Refining | G45: =G55-G35 -> 4.0001553 | H45: =H55-H35 -> 1.200056 | I45: =I55-I35 -> 7.6578605e-13 | J45: =J55-J35 -> 6.3631621e-06 | K45: =K55-K35 -> 1.1610115 | L45: =L55-L35 -> 0.22373536 | M45: =M55-M35 -> 3.7574044e-07 | N45: =N55-N35 -> 8.3539847e-10 | ... AB45: =AB55-AB35 -> 2.2084375e-07 | AC45: =SUM(G45:AB45) -> 8.2949134
A46: IMAGE_SSP2L | B46: 2040 | C46: Co refining CA | D46: Canada | E46: Cobalt | F46: Refining | G46: =G56-G36 -> 4.0001553 | H46: =H56-H36 -> 1.200056 | I46: =I56-I36 -> 7.6578605e-13 | J46: =J56-J36 -> 6.3631621e-06 | K46: =K56-K36 -> 1.1610115 | L46: =L56-L36 -> 0.22373536 | M46: =M56-M36 -> 3.7574044e-07 | N46: =N56-N36 -> 8.3539847e-10 | ... AB46: =AB56-AB36 -> 2.2084375e-07 | AC46: =SUM(G46:AB46) -> 8.2949134
