Workbook

Sheet README

Sheet Scenarios
A1: Scenario# | B1: Scenario_name | C1: Mining | D1: Refining | E1: Secondary_production
A2: 1 | B2: NIMBY | C2: 100% RoW | D2: 100% RoW | E2: BAU
A3: 2 | B3: Status Quo | C3: CCI BAU; rest RoW | D3: Current CA capacity; rest RoW | E3: BAU
A4: 3 | B4: Expansion Extractive | C4: CCI ++; rest RoW | D4: Current CA capacity; rest RoW | E4: BAU
A5: 4 | B5: Expansion Extractive+Circularity | C5: CCI ++; rest RoW | D5: Current CA capacity; rest RoW | E5: NZE
A6: 5 | B6: Integrated | C6: CCI ++; rest RoW | E6: BAU

Sheet Associated_LCIs
A1: Scenario name | B1: Year | C1: Metal | D1: Impact category | E1: Unit | F1: Mining | G1: Refining | H1: Mining+refining
A2: 100% ROW | B2: 2025 | C2: Cobalt | D2: GWP | E2: kgCO2eq/kg | F2: =GWP_LCA_results!G37 -> 0.10880177 | G2: =GWP_LCA_results!G47 -> 11.014118 | H2: =F2+G2 -> 11.122919
A3: 100% ROW | B3: 2025 | C3: Copper | D3: GWP | E3: kgCO2eq/kg | F3: =GWP_LCA_results!G68 -> 0.96646219 | G3: =GWP_LCA_results!G78 -> 4.2778748 | H3: =F3+G3 -> 5.244337
A4: 100% ROW | B4: 2025 | C4: Graphite | D4: GWP | E4: kgCO2eq/kg | H4: =F4+G4 -> 0
A5: 100% ROW | B5: 2025 | C5: Lithium | D5: GWP | E5: kgCO2eq/kg | H5: =GWP_LCA_results!G98 -> 15.24706
A6: 100% ROW | B6: 2025 | C6: Neodymium | D6: GWP | E6: kgCO2eq/kg | H6: =GWP_LCA_results!G103 -> 49.035825
A7: 100% ROW | B7: 2025 | C7: Nickel | D7: GWP | E7: kgCO2eq/kg | F7: =GWP_LCA_results!G113 -> 0.63772814 | G7: =GWP_LCA_results!G123 -> 14.931706 | H7: =F7+G7 -> 15.569435
A8: 100% ROW | B8: 2025 | C8: Cobalt | D8: Total EP | E8: PDF.m2.yr/kg | H8: =F8+G8 -> 0
A9: 100% ROW | B9: 2025 | C9: Copper | D9: Total EP | E9: PDF.m2.yr/kg | H9: =F9+G9 -> 0
A10: 100% ROW | B10: 2025 | C10: Graphite | D10: Total EP | E10: PDF.m2.yr/kg | H10: =F10+G10 -> 0
A11: 100% ROW | B11: 2025 | C11: Lithium | D11: Total EP | E11: PDF.m2.yr/kg | H11: =F11+G11 -> 0
A12: 100% ROW | B12: 2025 | C12: Neodymium | D12: Total EP | E12: PDF.m2.yr/kg | H12: =F12+G12 -> 0
A13: 100% ROW | B13: 2025 | C13: Nickel | D13: Total EP | E13: PDF.m2.yr/kg | H13: =F13+G13 -> 0
A14: 100% ROW | B14: 2025 | C14: Cobalt | D14: Total HH | E14: DALY/kg | H14: =F14+G14 -> 0
A15: 100% ROW | B15: 2025 | C15: Copper | D15: Total HH | E15: DALY/kg | H15: =F15+G15 -> 0
A16: 100% ROW | B16: 2025 | C16: Graphite | D16: Total HH | E16: DALY/kg | H16: =F16+G16 -> 0
A17: 100% ROW | B17: 2025 | C17: Lithium | D17: Total HH | E17: DALY/kg | H17: =F17+G17 -> 0
A18: 100% ROW | B18: 2025 | C18: Neodymium | D18: Total HH | E18: DALY/kg | H18: =F18+G18 -> 0
A19: 100% ROW | B19: 2025 | C19: Nickel | D19: Total HH | E19: DALY/kg | H19: =F19+G19 -> 0
A20: Mining CA, Refining ROW | B20: 2025 | C20: Cobalt | D20: GWP | E20: kgCO2eq/kg | F20: =GWP_LCA_results!G33 -> 0.03479059 | G20: =GWP_LCA_results!G48 -> 10.841425 | H20: =F20+G20 -> 10.876215
A21: Mining CA, Refining ROW | B21: 2025 | C21: Copper | D21: GWP | E21: kgCO2eq/kg | F21: =GWP_LCA_results!G63 -> 0.95853164 | G21: =GWP_LCA_results!G78 -> 4.2778748 | H21: =F21+G21 -> 5.2364065
A22: Mining CA, Refining ROW | B22: 2025 | C22: Graphite | D22: GWP | E22: kgCO2eq/kg | H22: =F22+G22 -> 0
A23: Mining CA, Refining ROW | B23: 2025 | C23: Lithium | D23: GWP | E23: kgCO2eq/kg | H23: =GWP_LCA_results!G93 -> 5.0197176
A24: Mining CA, Refining ROW | B24: 2025 | C24: Neodymium | D24: GWP | E24: kgCO2eq/kg | H24: =F24+G24 -> 0
A25: Mining CA, Refining ROW | B25: 2025 | C25: Nickel | D25: GWP | E25: kgCO2eq/kg | F25: =GWP_LCA_results!G108 -> 0.5004485 | G25: =GWP_LCA_results!G123 -> 14.931706 | H25: =F25+G25 -> 15.432155
A26: Mining CA, Refining ROW | B26: 2025 | C26: Cobalt | D26: Total EP | E26: PDF.m2.yr/kg | H26: =F26+G26 -> 0
A27: Mining CA, Refining ROW | B27: 2025 | C27: Copper | D27: Total EP | E27: PDF.m2.yr/kg | H27: =F27+G27 -> 0
A28: Mining CA, Refining ROW | B28: 2025 | C28: Graphite | D28: Total EP | E28: PDF.m2.yr/kg | H28: =F28+G28 -> 0
A29: Mining CA, Refining ROW | B29: 2025 | C29: Lithium | D29: Total EP | E29: PDF.m2.yr/kg | H29: =F29+G29 -> 0
A30: Mining CA, Refining ROW | B30: 2025 | C30: Neodymium | D30: Total EP | E30: PDF.m2.yr/kg | H30: =F30+G30 -> 0
A31: Mining CA, Refining ROW | B31: 2025 | C31: Nickel | D31: Total EP | E31: PDF.m2.yr/kg | H31: =F31+G31 -> 0
A32: Mining CA, Refining ROW | B32: 2025 | C32: Cobalt | D32: Total HH | E32: DALY/kg | H32: =F32+G32 -> 0
A33: Mining CA, Refining ROW | B33: 2025 | C33: Copper | D33: Total HH | E33: DALY/kg | H33: =F33+G33 -> 0
A34: Mining CA, Refining ROW | B34: 2025 | C34: Graphite | D34: Total HH | E34: DALY/kg | H34: =F34+G34 -> 0
A35: Mining CA, Refining ROW | B35: 2025 | C35: Lithium | D35: Total HH | E35: DALY/kg | H35: =F35+G35 -> 0
A36: Mining CA, Refining ROW | B36: 2025 | C36: Neodymium | D36: Total HH | E36: DALY/kg | H36: =F36+G36 -> 0
A37: Mining CA, Refining ROW | B37: 2025 | C37: Nickel | D37: Total HH | E37: DALY/kg | H37: =F37+G37 -> 0
A38: Mining ROW, Refining CA | B38: 2025 | C38: Cobalt | D38: GWP | E38: kgCO2eq/kg | F38: =GWP_LCA_results!G38 -> 0.12755568 | G38: =GWP_LCA_results!G43 -> 10.263996 | H38: =F38+G38 -> 10.391551
A39: Mining ROW, Refining CA | B39: 2025 | C39: Copper | D39: GWP | E39: kgCO2eq/kg | F39: =GWP_LCA_results!G68 -> 0.96646219 | G39: =GWP_LCA_results!G73 -> 3.3081251 | H39: =F39+G39 -> 4.2745873
A40: Mining ROW, Refining CA | B40: 2025 | C40: Graphite | D40: GWP | E40: kgCO2eq/kg | H40: =F40+G40 -> 0
...

Sheet EQ_LCA_results
A1: Scenario | B1: Year | C1: Commodity | D1: Geography | E1: Metal | F1: Reference point | G1: Climate change EQ LT (PDF.m2.yr) | H1: Climate change EQ ST (PDF.m2.yr) | I1: Fisheries impact (PDF.m2.yr) | J1: Freshwater acidification (PDF.m2.yr) | K1: Freshwater ecotoxicity LT (PDF.m2.yr) | L1: Freshwater ecotoxicity ST (PDF.m2.yr) | M1: Freshwater eutrophication (PDF.m2.yr) | N1: Ionizing radiations EQ (PDF.m2.yr) | O1: Land occupation biodiversity (PDF.m2.yr) | P1: Land transformation biodiversity (PDF.m2.yr) | Q1: Marine acidification LT (PDF.m2.yr) | R1: Marine acidification ST (PDF.m2.yr) | S1: Marine ecotoxicity LT (PDF.m2.yr) | T1: Marine ecotoxicity ST (PDF.m2.yr) | U1: Marine eutrophication (PDF.m2.yr) | V1: Photochemical ozone EQ (PDF.m2.yr) | W1: Terrestrial acidification (PDF.m2.yr) | X1: Terrestrial ecotoxicity LT (PDF.m2.yr) | Y1: Terrestrial ecotoxicity ST (PDF.m2.yr) | Z1: Thermally polluted water (PDF.m2.yr) | AA1: Water availability freshwater (PDF.m2.yr) | AB1: Water availability terrestrial (PDF.m2.yr) | AC1: Total EQ
A2: IMAGE_SSP2L | B2: 2020 | C2: C mining CA | D2: Canada | E2: Graphite | F2: Mining | G2: 0.0044140233 | H2: 0.0013540927 | I2: 9.0255917e-17 | J2: 9.1593607e-09 | K2: 0.00030948318 | L2: 0.00023297994 | M2: 1.3657046e-10 | N2: 2.5607708e-13 | O2: 1.6106544e-08 | P2: 1.9561119e-08 | Q2: 0.001580599 | R2: 0.00017157669 | S2: 2.8141914e-10 | T2: 4.8124512e-10 | U2: 1.1808556e-06 | V2: 1.6491284e-06 | W2: 6.0190238e-08 | X2: 1.0272339e-05 | Y2: 1.7565447e-05 | Z2: 6.6520597e-11 | AA2: 4.9920335e-12 | AB2: 6.4150874e-11 | AC2: =SUM(G2:AB2) -> 0.0080935286
A3: IMAGE_SSP2L | B3: 2025 | C3: C mining CA | D3: Canada | E3: Graphite | F3: Mining | G3: 0.0044140233 | H3: 0.0013540927 | I3: 9.0255917e-17 | J3: 9.1593607e-09 | K3: 0.00030948318 | L3: 0.00023297994 | M3: 1.3657046e-10 | N3: 2.5607708e-13 | O3: 1.6106544e-08 | P3: 1.9561119e-08 | Q3: 0.001580599 | R3: 0.00017157669 | S3: 2.8141914e-10 | T3: 4.8124512e-10 | U3: 1.1808556e-06 | V3: 1.6491284e-06 | W3: 6.0190238e-08 | X3: 1.0272339e-05 | Y3: 1.7565447e-05 | Z3: 6.6520597e-11 | AA3: 4.9920335e-12 | AB3: 6.4150874e-11 | AC3: =SUM(G3:AB3) -> 0.0080935286
A4: IMAGE_SSP2L | B4: 2030 | C4: C mining CA | D4: Canada | E4: Graphite | F4: Mining | G4: 0.0044140233 | H4: 0.0013540927 | I4: 9.0255917e-17 | J4: 9.1593607e-09 | K4: 0.00030948318 | L4: 0.00023297994 | M4: 1.3657046e-10 | N4: 2.5607708e-13 | O4: 1.6106544e-08 | P4: 1.9561119e-08 | Q4: 0.001580599 | R4: 0.00017157669 | S4: 2.8141914e-10 | T4: 4.8124512e-10 | U4: 1.1808556e-06 | V4: 1.6491284e-06 | W4: 6.0190238e-08 | X4: 1.0272339e-05 | Y4: 1.7565447e-05 | Z4: 6.6520597e-11 | AA4: 4.9920335e-12 | AB4: 6.4150874e-11 | AC4: =SUM(G4:AB4) -> 0.0080935286
A5: IMAGE_SSP2L | B5: 2035 | C5: C mining CA | D5: Canada | E5: Graphite | F5: Mining | G5: 0.0044140233 | H5: 0.0013540927 | I5: 9.0255917e-17 | J5: 9.1593607e-09 | K5: 0.00030948318 | L5: 0.00023297994 | M5: 1.3657046e-10 | N5: 2.5607708e-13 | O5: 1.6106544e-08 | P5: 1.9561119e-08 | Q5: 0.001580599 | R5: 0.00017157669 | S5: 2.8141914e-10 | T5: 4.8124512e-10 | U5: 1.1808556e-06 | V5: 1.6491284e-06 | W5: 6.0190238e-08 | X5: 1.0272339e-05 | Y5: 1.7565447e-05 | Z5: 6.6520597e-11 | AA5: 4.9920335e-12 | AB5: 6.4150874e-11 | AC5: =SUM(G5:AB5) -> 0.0080935286
A6: IMAGE_SSP2L | B6: 2040 | C6: C mining CA | D6: Canada | E6: Graphite | F6: Mining | G6: 0.0044140233 | H6: 0.0013540927 | I6: 9.0255917e-17 | J6: 9.1593607e-09 | K6: 0.00030948318 | L6: 0.00023297994 | M6: 1.3657046e-10 | N6: 2.5607708e-13 | O6: 1.6106544e-08 | P6: 1.9561119e-08 | Q6: 0.001580599 | R6: 0.00017157669 | S6: 2.8141914e-10 | T6: 4.8124512e-10 | U6: 1.1808556e-06 | V6: 1.6491284e-06 | W6: 6.0190238e-08 | X6: 1.0272339e-05 | Y6: 1.7565447e-05 | Z6: 6.6520597e-11 | AA6: 4.9920335e-12 | AB6: 6.4150874e-11 | AC6: =SUM(G6:AB6) -> 0.0080935286
A7: IMAGE_SSP2L | B7: 2020 | C7: C mining World | D7: World | E7: Graphite | F7: Mining | G7: 0.056765328 | H7: 0.017204601 | I7: 9.6444358e-16 | J7: 2.8122556e-08 | K7: 0.0032888201 | L7: 0.0028802483 | M7: 6.3805587e-10 | N7: 4.7528047e-13 | O7: 9.5448628e-08 | P7: 1.7547761e-07 | Q7: 0.020512609 | R7: 0.0022266889 | S7: 3.674225e-09 | T7: 6.5616288e-09 | U7: 1.016253e-05 | V7: 2.1570027e-05 | W7: 1.850375e-07 | X7: 0.00013411561 | Y7: 0.00023949944 | Z7: 3.3357018e-10 | AA7: 1.5215424e-11 | AB7: 7.6637923e-10 | AC7: =SUM(G7:AB7) -> 0.10328414
A8: IMAGE_SSP2L | B8: 2025 | C8: C mining World | D8: World | E8: Graphite | F8: Mining | G8: 0.056765328 | H8: 0.017204601 | I8: 9.6444358e-16 | J8: 2.8122556e-08 | K8: 0.0032888201 | L8: 0.0028802483 | M8: 6.3805587e-10 | N8: 4.7528047e-13 | O8: 9.5448628e-08 | P8: 1.7547761e-07 | Q8: 0.020512609 | R8: 0.0022266889 | S8: 3.674225e-09 | T8: 6.5616288e-09 | U8: 1.016253e-05 | V8: 2.1570027e-05 | W8: 1.850375e-07 | X8: 0.00013411561 | Y8: 0.00023949944 | Z8: 3.3357018e-10 | AA8: 1.5215424e-11 | AB8: 7.6637923e-10 | AC8: =SUM(G8:AB8) -> 0.10328414
A9: IMAGE_SSP2L | B9: 2030 | C9: C mining World | D9: World | E9: Graphite | F9: Mining | G9: 0.056765328 | H9: 0.017204601 | I9: 9.6444358e-16 | J9: 2.8122556e-08 | K9: 0.0032888201 | L9: 0.0028802483 | M9: 6.3805587e-10 | N9: 4.7528047e-13 | O9: 9.5448628e-08 | P9: 1.7547761e-07 | Q9: 0.020512609 | R9: 0.0022266889 | S9: 3.674225e-09 | T9: 6.5616288e-09 | U9: 1.016253e-05 | V9: 2.1570027e-05 | W9: 1.850375e-07 | X9: 0.00013411561 | Y9: 0.00023949944 | Z9: 3.3357018e-10 | AA9: 1.5215424e-11 | AB9: 7.6637923e-10 | AC9: =SUM(G9:AB9) -> 0.10328414
A10: IMAGE_SSP2L | B10: 2035 | C10: C mining World | D10: World | E10: Graphite | F10: Mining | G10: 0.056765328 | H10: 0.017204601 | I10: 9.6444358e-16 | J10: 2.8122556e-08 | K10: 0.0032888201 | L10: 0.0028802483 | M10: 6.3805587e-10 | N10: 4.7528047e-13 | O10: 9.5448628e-08 | P10: 1.7547761e-07 | Q10: 0.020512609 | R10: 0.0022266889 | S10: 3.674225e-09 | T10: 6.5616288e-09 | U10: 1.016253e-05 | V10: 2.1570027e-05 | W10: 1.850375e-07 | X10: 0.00013411561 | Y10: 0.00023949944 | Z10: 3.3357018e-10 | AA10: 1.5215424e-11 | AB10: 7.6637923e-10 | AC10: =SUM(G10:AB10) -> 0.10328414
A11: IMAGE_SSP2L | B11: 2040 | C11: C mining World | D11: World | E11: Graphite | F11: Mining | G11: 0.056765328 | H11: 0.017204601 | I11: 9.6444358e-16 | J11: 2.8122556e-08 | K11: 0.0032888201 | L11: 0.0028802483 | M11: 6.3805587e-10 | N11: 4.7528047e-13 | O11: 9.5448628e-08 | P11: 1.7547761e-07 | Q11: 0.020512609 | R11: 0.0022266889 | S11: 3.674225e-09 | T11: 6.5616288e-09 | U11: 1.016253e-05 | V11: 2.1570027e-05 | W11: 1.850375e-07 | X11: 0.00013411561 | Y11: 0.00023949944 | Z11: 3.3357018e-10 | AA11: 1.5215424e-11 | AB11: 7.6637923e-10 | AC11: =SUM(G11:AB11) -> 0.10328414
A12: IMAGE_SSP2L | B12: 2020 | C12: C refining CA | D12: Canada | E12: Graphite | F12: Refining | G12: =G22-G2 -> 1.3184625 | H12: =H22-H2 -> 0.42122002 | I12: =I22-I2 -> 3.398158e-14 | J12: =J22-J2 -> 5.4856625e-07 | K12: =K22-K2 -> 0.40464908 | L12: =L22-L2 -> 0.25797192 | M12: =M22-M2 -> 2.8698002e-08 | N12: =N22-N2 -> 1.5321352e-10 | ... AB12: =AB22-AB2 -> 1.6253585e-08 | AC12: =SUM(G12:AB12) -> 2.9683353
A13: IMAGE_SSP2L | B13: 2025 | C13: C refining CA | D13: Canada | E13: Graphite | F13: Refining | G13: =G23-G3 -> 1.3184625 | H13: =H23-H3 -> 0.42122002 | I13: =I23-I3 -> 3.398158e-14 | J13: =J23-J3 -> 5.4856625e-07 | K13: =K23-K3 -> 0.40464908 | L13: =L23-L3 -> 0.25797192 | M13: =M23-M3 -> 2.8698002e-08 | N13: =N23-N3 -> 1.5321352e-10 | ... AB13: =AB23-AB3 -> 1.6253585e-08 | AC13: =SUM(G13:AB13) -> 2.9683353
A14: IMAGE_SSP2L | B14: 2030 | C14: C refining CA | D14: Canada | E14: Graphite | F14: Refining | G14: =G24-G4 -> 1.3184625 | H14: =H24-H4 -> 0.42122002 | I14: =I24-I4 -> 3.398158e-14 | J14: =J24-J4 -> 5.4856625e-07 | K14: =K24-K4 -> 0.40464908 | L14: =L24-L4 -> 0.25797192 | M14: =M24-M4 -> 2.8698002e-08 | N14: =N24-N4 -> 1.5321352e-10 | ... AB14: =AB24-AB4 -> 1.6253585e-08 | AC14: =SUM(G14:AB14) -> 2.9683353
A15: IMAGE_SSP2L | B15: 2035 | C15: C refining CA | D15: Canada | E15: Graphite | F15: Refining | G15: =G25-G5 -> 1.3184625 | H15: =H25-H5 -> 0.42122002 | I15: =I25-I5 -> 3.398158e-14 | J15: =J25-J5 -> 5.4856625e-07 | K15: =K25-K5 -> 0.40464908 | L15: =L25-L5 -> 0.25797192 | M15: =M25-M5 -> 2.8698002e-08 | N15: =N25-N5 -> 1.5321352e-10 | ... AB15: =AB25-AB5 -> 1.6253585e-08 | AC15: =SUM(G15:AB15) -> 2.9683353
A16: IMAGE_SSP2L | B16: 2040 | C16: C refining CA | D16: Canada | E16: Graphite | F16: Refining | G16: =G26-G6 -> 1.3184625 | H16: =H26-H6 -> 0.42122002 | I16: =I26-I6 -> 3.398158e-14 | J16: =J26-J6 -> 5.4856625e-07 | K16: =K26-K6 -> 0.40464908 | L16: =L26-L6 -> 0.25797192 | M16: =M26-M6 -> 2.8698002e-08 | N16: =N26-N6 -> 1.5321352e-10 | ... AB16: =AB26-AB6 -> 1.6253585e-08 | AC16: =SUM(G16:AB16) -> 2.9683353
A17: IMAGE_SSP2L | B17: 2020 | C17: C refining World | D17: World | E17: Graphite | F17: Refining | G17: =G27-G7 -> 2.1329131 | H17: =H27-H7 -> 0.67892309 | I17: =I27-I7 -> 3.990826e-14 | J17: =J27-J7 -> 6.2171808e-07 | K17: =K27-K7 -> 0.60186421 | L17: =L27-L7 -> 0.39213865 | M17: =M27-M7 -> 3.3582931e-08 | N17: =N27-N7 -> 1.0031658e-10 | ... AB17: =AB27-AB7 -> 1.905773e-08 | AC17: =SUM(G17:AB17) -> 4.6999493
A18: IMAGE_SSP2L | B18: 2025 | C18: C refining World | D18: World | E18: Graphite | F18: Refining | G18: =G28-G8 -> 2.1329131 | H18: =H28-H8 -> 0.67892309 | I18: =I28-I8 -> 3.990826e-14 | J18: =J28-J8 -> 6.2171808e-07 | K18: =K28-K8 -> 0.60186421 | L18: =L28-L8 -> 0.39213865 | M18: =M28-M8 -> 3.3582931e-08 | N18: =N28-N8 -> 1.0031658e-10 | ... AB18: =AB28-AB8 -> 1.905773e-08 | AC18: =SUM(G18:AB18) -> 4.6999493
A19: IMAGE_SSP2L | B19: 2030 | C19: C refining World | D19: World | E19: Graphite | F19: Refining | G19: =G29-G9 -> 2.1329131 | H19: =H29-H9 -> 0.67892309 | I19: =I29-I9 -> 3.990826e-14 | J19: =J29-J9 -> 6.2171808e-07 | K19: =K29-K9 -> 0.60186421 | L19: =L29-L9 -> 0.39213865 | M19: =M29-M9 -> 3.3582931e-08 | N19: =N29-N9 -> 1.0031658e-10 | ... AB19: =AB29-AB9 -> 1.905773e-08 | AC19: =SUM(G19:AB19) -> 4.6999493
A20: IMAGE_SSP2L | B20: 2035 | C20: C refining World | D20: World | E20: Graphite | F20: Refining | G20: =G30-G10 -> 2.1329131 | H20: =H30-H10 -> 0.67892309 | I20: =I30-I10 -> 3.990826e-14 | J20: =J30-J10 -> 6.2171808e-07 | K20: =K30-K10 -> 0.60186421 | L20: =L30-L10 -> 0.39213865 | M20: =M30-M10 -> 3.3582931e-08 | N20: =N30-N10 -> 1.0031658e-10 | ... AB20: =AB30-AB10 -> 1.905773e-08 | AC20: =SUM(G20:AB20) -> 4.6999493
A21: IMAGE_SSP2L | B21: 2040 | C21: C refining World | D21: World | E21: Graphite | F21: Refining | G21: =G31-G11 -> 2.1329131 | H21: =H31-H11 -> 0.67892309 | I21: =I31-I11 -> 3.990826e-14 | J21: =J31-J11 -> 6.2171808e-07 | K21: =K31-K11 -> 0.60186421 | L21: =L31-L11 -> 0.39213865 | M21: =M31-M11 -> 3.3582931e-08 | N21: =N31-N11 -> 1.0031658e-10 | ... AB21: =AB31-AB11 -> 1.905773e-08 | AC21: =SUM(G21:AB21) -> 4.6999493
A22: IMAGE_SSP2L | B22: 2020 | C22: C refining CA | D22: Canada | E22: Graphite | F22: Mining+refining | G22: 1.3228766 | H22: 0.42257411 | I22: 3.4071835e-14 | J22: 5.5772561e-07 | K22: 0.40495857 | L22: 0.2582049 | M22: 2.8834573e-08 | N22: 1.534696e-10 | O22: 5.1805579e-06 | P22: 6.6702226e-06 | Q22: 0.47448979 | R22: 0.051507005 | S22: 5.5012886e-07 | T22: 5.6849021e-07 | U22: 0.00034603832 | V22: 0.00062441706 | W22: 3.7288093e-06 | X22: 0.020080271 | Y22: 0.020749893 | Z22: 6.6254664e-09 | AA22: 3.0025869e-10 | AB22: 1.6317736e-08 | AC22: =SUM(G22:AB22) -> 2.9764289
A23: IMAGE_SSP2L | B23: 2025 | C23: C refining CA | D23: Canada | E23: Graphite | F23: Mining+refining | G23: 1.3228766 | H23: 0.42257411 | I23: 3.4071835e-14 | J23: 5.5772561e-07 | K23: 0.40495857 | L23: 0.2582049 | M23: 2.8834573e-08 | N23: 1.534696e-10 | O23: 5.1805579e-06 | P23: 6.6702226e-06 | Q23: 0.47448979 | R23: 0.051507005 | S23: 5.5012886e-07 | T23: 5.6849021e-07 | U23: 0.00034603832 | V23: 0.00062441706 | W23: 3.7288093e-06 | X23: 0.020080271 | Y23: 0.020749893 | Z23: 6.6254664e-09 | AA23: 3.0025869e-10 | AB23: 1.6317736e-08 | AC23: =SUM(G23:AB23) -> 2.9764289
A24: IMAGE_SSP2L | B24: 2030 | C24: C refining CA | D24: Canada | E24: Graphite | F24: Mining+refining | G24: 1.3228766 | H24: 0.42257411 | I24: 3.4071835e-14 | J24: 5.5772561e-07 | K24: 0.40495857 | L24: 0.2582049 | M24: 2.8834573e-08 | N24: 1.534696e-10 | O24: 5.1805579e-06 | P24: 6.6702226e-06 | Q24: 0.47448979 | R24: 0.051507005 | S24: 5.5012886e-07 | T24: 5.6849021e-07 | U24: 0.00034603832 | V24: 0.00062441706 | W24: 3.7288093e-06 | X24: 0.020080271 | Y24: 0.020749893 | Z24: 6.6254664e-09 | AA24: 3.0025869e-10 | AB24: 1.6317736e-08 | AC24: =SUM(G24:AB24) -> 2.9764289
A25: IMAGE_SSP2L | B25: 2035 | C25: C refining CA | D25: Canada | E25: Graphite | F25: Mining+refining | G25: 1.3228766 | H25: 0.42257411 | I25: 3.4071835e-14 | J25: 5.5772561e-07 | K25: 0.40495857 | L25: 0.2582049 | M25: 2.8834573e-08 | N25: 1.534696e-10 | O25: 5.1805579e-06 | P25: 6.6702226e-06 | Q25: 0.47448979 | R25: 0.051507005 | S25: 5.5012886e-07 | T25: 5.6849021e-07 | U25: 0.00034603832 | V25: 0.00062441706 | W25: 3.7288093e-06 | X25: 0.020080271 | Y25: 0.020749893 | Z25: 6.6254664e-09 | AA25: 3.0025869e-10 | AB25: 1.6317736e-08 | AC25: =SUM(G25:AB25) -> 2.9764289
A26: IMAGE_SSP2L | B26: 2040 | C26: C refining CA | D26: Canada | E26: Graphite | F26: Mining+refining | G26: 1.3228766 | H26: 0.42257411 | I26: 3.4071835e-14 | J26: 5.5772561e-07 | K26: 0.40495857 | L26: 0.2582049 | M26: 2.8834573e-08 | N26: 1.534696e-10 | O26: 5.1805579e-06 | P26: 6.6702226e-06 | Q26: 0.47448979 | R26: 0.051507005 | S26: 5.5012886e-07 | T26: 5.6849021e-07 | U26: 0.00034603832 | V26: 0.00062441706 | W26: 3.7288093e-06 | X26: 0.020080271 | Y26: 0.020749893 | Z26: 6.6254664e-09 | AA26: 3.0025869e-10 | AB26: 1.6317736e-08 | AC26: =SUM(G26:AB26) -> 2.9764289
A27: IMAGE_SSP2L | B27: 2020 | C27: C refining World | D27: World | E27: Graphite | F27: Mining+refining | G27: 2.1896784 | H27: 0.6961277 | I27: 4.0872704e-14 | J27: 6.4984064e-07 | K27: 0.60515303 | L27: 0.3950189 | M27: 3.4220987e-08 | N27: 1.0079186e-10 | O27: 6.2488728e-06 | P27: 7.7248372e-06 | Q27: 0.78656662 | R27: 0.085383735 | S27: 5.9645773e-07 | T27: 6.1426009e-07 | U27: 0.00043321963 | V27: 0.00065887171 | W27: 4.3518163e-06 | X27: 0.021772221 | Y27: 0.022420493 | Z27: 7.466954e-09 | AA27: 3.5756397e-10 | AB27: 1.982411e-08 | AC27: =SUM(G27:AB27) -> 4.8032334
A28: IMAGE_SSP2L | B28: 2025 | C28: C refining World | D28: World | E28: Graphite | F28: Mining+refining | G28: 2.1896784 | H28: 0.6961277 | I28: 4.0872704e-14 | J28: 6.4984064e-07 | K28: 0.60515303 | L28: 0.3950189 | M28: 3.4220987e-08 | N28: 1.0079186e-10 | O28: 6.2488728e-06 | P28: 7.7248372e-06 | Q28: 0.78656662 | R28: 0.085383735 | S28: 5.9645773e-07 | T28: 6.1426009e-07 | U28: 0.00043321963 | V28: 0.00065887171 | W28: 4.3518163e-06 | X28: 0.021772221 | Y28: 0.022420493 | Z28: 7.466954e-09 | AA28: 3.5756397e-10 | AB28: 1.982411e-08 | AC28: =SUM(G28:AB28) -> 4.8032334
A29: IMAGE_SSP2L | B29: 2030 | C29: C refining World | D29: World | E29: Graphite | F29: Mining+refining | G29: 2.1896784 | H29: 0.6961277 | I29: 4.0872704e-14 | J29: 6.4984064e-07 | K29: 0.60515303 | L29: 0.3950189 | M29: 3.4220987e-08 | N29: 1.0079186e-10 | O29: 6.2488728e-06 | P29: 7.7248372e-06 | Q29: 0.78656662 | R29: 0.085383735 | S29: 5.9645773e-07 | T29: 6.1426009e-07 | U29: 0.00043321963 | V29: 0.00065887171 | W29: 4.3518163e-06 | X29: 0.021772221 | Y29: 0.022420493 | Z29: 7.466954e-09 | AA29: 3.5756397e-10 | AB29: 1.982411e-08 | AC29: =SUM(G29:AB29) -> 4.8032334
A30: IMAGE_SSP2L | B30: 2035 | C30: C refining World | D30: World | E30: Graphite | F30: Mining+refining | G30: 2.1896784 | H30: 0.6961277 | I30: 4.0872704e-14 | J30: 6.4984064e-07 | K30: 0.60515303 | L30: 0.3950189 | M30: 3.4220987e-08 | N30: 1.0079186e-10 | O30: 6.2488728e-06 | P30: 7.7248372e-06 | Q30: 0.78656662 | R30: 0.085383735 | S30: 5.9645773e-07 | T30: 6.1426009e-07 | U30: 0.00043321963 | V30: 0.00065887171 | W30: 4.3518163e-06 | X30: 0.021772221 | Y30: 0.022420493 | Z30: 7.466954e-09 | AA30: 3.5756397e-10 | AB30: 1.982411e-08 | AC30: =SUM(G30:AB30) -> 4.8032334
A31: IMAGE_SSP2L | B31: 2040 | C31: C refining World | D31: World | E31: Graphite | F31: Mining+refining | G31: 2.1896784 | H31: 0.6961277 | I31: 4.0872704e-14 | J31: 6.4984064e-07 | K31: 0.60515303 | L31: 0.3950189 | M31: 3.4220987e-08 | N31: 1.0079186e-10 | O31: 6.2488728e-06 | P31: 7.7248372e-06 | Q31: 0.78656662 | R31: 0.085383735 | S31: 5.9645773e-07 | T31: 6.1426009e-07 | U31: 0.00043321963 | V31: 0.00065887171 | W31: 4.3518163e-06 | X31: 0.021772221 | Y31: 0.022420493 | Z31: 7.466954e-09 | AA31: 3.5756397e-10 | AB31: 1.982411e-08 | AC31: =SUM(G31:AB31) -> 4.8032334
A32: IMAGE_SSP2L | B32: 2020 | C32: Co mining CA | D32: Canada | E32: Cobalt | F32: Mining | G32: 0.013181434 | H32: 0.0039930123 | I32: 7.203811e-17 | J32: 1.5490258e-08 | K32: 0.00068311664 | L32: 0.00066585495 | M32: 2.6505496e-10 | N32: 8.2116631e-14 | O32: 3.7798043e-08 | P32: 4.6738717e-08 | Q32: 0.0047862556 | R32: 0.00051955577 | S32: 4.1086658e-10 | T32: 5.0712603e-10 | U32: 2.3909561e-06 | V32: 5.3903474e-06 | W32: 1.008942e-07 | X32: 1.4997641e-05 | Y32: 1.85101e-05 | Z32: 2.2016033e-10 | AA32: 5.9452408e-12 | AB32: 1.7065892e-10 | AC32: =SUM(G32:AB32) -> 0.02387072
A33: IMAGE_SSP2L | B33: 2025 | C33: Co mining CA | D33: Canada | E33: Cobalt | F33: Mining | G33: 0.013181434 | H33: 0.0039930123 | I33: 7.203811e-17 | J33: 1.5490258e-08 | K33: 0.00068311664 | L33: 0.00066585495 | M33: 2.6505496e-10 | N33: 8.2116631e-14 | O33: 3.7798043e-08 | P33: 4.6738717e-08 | Q33: 0.0047862556 | R33: 0.00051955577 | S33: 4.1086658e-10 | T33: 5.0712603e-10 | U33: 2.3909561e-06 | V33: 5.3903474e-06 | W33: 1.008942e-07 | X33: 1.4997641e-05 | Y33: 1.85101e-05 | Z33: 2.2016033e-10 | AA33: 5.9452408e-12 | AB33: 1.7065892e-10 | AC33: =SUM(G33:AB33) -> 0.02387072
... A41: IMAGE_SSP2L | B41: 2040 | C41: Co mining World | D41: World | E41: Cobalt | F41: Mining | G41: 0.041630757 | H41: 0.012595724 | I41: 5.6966791e-16 | J41: 2.4897232e-08 | K41: 0.0021581296 | L41: 0.0020229846 | M41: 5.2584969e-10 | N41: 2.6014119e-13 | O41: 7.9287044e-08 | P41: 1.3211088e-07 | Q41: 0.015073977 | R41: 0.0016363113 | S41: 2.2934816e-09 | T41: 3.9494097e-09 | U41: 7.3154325e-06 | V41: 1.6454356e-05 | W41: 1.6292274e-07 | X41: 8.3715537e-05 | Y41: 0.00014415345 | Z41: 3.5287061e-10 | AA41: 1.1256898e-11 | AB41: 5.6050316e-10 | AC41: =SUM(G41:AB41) -> 0.075369929
A42: IMAGE_SSP2L | B42: 2020 | C42: Co refining CA | D42: Canada | E42: Cobalt | F42: Refining | G42: =G52-G32 -> 4.0001553 | H42: =H52-H32 -> 1.200056 | I42: =I52-I32 -> 7.6578605e-13 | J42: =J52-J32 -> 6.3631621e-06 | K42: =K52-K32 -> 1.1610115 | L42: =L52-L32 -> 0.22373536 | M42: =M52-M32 -> 3.7574044e-07 | N42: =N52-N32 -> 8.3539847e-10 | ... AB42: =AB52-AB32 -> 2.2084375e-07 | AC42: =SUM(G42:AB42) -> 8.2949134
A43: IMAGE_SSP2L | B43: 2025 | C43: Co refining CA | D43: Canada | E43: Cobalt | F43: Refining | G43: =G53-G33 -> 4.0001553 | H43: =H53-H33 -> 1.200056 | I43: =I53-I33 -> 7.6578605e-13 | J43: =J53-J33 -> 6.3631621e-06 | K43: =K53-K33 -> 1.1610115 | L43: =L53-L33 -> 0.22373536 | M43: =M53-M33 -> 3.7574044e-07 | N43: =N53-N33 -> 8.3539847e-10 | ... AB43: =AB53-AB33 -> 2.2084375e-07 | AC43: =SUM(G43:AB43) -> 8.2949134
A44: IMAGE_SSP2L | B44: 2030 | C44: Co refining CA | D44: Canada | E44: Cobalt | F44: Refining | G44: =G54-G34 -> 4.0001553 | H44: =H54-H34 -> 1.200056 | I44: =I54-I34 -> 7.6578605e-13 | J44: =J54-J34 -> 6.3631621e-06 | K44: =K54-K34 -> 1.1610115 | L44: =L54-L34 -> 0.22373536 | M44: =M54-M34 -> 3.7574044e-07 | N44: =N54-N34 -> 8.3539847e-10 | ... AB44: =AB54-AB34 -> 2.2084375e-07 | AC44: =SUM(G44:AB44) -> 8.2949134
A45: IMAGE_SSP2L | B45: 2035 | C45: Co refining CA | D45: Canada | E45: Cobalt | F45: Refining | G45: =G55-G35 -> 4.0001553 | H45: =H55-H35 -> 1.200056 | I45: =I55-I35 -> 7.6578605e-13 | J45: =J55-J35 -> 6.3631621e-06 | K45: =K55-K35 -> 1.1610115 | L45: =L55-L35 -> 0.22373536 | M45: =M55-M35 -> 3.7574044e-07 | N45: =N55-N35 -> 8.3539847e-10 | ... AB45: =AB55-AB35 -> 2.2084375e-07 | AC45: =SUM(G45:AB45) -> 8.2949134
A46: IMAGE_SSP2L | B46: 2040 | C46: Co refining CA | D46: Canada | E46: Cobalt | F46: Refining | G46: =G56-G36 -> 4.0001553 | H46: =H56-H36 -> 1.200056 | I46: =I56-I36 -> 7.6578605e-13 | J46: =J56-J36 -> 6.3631621e-06 | K46: =K56-K36 -> 1.1610115 | L46: =L56-L36 -> 0.22373536 | M46: =M56-M36 -> 3.7574044e-07 | N46: =N56-N36 -> 8.3539847e-10 | ... AB46: =AB56-AB36 -> 2.2084375e-07 | AC46: =SUM(G46:AB46) -> 8.2949134
A47: IMAGE_SSP2L | B47: 2020 | C47: Co refining World | D47: World | E47: Cobalt | F47: Refining | G47: =G57-G37 -> 4.2395123 | H47: =H57-H37 -> 1.2748941 | I47: =I57-I37 -> 4.6594443e-13 | J47: =J57-J37 -> 6.2856871e-06 | K47: =K57-K37 -> 1.2042247 | L47: =L57-L37 -> 0.25572659 | M47: =M57-M37 -> 3.7002489e-07 | N47: =N57-N37 -> 8.2419654e-10 | ... AB47: =AB57-AB37 -> 2.160248e-07 | AC47: =SUM(G47:AB47) -> 8.7812854
...

Sheet HH_LCA_results
A1: Scenario | B1: Year | C1: Commodity | D1: Geography | E1: Metal | F1: Reference point | G1: Climate change HH LT (DALY) | H1: Climate change HH ST (DALY) | I1: Human toxicity cancer LT (DALY) | J1: Human toxicity cancer ST (DALY) | K1: Human toxicity non-cancer LT (DALY) | L1: Human toxicity non-cancer ST (DALY) | M1: Ionizing radiations HH (DALY) | N1: Ozone layer depletion (DALY) | O1: Particulate matter formation (DALY) | P1: Photochemical ozone HH (DALY) | Q1: Water availability HH (DALY) | R1: Total HH
A2: IMAGE_SSP2L | B2: 2020 | C2: C mining CA | D2: Canada | E2: Graphite | F2: Mining | G2: 5.948767e-08 | H2: 1.824907e-08 | I2: 1.8888778e-11 | J2: 8.2769114e-10 | K2: 5.175596e-10 | L2: 2.0597785e-10 | M2: 2.7419535e-12 | N2: 2.3950329e-13 | O2: 9.9025772e-13 | P2: 1.0780135e-13 | Q2: 6.0973892e-13 | R2: =SUM(G2:Q2) -> 7.9311547e-08
A3: IMAGE_SSP2L | B3: 2025 | C3: C mining CA | D3: Canada | E3: Graphite | F3: Mining | G3: 5.948767e-08 | H3: 1.824907e-08 | I3: 1.8888778e-11 | J3: 8.2769114e-10 | K3: 5.175596e-10 | L3: 2.0597785e-10 | M3: 2.7419535e-12 | N3: 2.3950329e-13 | O3: 9.9025772e-13 | P3: 1.0780135e-13 | Q3: 6.0973892e-13 | R3: =SUM(G3:Q3) -> 7.9311547e-08
A4: IMAGE_SSP2L | B4: 2030 | C4: C mining CA | D4: Canada | E4: Graphite | F4: Mining | G4: 5.948767e-08 | H4: 1.824907e-08 | I4: 1.8888778e-11 | J4: 8.2769114e-10 | K4: 5.175596e-10 | L4: 2.0597785e-10 | M4: 2.7419535e-12 | N4: 2.3950329e-13 | O4: 9.9025772e-13 | P4: 1.0780135e-13 | Q4: 6.0973892e-13 | R4: =SUM(G4:Q4) -> 7.9311547e-08
A5: IMAGE_SSP2L | B5: 2035 | C5: C mining CA | D5: Canada | E5: Graphite | F5: Mining | G5: 5.948767e-08 | H5: 1.824907e-08 | I5: 1.8888778e-11 | J5: 8.2769114e-10 | K5: 5.175596e-10 | L5: 2.0597785e-10 | M5: 2.7419535e-12 | N5: 2.3950329e-13 | O5: 9.9025772e-13 | P5: 1.0780135e-13 | Q5: 6.0973892e-13 | R5: =SUM(G5:Q5) -> 7.9311547e-08
A6: IMAGE_SSP2L | B6: 2040 | C6: C mining CA | D6: Canada | E6: Graphite | F6: Mining | G6: 5.948767e-08 | H6: 1.824907e-08 | I6: 1.8888778e-11 | J6: 8.2769114e-10 | K6: 5.175596e-10 | L6: 2.0597785e-10 | M6: 2.7419535e-12 | N6: 2.3950329e-13 | O6: 9.9025772e-13 | P6: 1.0780135e-13 | Q6: 6.0973892e-13 | R6: =SUM(G6:Q6) -> 7.9311547e-08
A7: IMAGE_SSP2L | B7: 2020 | C7: C mining World | D7: World | E7: Graphite | F7: Mining | G7: 7.6502477e-07 | H7: 2.3186594e-07 | I7: 6.7313254e-10 | J7: 1.1631166e-08 | K7: 8.8395955e-09 | L7: 2.3820629e-09 | M7: 8.5281173e-12 | N7: 3.1741282e-12 | O7: 3.0655233e-12 | P7: 1.400023e-12 | Q7: 1.8584483e-12 | R7: =SUM(G7:Q7) -> 1.0204347e-06
A8: IMAGE_SSP2L | B8: 2025 | C8: C mining World | D8: World | E8: Graphite | F8: Mining | G8: 7.6502477e-07 | H8: 2.3186594e-07 | I8: 6.7313254e-10 | J8: 1.1631166e-08 | K8: 8.8395955e-09 | L8: 2.3820629e-09 | M8: 8.5281173e-12 | N8: 3.1741282e-12 | O8: 3.0655233e-12 | P8: 1.400023e-12 | Q8: 1.8584483e-12 | R8: =SUM(G8:Q8) -> 1.0204347e-06
A9: IMAGE_SSP2L | B9: 2030 | C9: C mining World | D9: World | E9: Graphite | F9: Mining | G9: 7.6502477e-07 | H9: 2.3186594e-07 | I9: 6.7313254e-10 | J9: 1.1631166e-08 | K9: 8.8395955e-09 | L9: 2.3820629e-09 | M9: 8.5281173e-12 | N9: 3.1741282e-12 | O9: 3.0655233e-12 | P9: 1.400023e-12 | Q9: 1.8584483e-12 | R9: =SUM(G9:Q9) -> 1.0204347e-06
A10: IMAGE_SSP2L | B10: 2035 | C10: C mining World | D10: World | E10: Graphite | F10: Mining | G10: 7.6502477e-07 | H10: 2.3186594e-07 | I10: 6.7313254e-10 | J10: 1.1631166e-08 | K10: 8.8395955e-09 | L10: 2.3820629e-09 | M10: 8.5281173e-12 | N10: 3.1741282e-12 | O10: 3.0655233e-12 | P10: 1.400023e-12 | Q10: 1.8584483e-12 | R10: =SUM(G10:Q10) -> 1.0204347e-06
A11: IMAGE_SSP2L | B11: 2040 | C11: C mining World | D11: World | E11: Graphite | F11: Mining | G11: 7.6502477e-07 | H11: 2.3186594e-07 | I11: 6.7313254e-10 | J11: 1.1631166e-08 | K11: 8.8395955e-09 | L11: 2.3820629e-09 | M11: 8.5281173e-12 | N11: 3.1741282e-12 | O11: 3.0655233e-12 | P11: 1.400023e-12 | Q11: 1.8584483e-12 | R11: =SUM(G11:Q11) -> 1.0204347e-06
A12: IMAGE_SSP2L | B12: 2020 | C12: C refining CA | D12: Canada | E12: Graphite | F12: Refining | G12: =G22-G2 -> 1.7768883e-05 | H12: =H22-H2 -> 5.6767706e-06 | I12: =I22-I2 -> 1.1553476e-08 | J12: =J22-J2 -> 2.8091069e-06 | K12: =K22-K2 -> 3.3653622e-07 | L12: =L22-L2 -> 1.1701744e-07 | M12: =M22-M2 -> 1.7291399e-09 | N12: =N22-N2 -> 1.126697e-10 | ... Q12: =Q22-Q2 -> 3.6064576e-11 | R12: =SUM(G12:Q12) -> 2.6721847e-05
A13: IMAGE_SSP2L | B13: 2025 | C13: C refining CA | D13: Canada | E13: Graphite | F13: Refining | G13: =G23-G3 -> 1.7768883e-05 | H13: =H23-H3 -> 5.6767706e-06 | I13: =I23-I3 -> 1.1553476e-08 | J13: =J23-J3 -> 2.8091069e-06 | K13: =K23-K3 -> 3.3653622e-07 | L13: =L23-L3 -> 1.1701744e-07 | M13: =M23-M3 -> 1.7291399e-09 | N13: =N23-N3 -> 1.126697e-10 | ... Q13: =Q23-Q3 -> 3.6064576e-11 | R13: =SUM(G13:Q13) -> 2.6721847e-05
A14: IMAGE_SSP2L | B14: 2030 | C14: C refining CA | D14: Canada | E14: Graphite | F14: Refining | G14: =G24-G4 -> 1.7768883e-05 | H14: =H24-H4 -> 5.6767706e-06 | I14: =I24-I4 -> 1.1553476e-08 | J14: =J24-J4 -> 2.8091069e-06 | K14: =K24-K4 -> 3.3653622e-07 | L14: =L24-L4 -> 1.1701744e-07 | M14: =M24-M4 -> 1.7291399e-09 | N14: =N24-N4 -> 1.126697e-10 | ... Q14: =Q24-Q4 -> 3.6064576e-11 | R14: =SUM(G14:Q14) -> 2.6721847e-05
A15: IMAGE_SSP2L | B15: 2035 | C15: C refining CA | D15: Canada | E15: Graphite | F15: Refining | G15: =G25-G5 -> 1.7768883e-05 | H15: =H25-H5 -> 5.6767706e-06 | I15: =I25-I5 -> 1.1553476e-08 | J15: =J25-J5 -> 2.8091069e-06 | K15: =K25-K5 -> 3.3653622e-07 | L15: =L25-L5 -> 1.1701744e-07 | M15: =M25-M5 -> 1.7291399e-09 | N15: =N25-N5 -> 1.126697e-10 | ... Q15: =Q25-Q5 -> 3.6064576e-11 | R15: =SUM(G15:Q15) -> 2.6721847e-05
A16: IMAGE_SSP2L | B16: 2040 | C16: C refining CA | D16: Canada | E16: Graphite | F16: Refining | G16: =G26-G6 -> 1.7768883e-05 | H16: =H26-H6 -> 5.6767706e-06 | I16: =I26-I6 -> 1.1553476e-08 | J16: =J26-J6 -> 2.8091069e-06 | K16: =K26-K6 -> 3.3653622e-07 | L16: =L26-L6 -> 1.1701744e-07 | M16: =M26-M6 -> 1.7291399e-09 | N16: =N26-N6 -> 1.126697e-10 | ... Q16: =Q26-Q6 -> 3.6064576e-11 | R16: =SUM(G16:Q16) -> 2.6721847e-05
A17: IMAGE_SSP2L | B17: 2020 | C17: C refining World | D17: World | E17: Graphite | F17: Refining | G17: =G27-G7 -> 2.8745211e-05 | H17: =H27-H7 -> 9.1498278e-06 | I17: =I27-I7 -> 1.9872368e-08 | J17: =J27-J7 -> 2.8465185e-06 | K17: =K27-K7 -> 5.9341081e-07 | L17: =L27-L7 -> 1.7629437e-07 | M17: =M27-M7 -> 1.9908056e-09 | N17: =N27-N7 -> 1.1993705e-10 | ... Q17: =Q27-Q7 -> 4.1815271e-11 | R17: =SUM(G17:Q17) -> 4.1533397e-05
A18: IMAGE_SSP2L | B18: 2025 | C18: C refining World | D18: World | E18: Graphite | F18: Refining | G18: =G28-G8 -> 2.8745211e-05 | H18: =H28-H8 -> 9.1498278e-06 | I18: =I28-I8 -> 1.9872368e-08 | J18: =J28-J8 -> 2.8465185e-06 | K18: =K28-K8 -> 5.9341081e-07 | L18: =L28-L8 -> 1.7629437e-07 | M18: =M28-M8 -> 1.9908056e-09 | N18: =N28-N8 -> 1.1993705e-10 | ... Q18: =Q28-Q8 -> 4.1815271e-11 | R18: =SUM(G18:Q18) -> 4.1533397e-05
A19: IMAGE_SSP2L | B19: 2030 | C19: C refining World | D19: World | E19: Graphite | F19: Refining | G19: =G29-G9 -> 2.8745211e-05 | H19: =H29-H9 -> 9.1498278e-06 | I19: =I29-I9 -> 1.9872368e-08 | J19: =J29-J9 -> 2.8465185e-06 | K19: =K29-K9 -> 5.9341081e-07 | L19: =L29-L9 -> 1.7629437e-07 | M19: =M29-M9 -> 1.9908056e-09 | N19: =N29-N9 -> 1.1993705e-10 | ... Q19: =Q29-Q9 -> 4.1815271e-11 | R19: =SUM(G19:Q19) -> 4.1533397e-05
A20: IMAGE_SSP2L | B20: 2035 | C20: C refining World | D20: World | E20: Graphite | F20: Refining | G20: =G30-G10 -> 2.8745211e-05 | H20: =H30-H10 -> 9.1498278e-06 | I20: =I30-I10 -> 1.9872368e-08 | J20: =J30-J10 -> 2.8465185e-06 | K20: =K30-K10 -> 5.9341081e-07 | L20: =L30-L10 -> 1.7629437e-07 | M20: =M30-M10 -> 1.9908056e-09 | N20: =N30-N10 -> 1.1993705e-10 | ... Q20: =Q30-Q10 -> 4.1815271e-11 | R20: =SUM(G20:Q20) -> 4.1533397e-05
A21: IMAGE_SSP2L | B21: 2040 | C21: C refining World | D21: World | E21: Graphite | F21: Refining | G21: =G31-G11 -> 2.8745211e-05 | H21: =H31-H11 -> 9.1498278e-06 | I21: =I31-I11 -> 1.9872368e-08 | J21: =J31-J11 -> 2.8465185e-06 | K21: =K31-K11 -> 5.9341081e-07 | L21: =L31-L11 -> 1.7629437e-07 | M21: =M31-M11 -> 1.9908056e-09 | N21: =N31-N11 -> 1.1993705e-10 | ... Q21: =Q31-Q11 -> 4.1815271e-11 | R21: =SUM(G21:Q21) -> 4.1533397e-05
A22: IMAGE_SSP2L | B22: 2020 | C22: C refining CA | D22: Canada | E22: Graphite | F22: Mining+refining | G22: 1.7828371e-05 | H22: 5.6950197e-06 | I22: 1.1572364e-08 | J22: 2.8099346e-06 | K22: 3.3705378e-07 | L22: 1.1722342e-07 | M22: 1.7318818e-09 | N22: 1.1290921e-10 | O22: 6.1428755e-11 | P22: 4.0492933e-11 | Q22: 3.6674315e-11 | R22: =SUM(G22:Q22) -> 2.6801158e-05
A23: IMAGE_SSP2L | B23: 2025 | C23: C refining CA | D23: Canada | E23: Graphite | F23: Mining+refining | G23: 1.7828371e-05 | H23: 5.6950197e-06 | I23: 1.1572364e-08 | J23: 2.8099346e-06 | K23: 3.3705378e-07 | L23: 1.1722342e-07 | M23: 1.7318818e-09 | N23: 1.1290921e-10 | O23: 6.1428755e-11 | P23: 4.0492933e-11 | Q23: 3.6674315e-11 | R23: =SUM(G23:Q23) -> 2.6801158e-05
A24: IMAGE_SSP2L | B24: 2030 | C24: C refining CA | D24: Canada | E24: Graphite | F24: Mining+refining | G24: 1.7828371e-05 | H24: 5.6950197e-06 | I24: 1.1572364e-08 | J24: 2.8099346e-06 | K24: 3.3705378e-07 | L24: 1.1722342e-07 | M24: 1.7318818e-09 | N24: 1.1290921e-10 | O24: 6.1428755e-11 | P24: 4.0492933e-11 | Q24: 3.6674315e-11 | R24: =SUM(G24:Q24) -> 2.6801158e-05
A25: IMAGE_SSP2L | B25: 2035 | C25: C refining CA | D25: Canada | E25: Graphite | F25: Mining+refining | G25: 1.7828371e-05 | H25: 5.6950197e-06 | I25: 1.1572364e-08 | J25: 2.8099346e-06 | K25: 3.3705378e-07 | L25: 1.1722342e-07 | M25: 1.7318818e-09 | N25: 1.1290921e-10 | O25: 6.1428755e-11 | P25: 4.0492933e-11 | Q25: 3.6674315e-11 | R25: =SUM(G25:Q25) -> 2.6801158e-05
A26: IMAGE_SSP2L | B26: 2040 | C26: C refining CA | D26: Canada | E26: Graphite | F26: Mining+refining | G26: 1.7828371e-05 | H26: 5.6950197e-06 | I26: 1.1572364e-08 | J26: 2.8099346e-06 | K26: 3.3705378e-07 | L26: 1.1722342e-07 | M26: 1.7318818e-09 | N26: 1.1290921e-10 | O26: 6.1428755e-11 | P26: 4.0492933e-11 | Q26: 3.6674315e-11 | R26: =SUM(G26:Q26) -> 2.6801158e-05
A27: IMAGE_SSP2L | B27: 2020 | C27: C refining World | D27: World | E27: Graphite | F27: Mining+refining | G27: 2.9510235e-05 | H27: 9.3816938e-06 | I27: 2.0545501e-08 | J27: 2.8581496e-06 | K27: 6.022504e-07 | L27: 1.7867643e-07 | M27: 1.9993338e-09 | N27: 1.2311118e-10 | O27: 7.1376152e-11 | P27: 4.2732152e-11 | Q27: 4.3673719e-11 | R27: =SUM(G27:Q27) -> 4.2553831e-05
A28: IMAGE_SSP2L | B28: 2025 | C28: C refining World | D28: World | E28: Graphite | F28: Mining+refining | G28: 2.9510235e-05 | H28: 9.3816938e-06 | I28: 2.0545501e-08 | J28: 2.8581496e-06 | K28: 6.022504e-07 | L28: 1.7867643e-07 | M28: 1.9993338e-09 | N28: 1.2311118e-10 | O28: 7.1376152e-11 | P28: 4.2732152e-11 | Q28: 4.3673719e-11 | R28: =SUM(G28:Q28) -> 4.2553831e-05
A29: IMAGE_SSP2L | B29: 2030 | C29: C refining World | D29: World | E29: Graphite | F29: Mining+refining | G29: 2.9510235e-05 | H29: 9.3816938e-06 | I29: 2.0545501e-08 | J29: 2.8581496e-06 | K29: 6.022504e-07 | L29: 1.7867643e-07 | M29: 1.9993338e-09 | N29: 1.2311118e-10 | O29: 7.1376152e-11 | P29: 4.2732152e-11 | Q29: 4.3673719e-11 | R29: =SUM(G29:Q29) -> 4.2553831e-05
A30: IMAGE_SSP2L | B30: 2035 | C30: C refining World | D30: World | E30: Graphite | F30: Mining+refining | G30: 2.9510235e-05 | H30: 9.3816938e-06 | I30: 2.0545501e-08 | J30: 2.8581496e-06 | K30: 6.022504e-07 | L30: 1.7867643e-07 | M30: 1.9993338e-09 | N30: 1.2311118e-10 | O30: 7.1376152e-11 | P30: 4.2732152e-11 | Q30: 4.3673719e-11 | R30: =SUM(G30:Q30) -> 4.2553831e-05
A31: IMAGE_SSP2L | B31: 2040 | C31: C refining World | D31: World | E31: Graphite | F31: Mining+refining | G31: 2.9510235e-05 | H31: 9.3816938e-06 | I31: 2.0545501e-08 | J31: 2.8581496e-06 | K31: 6.022504e-07 | L31: 1.7867643e-07 | M31: 1.9993338e-09 | N31: 1.2311118e-10 | O31: 7.1376152e-11 | P31: 4.2732152e-11 | Q31: 4.3673719e-11 | R31: =SUM(G31:Q31) -> 4.2553831e-05
A32: IMAGE_SSP2L | B32: 2020 | C32: Co mining CA | D32: Canada | E32: Cobalt | F32: Mining | G32: 1.7764582e-07 | H32: 5.3813717e-08 | I32: 3.7909546e-11 | J32: 2.3803895e-09 | K32: 9.4756708e-10 | L32: 4.0846561e-10 | M32: 1.4382686e-12 | N32: 7.991718e-13 | O32: 1.6899129e-12 | P32: 3.5057455e-13 | Q32: 7.2616594e-13 | R32: =SUM(G32:Q32) -> 2.3523887e-07
A33: IMAGE_SSP2L | B33: 2025 | C33: Co mining CA | D33: Canada | E33: Cobalt | F33: Mining | G33: 1.7764582e-07 | H33: 5.3813717e-08 | I33: 3.7909546e-11 | J33: 2.3803895e-09 | K33: 9.4756708e-10 | L33: 4.0846561e-10 | M33: 1.4382686e-12 | N33: 7.991718e-13 | O33: 1.6899129e-12 | P33: 3.5057455e-13 | Q33: 7.2616594e-13 | R33: =SUM(G33:Q33) -> 2.3523887e-07
... A41: IMAGE_SSP2L | B41: 2040 | C41: Co mining World | D41: World | E41: Cobalt | F41: Mining | G41: 5.6105656e-07 | H41: 1.6975222e-07 | I41: 4.0818945e-10 | J41: 8.4098534e-09 | K41: 5.4649895e-09 | L41: 1.5795786e-09 | M41: 4.500309e-12 | N41: 2.422185e-12 | O41: 2.7200291e-12 | P41: 1.0681722e-12 | Q41: 1.3749445e-12 | R41: =SUM(G41:Q41) -> 7.4668348e-07
A42: IMAGE_SSP2L | B42: 2020 | C42: Co refining CA | D42: Canada | E42: Cobalt | F42: Refining | G42: =G52-G32 -> 5.3909982e-05 | H42: =H52-H32 -> 1.6173121e-05 | I42: =I52-I32 -> 5.7670926e-08 | J42: =J52-J32 -> 2.9949621e-06 | K42: =K52-K32 -> 1.9534624e-06 | L42: =L52-L32 -> 1.5874871e-06 | M42: =M52-M32 -> 8.9631899e-09 | N42: =N52-N32 -> 5.2045204e-10 | ... Q42: =Q52-Q32 -> 4.5538887e-10 | R42: =SUM(G42:Q42) -> 7.6687394e-05
A43: IMAGE_SSP2L | B43: 2025 | C43: Co refining CA | D43: Canada | E43: Cobalt | F43: Refining | G43: =G53-G33 -> 5.3909982e-05 | H43: =H53-H33 -> 1.6173121e-05 | I43: =I53-I33 -> 5.7670926e-08 | J43: =J53-J33 -> 2.9949621e-06 | K43: =K53-K33 -> 1.9534624e-06 | L43: =L53-L33 -> 1.5874871e-06 | M43: =M53-M33 -> 8.9631899e-09 | N43: =N53-N33 -> 5.2045204e-10 | ... Q43: =Q53-Q33 -> 4.5538887e-10 | R43: =SUM(G43:Q43) -> 7.6687394e-05
A44: IMAGE_SSP2L | B44: 2030 | C44: Co refining CA | D44: Canada | E44: Cobalt | F44: Refining | G44: =G54-G34 -> 5.3909982e-05 | H44: =H54-H34 -> 1.6173121e-05 | I44: =I54-I34 -> 5.7670926e-08 | J44: =J54-J34 -> 2.9949621e-06 | K44: =K54-K34 -> 1.9534624e-06 | L44: =L54-L34 -> 1.5874871e-06 | M44: =M54-M34 -> 8.9631899e-09 | N44: =N54-N34 -> 5.2045204e-10 | ... Q44: =Q54-Q34 -> 4.5538887e-10 | R44: =SUM(G44:Q44) -> 7.6687394e-05
A45: IMAGE_SSP2L | B45: 2035 | C45: Co refining CA | D45: Canada | E45: Cobalt | F45: Refining | G45: =G55-G35 -> 5.3909982e-05 | H45: =H55-H35 -> 1.6173121e-05 | I45: =I55-I35 -> 5.7670926e-08 | J45: =J55-J35 -> 2.9949621e-06 | K45: =K55-K35 -> 1.9534624e-06 | L45: =L55-L35 -> 1.5874871e-06 | M45: =M55-M35 -> 8.9631899e-09 | N45: =N55-N35 -> 5.2045204e-10 | ... Q45: =Q55-Q35 -> 4.5538887e-10 | R45: =SUM(G45:Q45) -> 7.6687394e-05
A46: IMAGE_SSP2L | B46: 2040 | C46: Co refining CA | D46: Canada | E46: Cobalt | F46: Refining | G46: =G56-G36 -> 5.3909982e-05 | H46: =H56-H36 -> 1.6173121e-05 | I46: =I56-I36 -> 5.7670926e-08 | J46: =J56-J36 -> 2.9949621e-06 | K46: =K56-K36 -> 1.9534624e-06 | L46: =L56-L36 -> 1.5874871e-06 | M46: =M56-M36 -> 8.9631899e-09 | N46: =N56-N36 -> 5.2045204e-10 | ... Q46: =Q56-Q36 -> 4.5538887e-10 | R46: =SUM(G46:Q46) -> 7.6687394e-05
A47: IMAGE_SSP2L | B47: 2020 | C47: Co refining World | D47: World | E47: Cobalt | F47: Refining | G47: =G57-G37 -> 5.713579e-05 | H47: =H57-H37 -> 1.7181713e-05 | I47: =I57-I37 -> 5.9992935e-08 | J47: =J57-J37 -> 3.0126481e-06 | K47: =K57-K37 -> 2.0135007e-06 | L47: =L57-L37 -> 1.6006058e-06 | M47: =M57-M37 -> 9.0382471e-09 | N47: =N57-N37 -> 5.2550279e-10 | ... Q47: =Q57-Q37 -> 4.4966116e-10 | R47: =SUM(G47:Q47) -> 8.1015025e-05
...

Sheet GWP_LCA_results
A1: Scenario | B1: Year | C1: Commodity | D1: Geography | E1: Metal | F1: Reference point | G1: Climate change ST (kg CO2 eq (short))
A2: IMAGE_SSP2L | B2: 2020 | C2: C mining CA | D2: Canada | E2: Graphite | F2: Mining | G2: 0.011672522
A3: IMAGE_SSP2L | B3: 2025 | C3: C mining CA | D3: Canada | E3: Graphite | F3: Mining | G3: 0.01172065
A4: IMAGE_SSP2L | B4: 2030 | C4: C mining CA | D4: Canada | E4: Graphite | F4: Mining | G4: 0.011304986
A5: IMAGE_SSP2L | B5: 2035 | C5: C mining CA | D5: Canada | E5: Graphite | F5: Mining | G5: 0.01079376
A6: IMAGE_SSP2L | B6: 2040 | C6: C mining CA | D6: Canada | E6: Graphite | F6: Mining | G6: 0.010266638
A7: IMAGE_SSP2L | B7: 2020 | C7: C mining World | D7: World | E7: Graphite | F7: Mining | G7: 0.14848143
A8: IMAGE_SSP2L | B8: 2025 | C8: C mining World | D8: World | E8: Graphite | F8: Mining | G8: 0.14771958
A9: IMAGE_SSP2L | B9: 2030 | C9: C mining World | D9: World | E9: Graphite | F9: Mining | G9: 0.14380677
A10: IMAGE_SSP2L | B10: 2035 | C10: C mining World | D10: World | E10: Graphite | F10: Mining | G10: 0.1340491
A11: IMAGE_SSP2L | B11: 2040 | C11: C mining World | D11: World | E11: Graphite | F11: Mining | G11: 0.11767796
A12: IMAGE_SSP2L | B12: 2020 | C12: C refining CA | D12: Canada | E12: Graphite | F12: Refining
A13: IMAGE_SSP2L | B13: 2025 | C13: C refining CA | D13: Canada | E13: Graphite | F13: Refining
A14: IMAGE_SSP2L | B14: 2030 | C14: C refining CA | D14: Canada | E14: Graphite | F14: Refining
A15: IMAGE_SSP2L | B15: 2035 | C15: C refining CA | D15: Canada | E15: Graphite | F15: Refining
A16: IMAGE_SSP2L | B16: 2040 | C16: C refining CA | D16: Canada | E16: Graphite | F16: Refining
A17: IMAGE_SSP2L | B17: 2020 | C17: C refining World | D17: World | E17: Graphite | F17: Refining
A18: IMAGE_SSP2L | B18: 2025 | C18: C refining World | D18: World | E18: Graphite | F18: Refining
A19: IMAGE_SSP2L | B19: 2030 | C19: C refining World | D19: World | E19: Graphite | F19: Refining
A20: IMAGE_SSP2L | B20: 2035 | C20: C refining World | D20: World | E20: Graphite | F20: Refining
A21: IMAGE_SSP2L | B21: 2040 | C21: C refining World | D21: World | E21: Graphite | F21: Refining
A22: IMAGE_SSP2L | B22: 2020 | C22: C refining CA | D22: Canada | E22: Graphite | F22: Mining+refining | G22: 3.7250374
A23: IMAGE_SSP2L | B23: 2025 | C23: C refining CA | D23: Canada | E23: Graphite | F23: Mining+refining
A24: IMAGE_SSP2L | B24: 2030 | C24: C refining CA | D24: Canada | E24: Graphite | F24: Mining+refining
A25: IMAGE_SSP2L | B25: 2035 | C25: C refining CA | D25: Canada | E25: Graphite | F25: Mining+refining
A26: IMAGE_SSP2L | B26: 2040 | C26: C refining CA | D26: Canada | E26: Graphite | F26: Mining+refining
A27: IMAGE_SSP2L | B27: 2020 | C27: C refining World | D27: World | E27: Graphite | F27: Mining+refining | G27: 6.124729
A28: IMAGE_SSP2L | B28: 2025 | C28: C refining World | D28: World | E28: Graphite | F28: Mining+refining | G28: 5.7444009
A29: IMAGE_SSP2L | B29: 2030 | C29: C refining World | D29: World | E29: Graphite | F29: Mining+refining | G29: 5.3665489
A30: IMAGE_SSP2L | B30: 2035 | C30: C refining World | D30: World | E30: Graphite | F30: Mining+refining | G30: 4.9027168
A31: IMAGE_SSP2L | B31: 2040 | C31: C refining World | D31: World | E31: Graphite | F31: Mining+refining | G31: 3.6796432
A32: IMAGE_SSP2L | B32: 2020 | C32: Co mining CA | D32: Canada | E32: Cobalt | F32: Mining | G32: 0.034599806
A33: IMAGE_SSP2L | B33: 2025 | C33: Co mining CA | D33: Canada | E33: Cobalt | F33: Mining | G33: 0.03479059
A34: IMAGE_SSP2L | B34: 2030 | C34: Co mining CA | D34: Canada | E34: Cobalt | F34: Mining | G34: 0.03439296
A35: IMAGE_SSP2L | B35: 2035 | C35: Co mining CA | D35: Canada | E35: Cobalt | F35: Mining | G35: 0.033966842
A36: IMAGE_SSP2L | B36: 2040 | C36: Co mining CA | D36: Canada | E36: Cobalt | F36: Mining | G36: 0.032950707
A37: IMAGE_SSP2L | B37: 2020 | C37: Co mining World | D37: World | E37: Cobalt | F37: Mining | G37: 0.10880177
A38: IMAGE_SSP2L | B38: 2025 | C38: Co mining World | D38: World | E38: Cobalt | F38: Mining | G38: 0.12755568
... A41: IMAGE_SSP2L | B41: 2040 | C41: Co mining World | D41: World | E41: Cobalt | F41: Mining | G41: 0.11189694
A42: IMAGE_SSP2L | B42: 2020 | C42: Co refining CA | D42: Canada | E42: Cobalt | F42: Refining | G42: =G52-G32 -> 10.360392
...

Sheet DEMAND
A1: Scenario | B1: Country | C1: Year | D1: Metal | E1: Metal_demand_t
A2: Canada Net-zero | B2: Canada | C2: 2020 | D2: Cobalt | E2: 1093.0696
A3: Canada Net-zero | B3: Canada | C3: 2020 | D3: Copper | E3: 734456.94
A4: Canada Net-zero | B4: Canada | C4: 2020 | D4: Neodymium | E4: 0
A5: Canada Net-zero | B5: Canada | C5: 2020 | D5: Nickel | E5: 6803.3693
A6: Canada Net-zero | B6: Canada | C6: 2021 | D6: Cobalt | E6: 1169.5356
A7: Canada Net-zero | B7: Canada | C7: 2021 | D7: Copper | E7: 738621.26
A8: Canada Net-zero | B8: Canada | C8: 2021 | D8: Neodymium | E8: 0
A9: Canada Net-zero | B9: Canada | C9: 2021 | D9: Nickel | E9: 6897.9909
A10: Canada Net-zero | B10: Canada | C10: 2022 | D10: Cobalt | E10: 1380.3796
A11: Canada Net-zero | B11: Canada | C11: 2022 | D11: Copper | E11: 750772.27
A12: Canada Net-zero | B12: Canada | C12: 2022 | D12: Neodymium | E12: 0
A13: Canada Net-zero | B13: Canada | C13: 2022 | D13: Nickel | E13: 7479.2098
... A531: Global Net-zero | B531: Canada | C531: 2050 | D531: Nickel | E531: 267966.24

Sheet PRODUCTION
A1: Metal | B1: Year | C1: Scenario | D1: Value | E1: Unit | F1: Value_t_mining | G1: Value_t_refining
A2: Cobalt | B2: 2018 | C2: Existing production | D2: 4.1361 | E2: kilotonnes | F2: 4136.1 | G2: 1817.1813
A3: Cobalt | B3: 2019 | C3: Existing production | D3: 3.433 | E3: kilotonnes | F3: 3433 | G3: 1508.2768
A4: Cobalt | B4: 2020 | C4: Existing production | D4: 3.236324 | E4: kilotonnes | F4: 3236.324 | G4: 1421.8678
A5: Cobalt | B5: 2021 | C5: Existing production | D5: 3.808657 | E5: kilotonnes | F5: 3808.657 | G5: 1673.3204
A6: Cobalt | B6: 2022 | C6: Existing production | D6: 2.536143 | E6: kilotonnes | F6: 2536.143 | G6: 1114.2457
A7: Cobalt | B7: 2023 | C7: Existing production | D7: 4.796 | E7: kilotonnes | F7: 4796 | G7: 2107.1061
A8: Cobalt | B8: 2024 | C8: Existing production | D8: 3.381 | E8: kilotonnes | F8: 3381 | G8: 1485.4307
A9: Cobalt | B9: 2025 | C9: Existing production | D9: 3.494 | E9: kilotonnes | F9: 3494 | G9: 1535.0769
A10: Cobalt | B10: 2026 | C10: Existing production | D10: 3.494 | E10: kilotonnes | F10: 3494 | G10: 1535.0769
A11: Cobalt | B11: 2027 | C11: Existing production | D11: 4.176 | E11: kilotonnes | F11: 4176 | G11: 1834.7113
A12: Cobalt | B12: 2028 | C12: Existing production | D12: 4.176 | E12: kilotonnes | F12: 4176 | G12: 1834.7113
A13: Cobalt | B13: 2029 | C13: Existing production | D13: 3.861 | E13: kilotonnes | F13: 3861 | G13: 1696.3171
... A277: Neodymium | B277: 2040 | C277: Production potential | D277: 0.43178439 | E277: kilotonnes | F277: 431.78439 | G277: 258.44192
